Workbook
Name NgonorreaePost: '2017-2022'!#REF!
Name subcategoria: categorias!$B:$B
Name POST: '2017-2022'!$A:$K
Name Estado: categorias!$C$2:$C$65536
Name SegmentaciónDeDatos_PubYear: #REF!
Name EXCLUIDAS: Excluidas!$A$1:$K$463
Name NgonorreaePre: '2012-2017'!$A$1:$K$534
Name categoria: categorias!$A:$A
Name KEYWORDS: 'Palabras claves'!$A:$K
Name SegmentaciónDeDatos_Alerta1: #REF!
Name PREALERTA: '2012-2017'!$A$1:$O$540
Name PRE: '2012-2017'!$A:$K
Name SegmentaciónDeDatos_KeyWords: #REF!
Name PalabrasClave: 'Palabras claves'!$K$1:$K$1371
Name EXCL: Excluidas!$A:$K
Name POSTALERTA: '2017-2022'!$A$1:$B$857
Name TablaNgonoreae: '2012-2022'!$A$1:$K$4211

Sheet DashBoard
C2: Rickettsia spp 2012-2022
C3: Total de publicaciones de | F3: =C2 -> Rickettsia spp 2012-2022 | G3: : | H3: =COUNTA('2012-2022'!A$1:A$873064)-1 -> 7031
D5: Publicaciones por Año | I5: Categorías y Subcategorías
D17: Publicaciones por mes

Sheet categorias
A1: Categorias | B1: Subcategorias | C1: Estados
A2: 1) Reporte de cepas resistentes | B2: 2a) Productos naturales | C2: Revisar
A3: 2) Nuevos tratamientos | B3: 2b) Péptidos | C3: Listo
A4: 3) Inmunizacióm | B4: 2c) Droga de diseño | C4: Excluir
A5: 4) otros | B5: 2d) Anticuerpos | C5: Otros-A
B6: 2e) Bacteriófagos | C6: Otros-B
B7: 2f) Estrategias antivirulencia | C7: Otros-C
B8: 2g) nueva combinación de ATB | C8: Otros-D

Sheet TablasDinamicas
B1: Etiquetas de fila | C1: Cuenta de Title | E1: Cuenta de Title | I1: Categoria | J1: subcategoria | K1: Cuenta de Title
B2: PreAlerta | C2: 2899 | E2: PubYear | F2: PubMonth | G2: Total | I2: 1) Interacción huésped-patógeno | J2: (en blanco) | K2: 2 | L2: 1) Interacción huésped-patógeno | M2: (en blanco) | N2: =GETPIVOTDATA("Title",$I$1,"Categoria",L2,"subcategoria",M2) -> #REF! | P2: Etiquetas de fila | Q2: Cuenta de Title | S2: Etiquetas de fila | T2: Cuenta de Title | V2: Etiquetas de fila | W2: Cuenta de Title
B3: PostAlerta | C3: 3619 | E3: 2017 | F3: Jan | G3: 69 | I3: Total 1) Interacción huésped-patógeno | K3: 2 | L3: 2) Reporte de cepas resistentes | M3: (en blanco) | N3: =GETPIVOTDATA("Title",$I$1,"Categoria",L3,"subcategoria",M3) -> #REF! | P3: (en blanco) | Q3: 7031 | T3: 0
B4: Excluido | C4: 513 | F4: Feb | G4: 61 | I4: 2) Reporte de cepas resistentes | J4: (en blanco) | K4: 2 | L4: 3) Casos clínicos | M4: (en blanco) | N4: =GETPIVOTDATA("Title",$I$1,"Categoria",L4,"subcategoria",M4) -> #REF! | P4: Total general | Q4: 7031 | S4: 2012 | T4: 428
B5: Total general | C5: 7031 | F5: Mar | G5: 76 | I5: Total 2) Reporte de cepas resistentes | K5: 2 | L5: 4) Nuevos tratamientos | M5: 4a) Productos naturales | N5: =GETPIVOTDATA("Title",$I$1,"Categoria",L5,"subcategoria",M5) -> #REF! | S5: 2013 | T5: 558 | V5: S/PalabrasClaves | W5: 6782
F6: Apr | G6: 42 | I6: 3) Casos clínicos | J6: (en blanco) | K6: 2 | L6: 4) Nuevos tratamientos | M6: 4b) Péptidos | N6: =GETPIVOTDATA("Title",$I$1,"Categoria",L6,"subcategoria",M6) -> #REF! | S6: 2014 | T6: 596 | V6: Excluido | W6: 469
F7: May | G7: 39 | I7: Total 3) Casos clínicos | K7: 2 | L7: 4) Nuevos tratamientos | M7: 4c) Droga de diseño | N7: =GETPIVOTDATA("Title",$I$1,"Categoria",L7,"subcategoria",M7) -> #REF! | S7: 2015 | T7: 583 | V7: PostAlerta | W7: 3504
F8: Jun | G8: 65 | I8: 4) Nuevos tratamientos | J8: 4a) Productos naturales | K8: 1 | L8: 4) Nuevos tratamientos | M8: 4d) Anticuerpos | N8: =GETPIVOTDATA("Title",$I$1,"Categoria",L8,"subcategoria",M8) -> #REF! | S8: 2016 | T8: 699 | V8: PreAlerta | W8: 2809
F9: Jul | G9: 45 | J9: 4b) Péptidos | K9: 1 | L9: 4) Nuevos tratamientos | M9: 4e) Bacteriófagos | N9: =GETPIVOTDATA("Title",$I$1,"Categoria",L9,"subcategoria",M9) -> #REF! | S9: 2017 | T9: 654 | V9: (en blanco)
F10: Aug | G10: 61 | J10: 4c) Droga de diseño | K10: 2 | L10: 4) Nuevos tratamientos | M10: 4f) Estrategias antivirulencia | N10: =GETPIVOTDATA("Title",$I$1,"Categoria",L10,"subcategoria",M10) -> #REF! | S10: 2018 | T10: 751 | V10: (en blanco)
F11: Sep | G11: 47 | J11: 4d) Anticuerpos | K11: 1 | S11: 2019 | T11: 700 | V11: Total general | W11: 6782
F12: Oct | G12: 43 | J12: 4e) Bacteriófagos | K12: 1 | S12: 2020 | T12: 762
F13: Nov | G13: 59 | J13: 4f) Estrategias antivirulencia | K13: 1 | S13: 2021 | T13: 785
F14: Dec | G14: 58 | I14: Total 4) Nuevos tratamientos | K14: 7 | S14: 2022 | T14: 258
F15: ver paper | G15: 11 | I15: (en blanco) | J15: (en blanco) | K15: 6769 | S15: 2023 | T15: 8
E16: Total 2017 | G16: 676 | I16: Total (en blanco) | K16: 6769 | S16: (en blanco) | T16: 0
E17: (en blanco) | F17: (en blanco) | I17: Total general | K17: 6782 | S17: Total general | T17: 6782
E18: Total (en blanco)
E19: Total general | G19: 676

Sheet 2012-2022
A1: PMID | B1: Title | C1: Authors | D1: Citation | E1: First Author | F1: Journal/Book | G1: Publication Year | H1: Create Date | I1: PMCID | J1: NIHMS ID | K1: DOI | L1: Alerta | M1: KeyWords | N1: Categoria | O1: subcategoria | P1: fecha de publicación | Q1: Estado | R1: PubYear | S1: PubMonth | T1: Abstract | U1: 1) Reporte de cepas resistentes? | V1: 2) Nuevos tratamientos | W1: 3) Inmunización | X1: Justificacion (no mas de 140 caracteres)
A2: 26467958 | B2: Modification of Insect and Arachnid Behaviours by Vertically Transmitted Endosymbionts: Infections as Drivers of Behavioural Change and Evolutionary Novelty | C2: Goodacre SL, Martin OY. | D2: Insects. 2012 Feb 29;3(1):246-61. doi: 10.3390/insects3010246. | E2: Goodacre SL | F2: Insects | G2: 2012 | H2: 42293 | I2: PMC4553626 | K2: 10.3390/insects3010246 | L2: =IF(ISNUMBER(VLOOKUP(A2,EXCL,1,FALSE)),"Excluido",IF(ISNUMBER(VLOOKUP(A2,POST,1,FALSE)),"PostAlerta",IF(ISNUMBER(VLOOKUP(A2,PRE,1,FALSE)),"PreAlerta",""))) -> Excluido | M2: =IF(ISNUMBER(VLOOKUP(A2,KEYWORDS,1,FALSE)),"C/PalabrasClaves","S/PalabrasClaves") -> S/PalabrasClaves | N2: =IF(ISNUMBER(SEARCH("TREATMENT", B2)), "4) Nuevos tratamientos", "") | P2: 2012 Feb 29 | R2: =LEFT('2012-2022'!$P2,4) -> 2012 | S2: Feb
A3: 21668575 | B3: Histopathological diagnosis of Japanese spotted fever using formalin-fixed, paraffin-embedded skin biopsy specimens: usefulness of immunohistochemistry and real-time PCR analysis | C3: Tamakuma K, Mizutani Y, Ito M, Shiogama K, Inada K, Miyamoto K, Utsunomiya H, Mahara F, Tsutsumi Y. | D3: Clin Microbiol Infect. 2012 Mar;18(3):260-7. doi: 10.1111/j.1469-0691.2011.03569.x. Epub 2011 Jun 10. | E3: Tamakuma K | F3: Clin Microbiol Infect | G3: 2012 | H3: 40709 | K3: 10.1111/j.1469-0691.2011.03569.x | L3: =IF(ISNUMBER(VLOOKUP(A3,EXCL,1,FALSE)),"Excluido",IF(ISNUMBER(VLOOKUP(A3,POST,1,FALSE)),"PostAlerta",IF(ISNUMBER(VLOOKUP(A3,PRE,1,FALSE)),"PreAlerta",""))) -> PreAlerta | M3: =IF(ISNUMBER(VLOOKUP(A3,KEYWORDS,1,FALSE)),"C/PalabrasClaves","S/PalabrasClaves") -> S/PalabrasClaves | N3: =IF(ISNUMBER(SEARCH("TREATMENT", B3)), "4) Nuevos tratamientos", "") | P3: 2012 Mar | R3: =LEFT('2012-2022'!$P3,4) -> 2012 | S3: Mar
A4: 21781141 | B4: Expression of heat shock proteins and subolesin affects stress responses, Anaplasma phagocytophilum infection and questing behaviour in the tick, Ixodes scapularis | C4: Busby AT, Ayllón N, Kocan KM, Blouin EF, de la Fuente G, Galindo RC, Villar M, de la Fuente J. | D4: Med Vet Entomol. 2012 Mar;26(1):92-102. doi: 10.1111/j.1365-2915.2011.00973.x. Epub 2011 Jul 22. | E4: Busby AT | F4: Med Vet Entomol | G4: 2012 | H4: 40750 | K4: 10.1111/j.1365-2915.2011.00973.x | L4: =IF(ISNUMBER(VLOOKUP(A4,EXCL,1,FALSE)),"Excluido",IF(ISNUMBER(VLOOKUP(A4,POST,1,FALSE)),"PostAlerta",IF(ISNUMBER(VLOOKUP(A4,PRE,1,FALSE)),"PreAlerta",""))) -> PreAlerta | M4: =IF(ISNUMBER(A4),(IF(ISNUMBER(VLOOKUP(A4,KEYWORDS,1,FALSE)),"C/PalabrasClaves","S/PalabrasClaves")),"") -> S/PalabrasClaves | N4: =IF(ISNUMBER(SEARCH("TREATMENT", B4)), "4) Nuevos tratamientos", "") | P4: 2012 Mar | R4: =LEFT('2012-2022'!$P4,4) -> 2012 | S4: Mar
A5: 21785920 | B5: Diplorickettsia massiliensis as a human pathogen | C5: Subramanian G, Mediannikov O, Angelakis E, Socolovschi C, Kaplanski G, Martzolff L, Raoult D. | D5: Eur J Clin Microbiol Infect Dis. 2012 Mar;31(3):365-9. doi: 10.1007/s10096-011-1318-7. Epub 2011 Jul 22. | E5: Subramanian G | F5: Eur J Clin Microbiol Infect Dis | G5: 2012 | H5: 40750 | K5: 10.1007/s10096-011-1318-7 | L5: =IF(ISNUMBER(VLOOKUP(A5,EXCL,1,FALSE)),"Excluido",IF(ISNUMBER(VLOOKUP(A5,POST,1,FALSE)),"PostAlerta",IF(ISNUMBER(VLOOKUP(A5,PRE,1,FALSE)),"PreAlerta",""))) -> PreAlerta | M5: =IF(ISNUMBER(A5),(IF(ISNUMBER(VLOOKUP(A5,KEYWORDS,1,FALSE)),"C/PalabrasClaves","S/PalabrasClaves")),"") -> S/PalabrasClaves | N5: =IF(ISNUMBER(SEARCH("TREATMENT", B5)), "4) Nuevos tratamientos", "") | P5: 2012 Mar | R5: =LEFT('2012-2022'!$P5,4) -> 2012 | S5: Mar
A6: 21842137 | B6: Correlations among Anaplasma marginale parasitemia and markers of oxidative stress in crossbred calves | C6: De UK, Dey S, Banerjee PS, Sahoo M. | D6: Trop Anim Health Prod. 2012 Mar;44(3):385-8. doi: 10.1007/s11250-011-9938-6. Epub 2011 Aug 13. | E6: De UK | F6: Trop Anim Health Prod | G6: 2012 | H6: 40771 | K6: 10.1007/s11250-011-9938-6 | L6: =IF(ISNUMBER(VLOOKUP(A6,EXCL,1,FALSE)),"Excluido",IF(ISNUMBER(VLOOKUP(A6,POST,1,FALSE)),"PostAlerta",IF(ISNUMBER(VLOOKUP(A6,PRE,1,FALSE)),"PreAlerta",""))) -> PreAlerta | M6: =IF(ISNUMBER(A6),(IF(ISNUMBER(VLOOKUP(A6,KEYWORDS,1,FALSE)),"C/PalabrasClaves","S/PalabrasClaves")),"") -> S/PalabrasClaves | N6: =IF(ISNUMBER(SEARCH("TREATMENT", B6)), "4) Nuevos tratamientos", "") | P6: 2012 Mar | R6: =LEFT('2012-2022'!$P6,4) -> 2012 | S6: Mar
A7: 21934703 | B7: Occasional males in parthenogenetic populations of Asobara japonica (Hymenoptera: Braconidae): low Wolbachia titer or incomplete coadaptation? | C7: Reumer BM, van Alphen JJ, Kraaijeveld K. | D7: Heredity (Edinb). 2012 Mar;108(3):341-6. doi: 10.1038/hdy.2011.82. Epub 2011 Sep 21. | E7: Reumer BM | F7: Heredity (Edinb) | G7: 2012 | H7: 40808 | I7: PMC3282404 | K7: 10.1038/hdy.2011.82 | L7: =IF(ISNUMBER(VLOOKUP(A7,EXCL,1,FALSE)),"Excluido",IF(ISNUMBER(VLOOKUP(A7,POST,1,FALSE)),"PostAlerta",IF(ISNUMBER(VLOOKUP(A7,PRE,1,FALSE)),"PreAlerta",""))) -> PreAlerta | M7: =IF(ISNUMBER(A7),(IF(ISNUMBER(VLOOKUP(A7,KEYWORDS,1,FALSE)),"C/PalabrasClaves","S/PalabrasClaves")),"") -> S/PalabrasClaves | N7: =IF(ISNUMBER(SEARCH("TREATMENT", B7)), "4) Nuevos tratamientos", "") | P7: 2012 Mar | R7: =LEFT('2012-2022'!$P7,4) -> 2012 | S7: Mar
A8: 21938022 | B8: Unveiling in situ interactions between marine protists and bacteria through single cell sequencing | C8: Martinez-Garcia M, Brazel D, Poulton NJ, Swan BK, Gomez ML, Masland D, Sieracki ME, Stepanauskas R. | D8: ISME J. 2012 Mar;6(3):703-7. doi: 10.1038/ismej.2011.126. Epub 2011 Sep 22. | E8: Martinez-Garcia M | F8: ISME J | G8: 2012 | H8: 40809 | I8: PMC3280149 | K8: 10.1038/ismej.2011.126 | L8: =IF(ISNUMBER(VLOOKUP(A8,EXCL,1,FALSE)),"Excluido",IF(ISNUMBER(VLOOKUP(A8,POST,1,FALSE)),"PostAlerta",IF(ISNUMBER(VLOOKUP(A8,PRE,1,FALSE)),"PreAlerta",""))) -> PreAlerta | M8: =IF(ISNUMBER(A8),(IF(ISNUMBER(VLOOKUP(A8,KEYWORDS,1,FALSE)),"C/PalabrasClaves","S/PalabrasClaves")),"") -> S/PalabrasClaves | N8: =IF(ISNUMBER(SEARCH("TREATMENT", B8)), "4) Nuevos tratamientos", "") | P8: 2012 Mar | R8: =LEFT('2012-2022'!$P8,4) -> 2012 | S8: Mar
A9: 22022815 | B9: Detection of Rickettsia parkeri and Candidatus Rickettsia andeanae in Amblyomma maculatum Gulf Coast ticks collected from humans in the United States | C9: Jiang J, Stromdahl EY, Richards AL. | D9: Vector Borne Zoonotic Dis. 2012 Mar;12(3):175-82. doi: 10.1089/vbz.2011.0614. Epub 2011 Oct 24. | E9: Jiang J | F9: Vector Borne Zoonotic Dis | G9: 2012 | H9: 40842 | K9: 10.1089/vbz.2011.0614 | L9: =IF(ISNUMBER(VLOOKUP(A9,EXCL,1,FALSE)),"Excluido",IF(ISNUMBER(VLOOKUP(A9,POST,1,FALSE)),"PostAlerta",IF(ISNUMBER(VLOOKUP(A9,PRE,1,FALSE)),"PreAlerta",""))) -> PreAlerta | M9: =IF(ISNUMBER(A9),(IF(ISNUMBER(VLOOKUP(A9,KEYWORDS,1,FALSE)),"C/PalabrasClaves","S/PalabrasClaves")),"") -> S/PalabrasClaves | N9: =IF(ISNUMBER(SEARCH("TREATMENT", B9)), "4) Nuevos tratamientos", "") | P9: 2012 Mar | R9: =LEFT('2012-2022'!$P9,4) -> 2012 | S9: Mar
A10: 22076027 | B10: Cross-effects of nickel contamination and parasitism on zebra mussel physiology | C10: Minguez L, Boiché A, Sroda S, Mastitsky S, Brulé N, Bouquerel J, Giambérini L. | D10: Ecotoxicology. 2012 Mar;21(2):538-47. doi: 10.1007/s10646-011-0814-y. Epub 2011 Nov 12. | E10: Minguez L | F10: Ecotoxicology | G10: 2012 | H10: 40862 | K10: 10.1007/s10646-011-0814-y | L10: =IF(ISNUMBER(VLOOKUP(A10,EXCL,1,FALSE)),"Excluido",IF(ISNUMBER(VLOOKUP(A10,POST,1,FALSE)),"PostAlerta",IF(ISNUMBER(VLOOKUP(A10,PRE,1,FALSE)),"PreAlerta",""))) -> PreAlerta | M10: =IF(ISNUMBER(A10),(IF(ISNUMBER(VLOOKUP(A10,KEYWORDS,1,FALSE)),"C/PalabrasClaves","S/PalabrasClaves")),"") -> S/PalabrasClaves | N10: =IF(ISNUMBER(SEARCH("TREATMENT", B10)), "4) Nuevos tratamientos", "") | P10: 2012 Mar | R10: =LEFT('2012-2022'!$P10,4) -> 2012 | S10: Mar
A11: 22159737 | B11: Polyclonal antibody against conserved sequences of mce1A protein blocks MTB infection in macrophages | C11: Sivagnanam S, Namasivayam N, Chellam R. | D11: Appl Microbiol Biotechnol. 2012 Mar;93(6):2463-73. doi: 10.1007/s00253-011-3754-9. Epub 2011 Dec 13. | E11: Sivagnanam S | F11: Appl Microbiol Biotechnol | G11: 2012 | H11: 40891 | K11: 10.1007/s00253-011-3754-9 | L11: =IF(ISNUMBER(VLOOKUP(A11,EXCL,1,FALSE)),"Excluido",IF(ISNUMBER(VLOOKUP(A11,POST,1,FALSE)),"PostAlerta",IF(ISNUMBER(VLOOKUP(A11,PRE,1,FALSE)),"PreAlerta",""))) -> PreAlerta | M11: =IF(ISNUMBER(A11),(IF(ISNUMBER(VLOOKUP(A11,KEYWORDS,1,FALSE)),"C/PalabrasClaves","S/PalabrasClaves")),"") -> S/PalabrasClaves | N11: =IF(ISNUMBER(SEARCH("TREATMENT", B11)), "4) Nuevos tratamientos", "") | P11: 2012 Mar | R11: =LEFT('2012-2022'!$P11,4) -> 2012 | S11: Mar
A12: 22172602 | B12: Infections with Wolbachia and Spiroplasma in the Scathophagidae and other Muscoidea | C12: Martin OY, Gubler A, Wimmer C, Germann C, Bernasconi MV. | D12: Infect Genet Evol. 2012 Mar;12(2):315-23. doi: 10.1016/j.meegid.2011.11.012. Epub 2011 Dec 8. | E12: Martin OY | F12: Infect Genet Evol | G12: 2012 | H12: 40894 | K12: 10.1016/j.meegid.2011.11.012 | L12: =IF(ISNUMBER(VLOOKUP(A12,EXCL,1,FALSE)),"Excluido",IF(ISNUMBER(VLOOKUP(A12,POST,1,FALSE)),"PostAlerta",IF(ISNUMBER(VLOOKUP(A12,PRE,1,FALSE)),"PreAlerta",""))) -> PreAlerta | M12: =IF(ISNUMBER(A12),(IF(ISNUMBER(VLOOKUP(A12,KEYWORDS,1,FALSE)),"C/PalabrasClaves","S/PalabrasClaves")),"") -> S/PalabrasClaves | N12: =IF(ISNUMBER(SEARCH("TREATMENT", B12)), "4) Nuevos tratamientos", "") | P12: 2012 Mar | R12: =LEFT('2012-2022'!$P12,4) -> 2012 | S12: Mar
A13: 22205824 | B13: "Candidatus Neoehrlichia mikurensis," Anaplasma phagocytophilum, and lyme disease spirochetes in questing european vector ticks and in feeding ticks removed from people | C13: Richter D, Matuschka FR. | D13: J Clin Microbiol. 2012 Mar;50(3):943-7. doi: 10.1128/JCM.05802-11. Epub 2012 Jan 11. | E13: Richter D | F13: J Clin Microbiol | G13: 2012 | H13: 40907 | I13: PMC3295140 | K13: 10.1128/JCM.05802-11 | L13: =IF(ISNUMBER(VLOOKUP(A13,EXCL,1,FALSE)),"Excluido",IF(ISNUMBER(VLOOKUP(A13,POST,1,FALSE)),"PostAlerta",IF(ISNUMBER(VLOOKUP(A13,PRE,1,FALSE)),"PreAlerta",""))) -> PreAlerta | M13: =IF(ISNUMBER(A13),(IF(ISNUMBER(VLOOKUP(A13,KEYWORDS,1,FALSE)),"C/PalabrasClaves","S/PalabrasClaves")),"") -> S/PalabrasClaves | N13: =IF(ISNUMBER(SEARCH("TREATMENT", B13)), "4) Nuevos tratamientos", "") | P13: 2012 Mar | R13: =LEFT('2012-2022'!$P13,4) -> 2012 | S13: Mar
A14: 22210220 | B14: Wolbachia strain wAlbB enhances infection by the rodent malaria parasite Plasmodium berghei in Anopheles gambiae mosquitoes | C14: Hughes GL, Vega-Rodriguez J, Xue P, Rasgon JL. | D14: Appl Environ Microbiol. 2012 Mar;78(5):1491-5. doi: 10.1128/AEM.06751-11. Epub 2011 Dec 30. | E14: Hughes GL | F14: Appl Environ Microbiol | G14: 2012 | H14: 40911 | I14: PMC3294472 | K14: 10.1128/AEM.06751-11 | L14: =IF(ISNUMBER(VLOOKUP(A14,EXCL,1,FALSE)),"Excluido",IF(ISNUMBER(VLOOKUP(A14,POST,1,FALSE)),"PostAlerta",IF(ISNUMBER(VLOOKUP(A14,PRE,1,FALSE)),"PreAlerta",""))) -> PreAlerta | M14: =IF(ISNUMBER(A14),(IF(ISNUMBER(VLOOKUP(A14,KEYWORDS,1,FALSE)),"C/PalabrasClaves","S/PalabrasClaves")),"") -> S/PalabrasClaves | N14: =IF(ISNUMBER(SEARCH("TREATMENT", B14)), "4) Nuevos tratamientos", "") | P14: 2012 Mar | R14: =LEFT('2012-2022'!$P14,4) -> 2012 | S14: Mar
A15: 22214329 | B15: Wolbachia and its implications for the immunopathology of filariasis | C15: Genchi C, Kramer LH, Sassera D, Bandi C. | D15: Endocr Metab Immune Disord Drug Targets. 2012 Mar;12(1):53-6. doi: 10.2174/187153012799279108. | E15: Genchi C | F15: Endocr Metab Immune Disord Drug Targets | G15: 2012 | H15: 40913 | K15: 10.2174/187153012799279108 | L15: =IF(ISNUMBER(VLOOKUP(A15,EXCL,1,FALSE)),"Excluido",IF(ISNUMBER(VLOOKUP(A15,POST,1,FALSE)),"PostAlerta",IF(ISNUMBER(VLOOKUP(A15,PRE,1,FALSE)),"PreAlerta",""))) -> Excluido | M15: =IF(ISNUMBER(A15),(IF(ISNUMBER(VLOOKUP(A15,KEYWORDS,1,FALSE)),"C/PalabrasClaves","S/PalabrasClaves")),"") -> S/PalabrasClaves | N15: =IF(ISNUMBER(SEARCH("TREATMENT", B15)), "4) Nuevos tratamientos", "") | P15: 2012 Mar | R15: =LEFT('2012-2022'!$P15,4) -> 2012 | S15: Mar
A16: 22219313 | B16: Prospective evaluation of commercial antibody-based rapid tests in combination with a loop-mediated isothermal amplification PCR assay for detection of Orientia tsutsugamushi during the acute phase of scrub typhus infection | C16: Blacksell SD, Paris DH, Chierakul W, Wuthiekanun V, Teeratakul A, Kantipong P, Day NP. | D16: Clin Vaccine Immunol. 2012 Mar;19(3):391-5. doi: 10.1128/CVI.05478-11. Epub 2012 Jan 4. | E16: Blacksell SD | F16: Clin Vaccine Immunol | G16: 2012 | H16: 40914 | I16: PMC3294598 | K16: 10.1128/CVI.05478-11 | L16: =IF(ISNUMBER(VLOOKUP(A16,EXCL,1,FALSE)),"Excluido",IF(ISNUMBER(VLOOKUP(A16,POST,1,FALSE)),"PostAlerta",IF(ISNUMBER(VLOOKUP(A16,PRE,1,FALSE)),"PreAlerta",""))) -> PreAlerta | M16: =IF(ISNUMBER(A16),(IF(ISNUMBER(VLOOKUP(A16,KEYWORDS,1,FALSE)),"C/PalabrasClaves","S/PalabrasClaves")),"") -> S/PalabrasClaves | N16: =IF(ISNUMBER(SEARCH("TREATMENT", B16)), "4) Nuevos tratamientos", "") | P16: 2012 Mar | R16: =LEFT('2012-2022'!$P16,4) -> 2012 | S16: Mar
A17: 22222114 | B17: Rickettsiae in arthropods collected from the North African Hedgehog (Atelerix algirus) and the desert hedgehog (Paraechinus aethiopicus) in Algeria | C17: Khaldi M, Socolovschi C, Benyettou M, Barech G, Biche M, Kernif T, Raoult D, Parola P. | D17: Comp Immunol Microbiol Infect Dis. 2012 Mar;35(2):117-22. doi: 10.1016/j.cimid.2011.11.007. Epub 2012 Jan 4. | E17: Khaldi M | F17: Comp Immunol Microbiol Infect Dis | G17: 2012 | H17: 40915 | K17: 10.1016/j.cimid.2011.11.007 | L17: =IF(ISNUMBER(VLOOKUP(A17,EXCL,1,FALSE)),"Excluido",IF(ISNUMBER(VLOOKUP(A17,POST,1,FALSE)),"PostAlerta",IF(ISNUMBER(VLOOKUP(A17,PRE,1,FALSE)),"PreAlerta",""))) -> PreAlerta | M17: =IF(ISNUMBER(A17),(IF(ISNUMBER(VLOOKUP(A17,KEYWORDS,1,FALSE)),"C/PalabrasClaves","S/PalabrasClaves")),"") -> S/PalabrasClaves | N17: =IF(ISNUMBER(SEARCH("TREATMENT", B17)), "4) Nuevos tratamientos", "") | P17: 2012 Mar | R17: =LEFT('2012-2022'!$P17,4) -> 2012 | S17: Mar
A18: 22257655 | B18: A case of rickettsialpox in Northern Europe | C18: Renvoisé A, van't Wout JW, van der Schroeff JG, Beersma MF, Raoult D. | D18: Int J Infect Dis. 2012 Mar;16(3):e221-2. doi: 10.1016/j.ijid.2011.11.009. Epub 2012 Jan 17. | E18: Renvoisé A | F18: Int J Infect Dis | G18: 2012 | H18: 40928 | K18: 10.1016/j.ijid.2011.11.009 | L18: =IF(ISNUMBER(VLOOKUP(A18,EXCL,1,FALSE)),"Excluido",IF(ISNUMBER(VLOOKUP(A18,POST,1,FALSE)),"PostAlerta",IF(ISNUMBER(VLOOKUP(A18,PRE,1,FALSE)),"PreAlerta",""))) -> PreAlerta | M18: =IF(ISNUMBER(A18),(IF(ISNUMBER(VLOOKUP(A18,KEYWORDS,1,FALSE)),"C/PalabrasClaves","S/PalabrasClaves")),"") -> S/PalabrasClaves | N18: =IF(ISNUMBER(SEARCH("TREATMENT", B18)), "4) Nuevos tratamientos", "") | P18: 2012 Mar | R18: =LEFT('2012-2022'!$P18,4) -> 2012 | S18: Mar
A19: 22266203 | B19: Presence and distribution of the endosymbiont Wolbachia among Solenopsis spp. (Hymenoptera: Formicidae) from Brazil and its evolutionary history | C19: Martins C, Souza RF, Bueno OC. | D19: J Invertebr Pathol. 2012 Mar;109(3):287-96. doi: 10.1016/j.jip.2012.01.001. Epub 2012 Jan 12. | E19: Martins C | F19: J Invertebr Pathol | G19: 2012 | H19: 40932 | K19: 10.1016/j.jip.2012.01.001 | L19: =IF(ISNUMBER(VLOOKUP(A19,EXCL,1,FALSE)),"Excluido",IF(ISNUMBER(VLOOKUP(A19,POST,1,FALSE)),"PostAlerta",IF(ISNUMBER(VLOOKUP(A19,PRE,1,FALSE)),"PreAlerta",""))) -> PreAlerta | M19: =IF(ISNUMBER(A19),(IF(ISNUMBER(VLOOKUP(A19,KEYWORDS,1,FALSE)),"C/PalabrasClaves","S/PalabrasClaves")),"") -> S/PalabrasClaves | N19: =IF(ISNUMBER(SEARCH("TREATMENT", B19)), "4) Nuevos tratamientos", "") | P19: 2012 Mar | R19: =LEFT('2012-2022'!$P19,4) -> 2012 | S19: Mar
A20: 22268975 | B20: Integration of molecular, ecological, morphological and endosymbiont data for species delimitation within the Pnigalio soemius complex (Hymenoptera: Eulophidae) | C20: Gebiola M, Gómez-Zurita J, Monti MM, Navone P, Bernardo U. | D20: Mol Ecol. 2012 Mar;21(5):1190-208. doi: 10.1111/j.1365-294X.2011.05428.x. Epub 2012 Jan 23. | E20: Gebiola M | F20: Mol Ecol | G20: 2012 | H20: 40933 | K20: 10.1111/j.1365-294X.2011.05428.x | L20: =IF(ISNUMBER(VLOOKUP(A20,EXCL,1,FALSE)),"Excluido",IF(ISNUMBER(VLOOKUP(A20,POST,1,FALSE)),"PostAlerta",IF(ISNUMBER(VLOOKUP(A20,PRE,1,FALSE)),"PreAlerta",""))) -> PreAlerta | M20: =IF(ISNUMBER(A20),(IF(ISNUMBER(VLOOKUP(A20,KEYWORDS,1,FALSE)),"C/PalabrasClaves","S/PalabrasClaves")),"") -> S/PalabrasClaves | N20: =IF(ISNUMBER(SEARCH("TREATMENT", B20)), "4) Nuevos tratamientos", "") | P20: 2012 Mar | R20: =LEFT('2012-2022'!$P20,4) -> 2012 | S20: Mar
A21: 22277830 | B21: New Rickettsia sp. in tsetse flies from Senegal | C21: Mediannikov O, Audoly G, Diatta G, Trape JF, Raoult D. | D21: Comp Immunol Microbiol Infect Dis. 2012 Mar;35(2):145-50. doi: 10.1016/j.cimid.2011.12.011. Epub 2012 Jan 23. | E21: Mediannikov O | F21: Comp Immunol Microbiol Infect Dis | G21: 2012 | H21: 40935 | K21: 10.1016/j.cimid.2011.12.011 | L21: =IF(ISNUMBER(VLOOKUP(A21,EXCL,1,FALSE)),"Excluido",IF(ISNUMBER(VLOOKUP(A21,POST,1,FALSE)),"PostAlerta",IF(ISNUMBER(VLOOKUP(A21,PRE,1,FALSE)),"PreAlerta",""))) -> PreAlerta | M21: =IF(ISNUMBER(A21),(IF(ISNUMBER(VLOOKUP(A21,KEYWORDS,1,FALSE)),"C/PalabrasClaves","S/PalabrasClaves")),"") -> S/PalabrasClaves | N21: =IF(ISNUMBER(SEARCH("TREATMENT", B21)), "4) Nuevos tratamientos", "") | P21: 2012 Mar | R21: =LEFT('2012-2022'!$P21,4) -> 2012 | S21: Mar
A22: 22282331 | B22: Tetracyclines and pain | C22: Bastos LF, de Oliveira AC, Watkins LR, Moraes MF, Coelho MM. | D22: Naunyn Schmiedebergs Arch Pharmacol. 2012 Mar;385(3):225-41. doi: 10.1007/s00210-012-0727-1. Epub 2012 Jan 27. | E22: Bastos LF | F22: Naunyn Schmiedebergs Arch Pharmacol | G22: 2012 | H22: 40936 | K22: 10.1007/s00210-012-0727-1 | L22: =IF(ISNUMBER(VLOOKUP(A22,EXCL,1,FALSE)),"Excluido",IF(ISNUMBER(VLOOKUP(A22,POST,1,FALSE)),"PostAlerta",IF(ISNUMBER(VLOOKUP(A22,PRE,1,FALSE)),"PreAlerta",""))) -> Excluido | M22: =IF(ISNUMBER(A22),(IF(ISNUMBER(VLOOKUP(A22,KEYWORDS,1,FALSE)),"C/PalabrasClaves","S/PalabrasClaves")),"") -> C/PalabrasClaves | N22: =IF(ISNUMBER(SEARCH("TREATMENT", B22)), "4) Nuevos tratamientos", "") | P22: 2012 Mar | R22: =LEFT('2012-2022'!$P22,4) -> 2012 | S22: Mar
A23: 22293464 | B23: Diversity and phylogenetic analysis of endosymbiotic bacteria from field caught Bemisia tabaci from different locations of North India based on 16S rDNA library screening | C23: Singh ST, Priya NG, Kumar J, Rana VS, Ellango R, Joshi A, Priyadarshini G, Asokan R, Rajagopal R. | D23: Infect Genet Evol. 2012 Mar;12(2):411-9. doi: 10.1016/j.meegid.2012.01.015. Epub 2012 Jan 24. | E23: Singh ST | F23: Infect Genet Evol | G23: 2012 | H23: 40941 | K23: 10.1016/j.meegid.2012.01.015 | L23: =IF(ISNUMBER(VLOOKUP(A23,EXCL,1,FALSE)),"Excluido",IF(ISNUMBER(VLOOKUP(A23,POST,1,FALSE)),"PostAlerta",IF(ISNUMBER(VLOOKUP(A23,PRE,1,FALSE)),"PreAlerta",""))) -> PreAlerta | M23: =IF(ISNUMBER(A23),(IF(ISNUMBER(VLOOKUP(A23,KEYWORDS,1,FALSE)),"C/PalabrasClaves","S/PalabrasClaves")),"") -> S/PalabrasClaves | N23: =IF(ISNUMBER(SEARCH("TREATMENT", B23)), "4) Nuevos tratamientos", "") | P23: 2012 Mar | R23: =LEFT('2012-2022'!$P23,4) -> 2012 | S23: Mar
A24: 22305337 | B24: Molecular detection and characterization of Anaplasma phagocytophilum strains | C24: Paulauskas A, Radzijevskaja J, Rosef O. | D24: Comp Immunol Microbiol Infect Dis. 2012 Mar;35(2):187-95. doi: 10.1016/j.cimid.2012.01.001. Epub 2012 Feb 3. | E24: Paulauskas A | F24: Comp Immunol Microbiol Infect Dis | G24: 2012 | H24: 40946 | K24: 10.1016/j.cimid.2012.01.001 | L24: =IF(ISNUMBER(VLOOKUP(A24,EXCL,1,FALSE)),"Excluido",IF(ISNUMBER(VLOOKUP(A24,POST,1,FALSE)),"PostAlerta",IF(ISNUMBER(VLOOKUP(A24,PRE,1,FALSE)),"PreAlerta",""))) -> PreAlerta | M24: =IF(ISNUMBER(A24),(IF(ISNUMBER(VLOOKUP(A24,KEYWORDS,1,FALSE)),"C/PalabrasClaves","S/PalabrasClaves")),"") -> S/PalabrasClaves | N24: =IF(ISNUMBER(SEARCH("TREATMENT", B24)), "4) Nuevos tratamientos", "") | P24: 2012 Mar | R24: =LEFT('2012-2022'!$P24,4) -> 2012 | S24: Mar
A25: 22321996 | B25: Human granulocytic anaplasmosis in eastern France: clinical presentation and laboratory diagnosis | C25: Koebel C, Kern A, Edouard S, Hoang AT, Celestin N, Hansmann Y, Jaulhac B, Brouqui P, De Martino SJ. | D25: Diagn Microbiol Infect Dis. 2012 Mar;72(3):214-8. doi: 10.1016/j.diagmicrobio.2011.12.005. | E25: Koebel C | F25: Diagn Microbiol Infect Dis | G25: 2012 | H25: 40950 | K25: 10.1016/j.diagmicrobio.2011.12.005 | L25: =IF(ISNUMBER(VLOOKUP(A25,EXCL,1,FALSE)),"Excluido",IF(ISNUMBER(VLOOKUP(A25,POST,1,FALSE)),"PostAlerta",IF(ISNUMBER(VLOOKUP(A25,PRE,1,FALSE)),"PreAlerta",""))) -> PreAlerta | M25: =IF(ISNUMBER(A25),(IF(ISNUMBER(VLOOKUP(A25,KEYWORDS,1,FALSE)),"C/PalabrasClaves","S/PalabrasClaves")),"") -> S/PalabrasClaves | N25: =IF(ISNUMBER(SEARCH("TREATMENT", B25)), "4) Nuevos tratamientos", "") | P25: 2012 Mar | R25: =LEFT('2012-2022'!$P25,4) -> 2012 | S25: Mar
A26: 22369153 | B26: Genomics of epidemic pathogens | C26: Georgiades K. | D26: Clin Microbiol Infect. 2012 Mar;18(3):213-7. doi: 10.1111/j.1469-0691.2012.03781.x. | E26: Georgiades K | F26: Clin Microbiol Infect | G26: 2012 | H26: 40968 | K26: 10.1111/j.1469-0691.2012.03781.x | L26: =IF(ISNUMBER(VLOOKUP(A26,EXCL,1,FALSE)),"Excluido",IF(ISNUMBER(VLOOKUP(A26,POST,1,FALSE)),"PostAlerta",IF(ISNUMBER(VLOOKUP(A26,PRE,1,FALSE)),"PreAlerta",""))) -> Excluido | M26: =IF(ISNUMBER(A26),(IF(ISNUMBER(VLOOKUP(A26,KEYWORDS,1,FALSE)),"C/PalabrasClaves","S/PalabrasClaves")),"") -> S/PalabrasClaves | N26: =IF(ISNUMBER(SEARCH("TREATMENT", B26)), "4) Nuevos tratamientos", "") | P26: 2012 Mar | R26: =LEFT('2012-2022'!$P26,4) -> 2012 | S26: Mar
A27: 22374949 | B27: Complete genome sequence of Rickettsia slovaca, the agent of tick-borne lymphadenitis | C27: Fournier PE, El Karkouri K, Robert C, Médigue C, Raoult D. | D27: J Bacteriol. 2012 Mar;194(6):1612. doi: 10.1128/JB.06625-11. | E27: Fournier PE | F27: J Bacteriol | G27: 2012 | H27: 40969 | I27: PMC3294842 | K27: 10.1128/JB.06625-11 | L27: =IF(ISNUMBER(VLOOKUP(A27,EXCL,1,FALSE)),"Excluido",IF(ISNUMBER(VLOOKUP(A27,POST,1,FALSE)),"PostAlerta",IF(ISNUMBER(VLOOKUP(A27,PRE,1,FALSE)),"PreAlerta",""))) -> PreAlerta | M27: =IF(ISNUMBER(A27),(IF(ISNUMBER(VLOOKUP(A27,KEYWORDS,1,FALSE)),"C/PalabrasClaves","S/PalabrasClaves")),"") -> S/PalabrasClaves | N27: =IF(ISNUMBER(SEARCH("TREATMENT", B27)), "4) Nuevos tratamientos", "") | P27: 2012 Mar | R27: =LEFT('2012-2022'!$P27,4) -> 2012 | S27: Mar
A28: 22376001 | B28: Absence of linkage disequilibria between chromosomal arrangements and mtDNA haplotypes in natural populations of Drosophila subobscura from the Balkan Peninsula | C28: Jelić M, Castro JA, Kurbalija Novičić Z, Kenig B, Dimitrijević D, Savić Veselinović M, Jovanović M, Milovanović D, Stamenković-Radak M, Andjelković M. | D28: Genome. 2012 Mar;55(3):214-21. doi: 10.1139/g2012-004. Epub 2012 Feb 29. | E28: Jelić M | F28: Genome | G28: 2012 | H28: 40970 | K28: 10.1139/g2012-004 | L28: =IF(ISNUMBER(VLOOKUP(A28,EXCL,1,FALSE)),"Excluido",IF(ISNUMBER(VLOOKUP(A28,POST,1,FALSE)),"PostAlerta",IF(ISNUMBER(VLOOKUP(A28,PRE,1,FALSE)),"PreAlerta",""))) -> PreAlerta | M28: =IF(ISNUMBER(A28),(IF(ISNUMBER(VLOOKUP(A28,KEYWORDS,1,FALSE)),"C/PalabrasClaves","S/PalabrasClaves")),"") -> S/PalabrasClaves | N28: =IF(ISNUMBER(SEARCH("TREATMENT", B28)), "4) Nuevos tratamientos", "") | P28: 2012 Mar | R28: =LEFT('2012-2022'!$P28,4) -> 2012 | S28: Mar
A29: 22379331 | B29: Persistence of Orientia tsutsugamushi in humans | C29: Chung MH, Lee JS, Baek JH, Kim M, Kang JS. | D29: J Korean Med Sci. 2012 Mar;27(3):231-5. doi: 10.3346/jkms.2012.27.3.231. Epub 2012 Feb 23. | E29: Chung MH | F29: J Korean Med Sci | G29: 2012 | H29: 40970 | I29: PMC3286767 | K29: 10.3346/jkms.2012.27.3.231 | L29: =IF(ISNUMBER(VLOOKUP(A29,EXCL,1,FALSE)),"Excluido",IF(ISNUMBER(VLOOKUP(A29,POST,1,FALSE)),"PostAlerta",IF(ISNUMBER(VLOOKUP(A29,PRE,1,FALSE)),"PreAlerta",""))) -> PreAlerta | M29: =IF(ISNUMBER(A29),(IF(ISNUMBER(VLOOKUP(A29,KEYWORDS,1,FALSE)),"C/PalabrasClaves","S/PalabrasClaves")),"") -> S/PalabrasClaves | N29: =IF(ISNUMBER(SEARCH("TREATMENT", B29)), "4) Nuevos tratamientos", "") | P29: 2012 Mar | R29: =LEFT('2012-2022'!$P29,4) -> 2012 | S29: Mar
A30: 22380432 | B30: Maintenance of a male-killing Wolbachia in Drosophila innubila by male-killing dependent and male-killing independent mechanisms | C30: Unckless RL, Jaenike J. | D30: Evolution. 2012 Mar;66(3):678-689. doi: 10.1111/j.1558-5646.2011.01485.x. Epub 2011 Nov 11. | E30: Unckless RL | F30: Evolution | G30: 2012 | H30: 40971 | K30: 10.1111/j.1558-5646.2011.01485.x | L30: =IF(ISNUMBER(VLOOKUP(A30,EXCL,1,FALSE)),"Excluido",IF(ISNUMBER(VLOOKUP(A30,POST,1,FALSE)),"PostAlerta",IF(ISNUMBER(VLOOKUP(A30,PRE,1,FALSE)),"PreAlerta",""))) -> PreAlerta | M30: =IF(ISNUMBER(A30),(IF(ISNUMBER(VLOOKUP(A30,KEYWORDS,1,FALSE)),"C/PalabrasClaves","S/PalabrasClaves")),"") -> S/PalabrasClaves | N30: =IF(ISNUMBER(SEARCH("TREATMENT", B30)), "4) Nuevos tratamientos", "") | P30: 2012 Mar | R30: =LEFT('2012-2022'!$P30,4) -> 2012 | S30: Mar
A31: 22386178 | B31: Clinical findings and diagnosis in human granulocytic anaplasmosis: a case series from Massachusetts | C31: Weil AA, Baron EL, Brown CM, Drapkin MS. | D31: Mayo Clin Proc. 2012 Mar;87(3):233-9. doi: 10.1016/j.mayocp.2011.09.008. | E31: Weil AA | F31: Mayo Clin Proc | G31: 2012 | H31: 40974 | I31: PMC3498394 | K31: 10.1016/j.mayocp.2011.09.008 | L31: =IF(ISNUMBER(VLOOKUP(A31,EXCL,1,FALSE)),"Excluido",IF(ISNUMBER(VLOOKUP(A31,POST,1,FALSE)),"PostAlerta",IF(ISNUMBER(VLOOKUP(A31,PRE,1,FALSE)),"PreAlerta",""))) -> PreAlerta | M31: =IF(ISNUMBER(A31),(IF(ISNUMBER(VLOOKUP(A31,KEYWORDS,1,FALSE)),"C/PalabrasClaves","S/PalabrasClaves")),"") -> S/PalabrasClaves | N31: =IF(ISNUMBER(SEARCH("TREATMENT", B31)), "4) Nuevos tratamientos", "") | P31: 2012 Mar | R31: =LEFT('2012-2022'!$P31,4) -> 2012 | S31: Mar
A32: 22392278 | B32: Preliminary analysis to target pyruvate phosphate dikinase from wolbachia endosymbiont of Brugia malayi for designing anti-filarial agents | C32: Palayam M, Lakshminarayanan K, Radhakrishnan M, Krishnaswamy G. | D32: Interdiscip Sci. 2012 Mar;4(1):74-82. doi: 10.1007/s12539-011-0109-2. Epub 2012 Mar 6. | E32: Palayam M | F32: Interdiscip Sci | G32: 2012 | H32: 40975 | K32: 10.1007/s12539-011-0109-2 | L32: =IF(ISNUMBER(VLOOKUP(A32,EXCL,1,FALSE)),"Excluido",IF(ISNUMBER(VLOOKUP(A32,POST,1,FALSE)),"PostAlerta",IF(ISNUMBER(VLOOKUP(A32,PRE,1,FALSE)),"PreAlerta",""))) -> PreAlerta | M32: =IF(ISNUMBER(A32),(IF(ISNUMBER(VLOOKUP(A32,KEYWORDS,1,FALSE)),"C/PalabrasClaves","S/PalabrasClaves")),"") -> C/PalabrasClaves | N32: =IF(ISNUMBER(SEARCH("TREATMENT", B32)), "4) Nuevos tratamientos", "") | P32: 2012 Mar | R32: =LEFT('2012-2022'!$P32,4) -> 2012 | S32: Mar
A33: 22484753 | B33: Rickettsial diseases in central India | C33: Mohta A. | D33: Indian Pediatr. 2012 Mar;49(3):251; discussion 251-2. | E33: Mohta A | F33: Indian Pediatr | G33: 2012 | H33: 41009 | L33: =IF(ISNUMBER(VLOOKUP(A33,EXCL,1,FALSE)),"Excluido",IF(ISNUMBER(VLOOKUP(A33,POST,1,FALSE)),"PostAlerta",IF(ISNUMBER(VLOOKUP(A33,PRE,1,FALSE)),"PreAlerta",""))) -> PreAlerta | M33: =IF(ISNUMBER(A33),(IF(ISNUMBER(VLOOKUP(A33,KEYWORDS,1,FALSE)),"C/PalabrasClaves","S/PalabrasClaves")),"") -> S/PalabrasClaves | N33: =IF(ISNUMBER(SEARCH("TREATMENT", B33)), "4) Nuevos tratamientos", "") | P33: 2012 Mar | R33: =LEFT('2012-2022'!$P33,4) -> 2012 | S33: Mar
A34: 22515036 | B34: Seroprevalence and bacteremia [corrected] of Anaplasma phagocytophilum in cats from Bavaria and Lower Saxony (Germany) | C34: Hamel D, Bondarenko A, Silaghi C, Nolte I, Pfister K. | D34: Berl Munch Tierarztl Wochenschr. 2012 Mar-Apr;125(3-4):163-7. | E34: Hamel D | F34: Berl Munch Tierarztl Wochenschr | G34: 2012 | H34: 41020 | L34: =IF(ISNUMBER(VLOOKUP(A34,EXCL,1,FALSE)),"Excluido",IF(ISNUMBER(VLOOKUP(A34,POST,1,FALSE)),"PostAlerta",IF(ISNUMBER(VLOOKUP(A34,PRE,1,FALSE)),"PreAlerta",""))) -> PreAlerta | M34: =IF(ISNUMBER(A34),(IF(ISNUMBER(VLOOKUP(A34,KEYWORDS,1,FALSE)),"C/PalabrasClaves","S/PalabrasClaves")),"") -> S/PalabrasClaves | N34: =IF(ISNUMBER(SEARCH("TREATMENT", B34)), "4) Nuevos tratamientos", "") | P34: 2012 Apr | R34: =LEFT('2012-2022'!$P34,4) -> 2012 | S34: Apr
A35: 22543604 | B35: Comparative seroprevalences of bovine trypanosomiasis and anaplasmosis in five states of Malaysia | C35: Rahman WA, Fong S, Chandrawathani P, Nurulaini R, Zaini CM, Premalaatha B. | D35: Trop Biomed. 2012 Mar;29(1):65-70. | E35: Rahman WA | F35: Trop Biomed | G35: 2012 | H35: 41030 | L35: =IF(ISNUMBER(VLOOKUP(A35,EXCL,1,FALSE)),"Excluido",IF(ISNUMBER(VLOOKUP(A35,POST,1,FALSE)),"PostAlerta",IF(ISNUMBER(VLOOKUP(A35,PRE,1,FALSE)),"PreAlerta",""))) -> PreAlerta | M35: =IF(ISNUMBER(A35),(IF(ISNUMBER(VLOOKUP(A35,KEYWORDS,1,FALSE)),"C/PalabrasClaves","S/PalabrasClaves")),"") -> S/PalabrasClaves | N35: =IF(ISNUMBER(SEARCH("TREATMENT", B35)), "4) Nuevos tratamientos", "") | P35: 2012 Mar | R35: =LEFT('2012-2022'!$P35,4) -> 2012 | S35: Mar
A36: 22585246 | B36: Pleuropulmonary scrub typhus: a summary of Thai cases | C36: Wiwanitkit S, Wiwanitkit V. | D36: J Vector Borne Dis. 2012 Mar;49(1):48. | E36: Wiwanitkit S | F36: J Vector Borne Dis | G36: 2012 | H36: 41045 | L36: =IF(ISNUMBER(VLOOKUP(A36,EXCL,1,FALSE)),"Excluido",IF(ISNUMBER(VLOOKUP(A36,POST,1,FALSE)),"PostAlerta",IF(ISNUMBER(VLOOKUP(A36,PRE,1,FALSE)),"PreAlerta",""))) -> PreAlerta | M36: =IF(ISNUMBER(A36),(IF(ISNUMBER(VLOOKUP(A36,KEYWORDS,1,FALSE)),"C/PalabrasClaves","S/PalabrasClaves")),"") -> S/PalabrasClaves | N36: =IF(ISNUMBER(SEARCH("TREATMENT", B36)), "4) Nuevos tratamientos", "") | P36: 2012 Mar | R36: =LEFT('2012-2022'!$P36,4) -> 2012 | S36: Mar
A37: 22595273 | B37: Molecular detection and analysis of spotted fever group Rickettsia in patients with fever and rash at a tertiary care centre in Tamil Nadu, India | C37: Prakash JA, Sohan Lal T, Rosemol V, Verghese VP, Pulimood SA, Reller M, Dumler JS. | D37: Pathog Glob Health. 2012 Mar;106(1):40-5. doi: 10.1179/2047773212Y.0000000001. | E37: Prakash JA | F37: Pathog Glob Health | G37: 2012 | H37: 41048 | I37: PMC4001510 | K37: 10.1179/2047773212Y.0000000001 | L37: =IF(ISNUMBER(VLOOKUP(A37,EXCL,1,FALSE)),"Excluido",IF(ISNUMBER(VLOOKUP(A37,POST,1,FALSE)),"PostAlerta",IF(ISNUMBER(VLOOKUP(A37,PRE,1,FALSE)),"PreAlerta",""))) -> PreAlerta | M37: =IF(ISNUMBER(A37),(IF(ISNUMBER(VLOOKUP(A37,KEYWORDS,1,FALSE)),"C/PalabrasClaves","S/PalabrasClaves")),"") -> S/PalabrasClaves | N37: =IF(ISNUMBER(SEARCH("TREATMENT", B37)), "4) Nuevos tratamientos", "") | P37: 2012 Mar | R37: =LEFT('2012-2022'!$P37,4) -> 2012 | S37: Mar
A38: 22383821 | B38: Didier Raoult profile. Sound and fury in the microbiology lab | C38: Mary C. | D38: Science. 2012 Mar 2;335(6072):1033-5. doi: 10.1126/science.335.6072.1033. | E38: Mary C | F38: Science | G38: 2012 | H38: 40971 | K38: 10.1126/science.335.6072.1033 | L38: =IF(ISNUMBER(VLOOKUP(A38,EXCL,1,FALSE)),"Excluido",IF(ISNUMBER(VLOOKUP(A38,POST,1,FALSE)),"PostAlerta",IF(ISNUMBER(VLOOKUP(A38,PRE,1,FALSE)),"PreAlerta",""))) -> PreAlerta | M38: =IF(ISNUMBER(A38),(IF(ISNUMBER(VLOOKUP(A38,KEYWORDS,1,FALSE)),"C/PalabrasClaves","S/PalabrasClaves")),"") -> S/PalabrasClaves | N38: =IF(ISNUMBER(SEARCH("TREATMENT", B38)), "4) Nuevos tratamientos", "") | P38: 2012 Mar 2 | R38: =LEFT('2012-2022'!$P38,4) -> 2012 | S38: Mar
A39: 22401583 | B39: First case of Anaplasma platys infection in a dog from Croatia | C39: Dyachenko V, Pantchev N, Balzer HJ, Meyersen A, Straubinger RK. | D39: Parasit Vectors. 2012 Mar 9;5:49. doi: 10.1186/1756-3305-5-49. | E39: Dyachenko V | F39: Parasit Vectors | G39: 2012 | H39: 40978 | I39: PMC3315729 | K39: 10.1186/1756-3305-5-49 | L39: =IF(ISNUMBER(VLOOKUP(A39,EXCL,1,FALSE)),"Excluido",IF(ISNUMBER(VLOOKUP(A39,POST,1,FALSE)),"PostAlerta",IF(ISNUMBER(VLOOKUP(A39,PRE,1,FALSE)),"PreAlerta",""))) -> PreAlerta | M39: =IF(ISNUMBER(A39),(IF(ISNUMBER(VLOOKUP(A39,KEYWORDS,1,FALSE)),"C/PalabrasClaves","S/PalabrasClaves")),"") -> S/PalabrasClaves | N39: =IF(ISNUMBER(SEARCH("TREATMENT", B39)), "4) Nuevos tratamientos", "") | P39: 2012 Mar 9 | R39: =LEFT('2012-2022'!$P39,4) -> 2012 | S39: Mar
A40: 22433114 | B40: Long term impact of large scale community-directed delivery of doxycycline for the treatment of onchocerciasis | C40: Tamarozzi F, Tendongfor N, Enyong PA, Esum M, Faragher B, Wanji S, Taylor MJ. | D40: Parasit Vectors. 2012 Mar 20;5:53. doi: 10.1186/1756-3305-5-53. | E40: Tamarozzi F | F40: Parasit Vectors | G40: 2012 | H40: 40990 | I40: PMC3350421 | K40: 10.1186/1756-3305-5-53 | L40: =IF(ISNUMBER(VLOOKUP(A40,EXCL,1,FALSE)),"Excluido",IF(ISNUMBER(VLOOKUP(A40,POST,1,FALSE)),"PostAlerta",IF(ISNUMBER(VLOOKUP(A40,PRE,1,FALSE)),"PreAlerta",""))) -> PreAlerta | M40: =IF(ISNUMBER(A40),(IF(ISNUMBER(VLOOKUP(A40,KEYWORDS,1,FALSE)),"C/PalabrasClaves","S/PalabrasClaves")),"") -> S/PalabrasClaves | P40: 2012 Mar 20 | R40: =LEFT('2012-2022'!$P40,4) -> 2012 | S40: Mar
...

Sheet 2012-2017
A1: PMID | B1: Title | C1: Authors | D1: Citation | E1: First Author | F1: Journal/Book | G1: Publication Year | H1: Create Date | I1: PMCID | J1: NIHMS ID | K1: DOI
A2: 26467958 | B2: Modification of Insect and Arachnid Behaviours by Vertically Transmitted Endosymbionts: Infections as Drivers of Behavioural Change and Evolutionary Novelty | C2: Goodacre SL, Martin OY. | D2: Insects. 2012 Feb 29;3(1):246-61. doi: 10.3390/insects3010246. | E2: Goodacre SL | F2: Insects | G2: 2012 | H2: 42293 | I2: PMC4553626 | K2: 10.3390/insects3010246
A3: 21668575 | B3: Histopathological diagnosis of Japanese spotted fever using formalin-fixed, paraffin-embedded skin biopsy specimens: usefulness of immunohistochemistry and real-time PCR analysis | C3: Tamakuma K, Mizutani Y, Ito M, Shiogama K, Inada K, Miyamoto K, Utsunomiya H, Mahara F, Tsutsumi Y. | D3: Clin Microbiol Infect. 2012 Mar;18(3):260-7. doi: 10.1111/j.1469-0691.2011.03569.x. Epub 2011 Jun 10. | E3: Tamakuma K | F3: Clin Microbiol Infect | G3: 2012 | H3: 40709 | K3: 10.1111/j.1469-0691.2011.03569.x
A4: 21781141 | B4: Expression of heat shock proteins and subolesin affects stress responses, Anaplasma phagocytophilum infection and questing behaviour in the tick, Ixodes scapularis | C4: Busby AT, Ayllón N, Kocan KM, Blouin EF, de la Fuente G, Galindo RC, Villar M, de la Fuente J. | D4: Med Vet Entomol. 2012 Mar;26(1):92-102. doi: 10.1111/j.1365-2915.2011.00973.x. Epub 2011 Jul 22. | E4: Busby AT | F4: Med Vet Entomol | G4: 2012 | H4: 40750 | K4: 10.1111/j.1365-2915.2011.00973.x
A5: 21785920 | B5: Diplorickettsia massiliensis as a human pathogen | C5: Subramanian G, Mediannikov O, Angelakis E, Socolovschi C, Kaplanski G, Martzolff L, Raoult D. | D5: Eur J Clin Microbiol Infect Dis. 2012 Mar;31(3):365-9. doi: 10.1007/s10096-011-1318-7. Epub 2011 Jul 22. | E5: Subramanian G | F5: Eur J Clin Microbiol Infect Dis | G5: 2012 | H5: 40750 | K5: 10.1007/s10096-011-1318-7
A6: 21842137 | B6: Correlations among Anaplasma marginale parasitemia and markers of oxidative stress in crossbred calves | C6: De UK, Dey S, Banerjee PS, Sahoo M. | D6: Trop Anim Health Prod. 2012 Mar;44(3):385-8. doi: 10.1007/s11250-011-9938-6. Epub 2011 Aug 13. | E6: De UK | F6: Trop Anim Health Prod | G6: 2012 | H6: 40771 | K6: 10.1007/s11250-011-9938-6
A7: 21934703 | B7: Occasional males in parthenogenetic populations of Asobara japonica (Hymenoptera: Braconidae): low Wolbachia titer or incomplete coadaptation? | C7: Reumer BM, van Alphen JJ, Kraaijeveld K. | D7: Heredity (Edinb). 2012 Mar;108(3):341-6. doi: 10.1038/hdy.2011.82. Epub 2011 Sep 21. | E7: Reumer BM | F7: Heredity (Edinb) | G7: 2012 | H7: 40808 | I7: PMC3282404 | K7: 10.1038/hdy.2011.82
A8: 21938022 | B8: Unveiling in situ interactions between marine protists and bacteria through single cell sequencing | C8: Martinez-Garcia M, Brazel D, Poulton NJ, Swan BK, Gomez ML, Masland D, Sieracki ME, Stepanauskas R. | D8: ISME J. 2012 Mar;6(3):703-7. doi: 10.1038/ismej.2011.126. Epub 2011 Sep 22. | E8: Martinez-Garcia M | F8: ISME J | G8: 2012 | H8: 40809 | I8: PMC3280149 | K8: 10.1038/ismej.2011.126
A9: 22022815 | B9: Detection of Rickettsia parkeri and Candidatus Rickettsia andeanae in Amblyomma maculatum Gulf Coast ticks collected from humans in the United States | C9: Jiang J, Stromdahl EY, Richards AL. | D9: Vector Borne Zoonotic Dis. 2012 Mar;12(3):175-82. doi: 10.1089/vbz.2011.0614. Epub 2011 Oct 24. | E9: Jiang J | F9: Vector Borne Zoonotic Dis | G9: 2012 | H9: 40842 | K9: 10.1089/vbz.2011.0614
A10: 22076027 | B10: Cross-effects of nickel contamination and parasitism on zebra mussel physiology | C10: Minguez L, Boiché A, Sroda S, Mastitsky S, Brulé N, Bouquerel J, Giambérini L. | D10: Ecotoxicology. 2012 Mar;21(2):538-47. doi: 10.1007/s10646-011-0814-y. Epub 2011 Nov 12. | E10: Minguez L | F10: Ecotoxicology | G10: 2012 | H10: 40862 | K10: 10.1007/s10646-011-0814-y
A11: 22159737 | B11: Polyclonal antibody against conserved sequences of mce1A protein blocks MTB infection in macrophages | C11: Sivagnanam S, Namasivayam N, Chellam R. | D11: Appl Microbiol Biotechnol. 2012 Mar;93(6):2463-73. doi: 10.1007/s00253-011-3754-9. Epub 2011 Dec 13. | E11: Sivagnanam S | F11: Appl Microbiol Biotechnol | G11: 2012 | H11: 40891 | K11: 10.1007/s00253-011-3754-9
A12: 22172602 | B12: Infections with Wolbachia and Spiroplasma in the Scathophagidae and other Muscoidea | C12: Martin OY, Gubler A, Wimmer C, Germann C, Bernasconi MV. | D12: Infect Genet Evol. 2012 Mar;12(2):315-23. doi: 10.1016/j.meegid.2011.11.012. Epub 2011 Dec 8. | E12: Martin OY | F12: Infect Genet Evol | G12: 2012 | H12: 40894 | K12: 10.1016/j.meegid.2011.11.012
A13: 22205824 | B13: "Candidatus Neoehrlichia mikurensis," Anaplasma phagocytophilum, and lyme disease spirochetes in questing european vector ticks and in feeding ticks removed from people | C13: Richter D, Matuschka FR. | D13: J Clin Microbiol. 2012 Mar;50(3):943-7. doi: 10.1128/JCM.05802-11. Epub 2012 Jan 11. | E13: Richter D | F13: J Clin Microbiol | G13: 2012 | H13: 40907 | I13: PMC3295140 | K13: 10.1128/JCM.05802-11
A14: 22210220 | B14: Wolbachia strain wAlbB enhances infection by the rodent malaria parasite Plasmodium berghei in Anopheles gambiae mosquitoes | C14: Hughes GL, Vega-Rodriguez J, Xue P, Rasgon JL. | D14: Appl Environ Microbiol. 2012 Mar;78(5):1491-5. doi: 10.1128/AEM.06751-11. Epub 2011 Dec 30. | E14: Hughes GL | F14: Appl Environ Microbiol | G14: 2012 | H14: 40911 | I14: PMC3294472 | K14: 10.1128/AEM.06751-11
A15: 22214329 | B15: Wolbachia and its implications for the immunopathology of filariasis | C15: Genchi C, Kramer LH, Sassera D, Bandi C. | D15: Endocr Metab Immune Disord Drug Targets. 2012 Mar;12(1):53-6. doi: 10.2174/187153012799279108. | E15: Genchi C | F15: Endocr Metab Immune Disord Drug Targets | G15: 2012 | H15: 40913 | K15: 10.2174/187153012799279108
A16: 22219313 | B16: Prospective evaluation of commercial antibody-based rapid tests in combination with a loop-mediated isothermal amplification PCR assay for detection of Orientia tsutsugamushi during the acute phase of scrub typhus infection | C16: Blacksell SD, Paris DH, Chierakul W, Wuthiekanun V, Teeratakul A, Kantipong P, Day NP. | D16: Clin Vaccine Immunol. 2012 Mar;19(3):391-5. doi: 10.1128/CVI.05478-11. Epub 2012 Jan 4. | E16: Blacksell SD | F16: Clin Vaccine Immunol | G16: 2012 | H16: 40914 | I16: PMC3294598 | K16: 10.1128/CVI.05478-11
A17: 22222114 | B17: Rickettsiae in arthropods collected from the North African Hedgehog (Atelerix algirus) and the desert hedgehog (Paraechinus aethiopicus) in Algeria | C17: Khaldi M, Socolovschi C, Benyettou M, Barech G, Biche M, Kernif T, Raoult D, Parola P. | D17: Comp Immunol Microbiol Infect Dis. 2012 Mar;35(2):117-22. doi: 10.1016/j.cimid.2011.11.007. Epub 2012 Jan 4. | E17: Khaldi M | F17: Comp Immunol Microbiol Infect Dis | G17: 2012 | H17: 40915 | K17: 10.1016/j.cimid.2011.11.007
A18: 22257655 | B18: A case of rickettsialpox in Northern Europe | C18: Renvoisé A, van't Wout JW, van der Schroeff JG, Beersma MF, Raoult D. | D18: Int J Infect Dis. 2012 Mar;16(3):e221-2. doi: 10.1016/j.ijid.2011.11.009. Epub 2012 Jan 17. | E18: Renvoisé A | F18: Int J Infect Dis | G18: 2012 | H18: 40928 | K18: 10.1016/j.ijid.2011.11.009
A19: 22266203 | B19: Presence and distribution of the endosymbiont Wolbachia among Solenopsis spp. (Hymenoptera: Formicidae) from Brazil and its evolutionary history | C19: Martins C, Souza RF, Bueno OC. | D19: J Invertebr Pathol. 2012 Mar;109(3):287-96. doi: 10.1016/j.jip.2012.01.001. Epub 2012 Jan 12. | E19: Martins C | F19: J Invertebr Pathol | G19: 2012 | H19: 40932 | K19: 10.1016/j.jip.2012.01.001
A20: 22268975 | B20: Integration of molecular, ecological, morphological and endosymbiont data for species delimitation within the Pnigalio soemius complex (Hymenoptera: Eulophidae) | C20: Gebiola M, Gómez-Zurita J, Monti MM, Navone P, Bernardo U. | D20: Mol Ecol. 2012 Mar;21(5):1190-208. doi: 10.1111/j.1365-294X.2011.05428.x. Epub 2012 Jan 23. | E20: Gebiola M | F20: Mol Ecol | G20: 2012 | H20: 40933 | K20: 10.1111/j.1365-294X.2011.05428.x
A21: 22277830 | B21: New Rickettsia sp. in tsetse flies from Senegal | C21: Mediannikov O, Audoly G, Diatta G, Trape JF, Raoult D. | D21: Comp Immunol Microbiol Infect Dis. 2012 Mar;35(2):145-50. doi: 10.1016/j.cimid.2011.12.011. Epub 2012 Jan 23. | E21: Mediannikov O | F21: Comp Immunol Microbiol Infect Dis | G21: 2012 | H21: 40935 | K21: 10.1016/j.cimid.2011.12.011
A22: 22282331 | B22: Tetracyclines and pain | C22: Bastos LF, de Oliveira AC, Watkins LR, Moraes MF, Coelho MM. | D22: Naunyn Schmiedebergs Arch Pharmacol. 2012 Mar;385(3):225-41. doi: 10.1007/s00210-012-0727-1. Epub 2012 Jan 27. | E22: Bastos LF | F22: Naunyn Schmiedebergs Arch Pharmacol | G22: 2012 | H22: 40936 | K22: 10.1007/s00210-012-0727-1
A23: 22293464 | B23: Diversity and phylogenetic analysis of endosymbiotic bacteria from field caught Bemisia tabaci from different locations of North India based on 16S rDNA library screening | C23: Singh ST, Priya NG, Kumar J, Rana VS, Ellango R, Joshi A, Priyadarshini G, Asokan R, Rajagopal R. | D23: Infect Genet Evol. 2012 Mar;12(2):411-9. doi: 10.1016/j.meegid.2012.01.015. Epub 2012 Jan 24. | E23: Singh ST | F23: Infect Genet Evol | G23: 2012 | H23: 40941 | K23: 10.1016/j.meegid.2012.01.015
A24: 22305337 | B24: Molecular detection and characterization of Anaplasma phagocytophilum strains | C24: Paulauskas A, Radzijevskaja J, Rosef O. | D24: Comp Immunol Microbiol Infect Dis. 2012 Mar;35(2):187-95. doi: 10.1016/j.cimid.2012.01.001. Epub 2012 Feb 3. | E24: Paulauskas A | F24: Comp Immunol Microbiol Infect Dis | G24: 2012 | H24: 40946 | K24: 10.1016/j.cimid.2012.01.001
A25: 22321996 | B25: Human granulocytic anaplasmosis in eastern France: clinical presentation and laboratory diagnosis | C25: Koebel C, Kern A, Edouard S, Hoang AT, Celestin N, Hansmann Y, Jaulhac B, Brouqui P, De Martino SJ. | D25: Diagn Microbiol Infect Dis. 2012 Mar;72(3):214-8. doi: 10.1016/j.diagmicrobio.2011.12.005. | E25: Koebel C | F25: Diagn Microbiol Infect Dis | G25: 2012 | H25: 40950 | K25: 10.1016/j.diagmicrobio.2011.12.005
A26: 22369153 | B26: Genomics of epidemic pathogens | C26: Georgiades K. | D26: Clin Microbiol Infect. 2012 Mar;18(3):213-7. doi: 10.1111/j.1469-0691.2012.03781.x. | E26: Georgiades K | F26: Clin Microbiol Infect | G26: 2012 | H26: 40968 | K26: 10.1111/j.1469-0691.2012.03781.x
A27: 22374949 | B27: Complete genome sequence of Rickettsia slovaca, the agent of tick-borne lymphadenitis | C27: Fournier PE, El Karkouri K, Robert C, Médigue C, Raoult D. | D27: J Bacteriol. 2012 Mar;194(6):1612. doi: 10.1128/JB.06625-11. | E27: Fournier PE | F27: J Bacteriol | G27: 2012 | H27: 40969 | I27: PMC3294842 | K27: 10.1128/JB.06625-11
A28: 22376001 | B28: Absence of linkage disequilibria between chromosomal arrangements and mtDNA haplotypes in natural populations of Drosophila subobscura from the Balkan Peninsula | C28: Jelić M, Castro JA, Kurbalija Novičić Z, Kenig B, Dimitrijević D, Savić Veselinović M, Jovanović M, Milovanović D, Stamenković-Radak M, Andjelković M. | D28: Genome. 2012 Mar;55(3):214-21. doi: 10.1139/g2012-004. Epub 2012 Feb 29. | E28: Jelić M | F28: Genome | G28: 2012 | H28: 40970 | K28: 10.1139/g2012-004
A29: 22379331 | B29: Persistence of Orientia tsutsugamushi in humans | C29: Chung MH, Lee JS, Baek JH, Kim M, Kang JS. | D29: J Korean Med Sci. 2012 Mar;27(3):231-5. doi: 10.3346/jkms.2012.27.3.231. Epub 2012 Feb 23. | E29: Chung MH | F29: J Korean Med Sci | G29: 2012 | H29: 40970 | I29: PMC3286767 | K29: 10.3346/jkms.2012.27.3.231
A30: 22380432 | B30: Maintenance of a male-killing Wolbachia in Drosophila innubila by male-killing dependent and male-killing independent mechanisms | C30: Unckless RL, Jaenike J. | D30: Evolution. 2012 Mar;66(3):678-689. doi: 10.1111/j.1558-5646.2011.01485.x. Epub 2011 Nov 11. | E30: Unckless RL | F30: Evolution | G30: 2012 | H30: 40971 | K30: 10.1111/j.1558-5646.2011.01485.x
A31: 22386178 | B31: Clinical findings and diagnosis in human granulocytic anaplasmosis: a case series from Massachusetts | C31: Weil AA, Baron EL, Brown CM, Drapkin MS. | D31: Mayo Clin Proc. 2012 Mar;87(3):233-9. doi: 10.1016/j.mayocp.2011.09.008. | E31: Weil AA | F31: Mayo Clin Proc | G31: 2012 | H31: 40974 | I31: PMC3498394 | K31: 10.1016/j.mayocp.2011.09.008
A32: 22392278 | B32: Preliminary analysis to target pyruvate phosphate dikinase from wolbachia endosymbiont of Brugia malayi for designing anti-filarial agents | C32: Palayam M, Lakshminarayanan K, Radhakrishnan M, Krishnaswamy G. | D32: Interdiscip Sci. 2012 Mar;4(1):74-82. doi: 10.1007/s12539-011-0109-2. Epub 2012 Mar 6. | E32: Palayam M | F32: Interdiscip Sci | G32: 2012 | H32: 40975 | K32: 10.1007/s12539-011-0109-2
A33: 22484753 | B33: Rickettsial diseases in central India | C33: Mohta A. | D33: Indian Pediatr. 2012 Mar;49(3):251; discussion 251-2. | E33: Mohta A | F33: Indian Pediatr | G33: 2012 | H33: 41009
A34: 22515036 | B34: Seroprevalence and bacteremia [corrected] of Anaplasma phagocytophilum in cats from Bavaria and Lower Saxony (Germany) | C34: Hamel D, Bondarenko A, Silaghi C, Nolte I, Pfister K. | D34: Berl Munch Tierarztl Wochenschr. 2012 Mar-Apr;125(3-4):163-7. | E34: Hamel D | F34: Berl Munch Tierarztl Wochenschr | G34: 2012 | H34: 41020
A35: 22543604 | B35: Comparative seroprevalences of bovine trypanosomiasis and anaplasmosis in five states of Malaysia | C35: Rahman WA, Fong S, Chandrawathani P, Nurulaini R, Zaini CM, Premalaatha B. | D35: Trop Biomed. 2012 Mar;29(1):65-70. | E35: Rahman WA | F35: Trop Biomed | G35: 2012 | H35: 41030
A36: 22585246 | B36: Pleuropulmonary scrub typhus: a summary of Thai cases | C36: Wiwanitkit S, Wiwanitkit V. | D36: J Vector Borne Dis. 2012 Mar;49(1):48. | E36: Wiwanitkit S | F36: J Vector Borne Dis | G36: 2012 | H36: 41045
A37: 22595273 | B37: Molecular detection and analysis of spotted fever group Rickettsia in patients with fever and rash at a tertiary care centre in Tamil Nadu, India | C37: Prakash JA, Sohan Lal T, Rosemol V, Verghese VP, Pulimood SA, Reller M, Dumler JS. | D37: Pathog Glob Health. 2012 Mar;106(1):40-5. doi: 10.1179/2047773212Y.0000000001. | E37: Prakash JA | F37: Pathog Glob Health | G37: 2012 | H37: 41048 | I37: PMC4001510 | K37: 10.1179/2047773212Y.0000000001
A38: 22383821 | B38: Didier Raoult profile. Sound and fury in the microbiology lab | C38: Mary C. | D38: Science. 2012 Mar 2;335(6072):1033-5. doi: 10.1126/science.335.6072.1033. | E38: Mary C | F38: Science | G38: 2012 | H38: 40971 | K38: 10.1126/science.335.6072.1033
A39: 22401583 | B39: First case of Anaplasma platys infection in a dog from Croatia | C39: Dyachenko V, Pantchev N, Balzer HJ, Meyersen A, Straubinger RK. | D39: Parasit Vectors. 2012 Mar 9;5:49. doi: 10.1186/1756-3305-5-49. | E39: Dyachenko V | F39: Parasit Vectors | G39: 2012 | H39: 40978 | I39: PMC3315729 | K39: 10.1186/1756-3305-5-49
A40: 22433114 | B40: Long term impact of large scale community-directed delivery of doxycycline for the treatment of onchocerciasis | C40: Tamarozzi F, Tendongfor N, Enyong PA, Esum M, Faragher B, Wanji S, Taylor MJ. | D40: Parasit Vectors. 2012 Mar 20;5:53. doi: 10.1186/1756-3305-5-53. | E40: Tamarozzi F | F40: Parasit Vectors | G40: 2012 | H40: 40990 | I40: PMC3350421 | K40: 10.1186/1756-3305-5-53
...

Sheet 2017-2022
A1: PMID | B1: Title | C1: Authors | D1: Citation | E1: First Author | F1: Journal/Book | G1: Publication Year | H1: Create Date | I1: PMCID | J1: NIHMS ID | K1: DOI
A2: 28241043 | B2: Use of eschar swabbing for the molecular diagnosis and genotyping of Orientia tsutsugamushi causing scrub typhus in Quang Nam province, Vietnam | C2: Le Viet N, Laroche M, Thi Pham HL, Viet NL, Mediannikov O, Raoult D, Parola P. | D2: PLoS Negl Trop Dis. 2017 Feb 27;11(2):e0005397. doi: 10.1371/journal.pntd.0005397. eCollection 2017 Feb. | E2: Le Viet N | F2: PLoS Negl Trop Dis | G2: 2017 | H2: 42794 | I2: PMC5344524 | K2: 10.1371/journal.pntd.0005397
A3: 28241784 | B3: Genetic profiling for Anaplasma and Ehrlichia species in ticks collected in the Eastern Cape Province of South Africa | C3: Iweriebor BC, Mmbaga EJ, Adegborioye A, Igwaran A, Obi LC, Okoh AI. | D3: BMC Microbiol. 2017 Feb 27;17(1):45. doi: 10.1186/s12866-017-0955-0. | E3: Iweriebor BC | F3: BMC Microbiol | G3: 2017 | H3: 42795 | I3: PMC5327538 | K3: 10.1186/s12866-017-0955-0
A4: 28241782 | B4: Molecular detection and identification of Wolbachia in three species of the genus Lutzomyia on the Colombian Caribbean coast | C4: Vivero RJ, Cadavid-Restrepo G, Herrera CX, Soto SI. | D4: Parasit Vectors. 2017 Feb 28;10(1):110. doi: 10.1186/s13071-017-2031-x. | E4: Vivero RJ | F4: Parasit Vectors | G4: 2017 | H4: 42795 | I4: PMC5329942 | K4: 10.1186/s13071-017-2031-x
A5: 27628851 | B5: Two-sex mosquito model for the persistence of Wolbachia | C5: Xue L, Manore CA, Thongsripong P, Hyman JM. | D5: J Biol Dyn. 2017 Mar;11(sup1):216-237. doi: 10.1080/17513758.2016.1229051. Epub 2016 Sep 14. | E5: Xue L | F5: J Biol Dyn | G5: 2017 | H5: 42629 | K5: 10.1080/17513758.2016.1229051
A6: 27731327 | B6: Incomplete offspring sex bias in Australian populations of the butterfly Eurema hecabe | C6: Kemp DJ, Thomson FE, Edwards W, Iturbe-Ormaetxe I. | D6: Heredity (Edinb). 2017 Mar;118(3):284-292. doi: 10.1038/hdy.2016.85. Epub 2016 Oct 12. | E6: Kemp DJ | F6: Heredity (Edinb) | G6: 2017 | H6: 42656 | I6: PMC5315524 | K6: 10.1038/hdy.2016.85
A7: 27773866 | B7: Rickettsia parkeri and "Candidatus Rickettsia andeanae" in Questing Amblyomma maculatum (Acari: Ixodidae) From Mississippi | C7: Lee JK, Moraru GM, Stokes JV, Wills RW, Mitchell E, Unz E, Moore-Henderson B, Harper AB, Varela-Stokes AS. | D7: J Med Entomol. 2017 Mar 1;54(2):476-480. doi: 10.1093/jme/tjw175. | E7: Lee JK | F7: J Med Entomol | G7: 2017 | H7: 42668 | I7: PMC5850715 | K7: 10.1093/jme/tjw175
A8: 27939332 | B8: Phylogenetic relationship and genotypic variability in Anaplasma marginale strains causing anaplasmosis in India | C8: George N, Bhandari V, Sharma P. | D8: Infect Genet Evol. 2017 Mar;48:71-75. doi: 10.1016/j.meegid.2016.11.028. Epub 2016 Dec 6. | E8: George N | F8: Infect Genet Evol | G8: 2017 | H8: 42717 | K8: 10.1016/j.meegid.2016.11.028
A9: 27986544 | B9: "Candidatus Rickettsia asemboensis" in Rhipicephalus sanguineus ticks, Brazil | C9: Dall'Agnol B, Souza U, Webster A, Weck B, Stenzel B, Labruna M, Klafke G, Martins JR, Ferreira CAS, Reck J. | D9: Acta Trop. 2017 Mar;167:18-20. doi: 10.1016/j.actatropica.2016.12.008. Epub 2016 Dec 13. | E9: Dall'Agnol B | F9: Acta Trop | G9: 2017 | H9: 42722 | K9: 10.1016/j.actatropica.2016.12.008
A10: 27986546 | B10: Molecular epidemiological survey of bacterial and parasitic pathogens in hard ticks from eastern China | C10: Liu XY, Gong XY, Zheng C, Song QY, Chen T, Wang J, Zheng J, Deng HK, Zheng KY. | D10: Acta Trop. 2017 Mar;167:26-30. doi: 10.1016/j.actatropica.2016.12.010. Epub 2016 Dec 13. | E10: Liu XY | F10: Acta Trop | G10: 2017 | H10: 42722 | K10: 10.1016/j.actatropica.2016.12.010
A11: 27992288 | B11: Survey for Rickettsiae Within Fleas of Great Gerbils, Almaty Oblast, Kazakhstan | C11: Sansyzbayev Y, Nurmakhanov T, Berdibekov A, Vilkova A, Yeskhodzhayev O, St John HK, Jiang J, Farris CM, Richards AL. | D11: Vector Borne Zoonotic Dis. 2017 Mar;17(3):172-178. doi: 10.1089/vbz.2016.2049. Epub 2016 Dec 19. | E11: Sansyzbayev Y | F11: Vector Borne Zoonotic Dis | G11: 2017 | H11: 42724 | K11: 10.1089/vbz.2016.2049
A12: 27992293 | B12: Molecular Characterization of Anaplasma sp. in Free-Living Gray Brockets (Mazama gouazoubira) | C12: Mongruel AC, Benevenute JL, André MR, Carrasco AO, Machado RZ, Seki MC. | D12: Vector Borne Zoonotic Dis. 2017 Mar;17(3):165-171. doi: 10.1089/vbz.2016.2026. Epub 2016 Dec 19. | E12: Mongruel AC | F12: Vector Borne Zoonotic Dis | G12: 2017 | H12: 42724 | K12: 10.1089/vbz.2016.2026
A13: 27993973 | B13: Anaplasma marginale Outer Membrane Protein A Is an Adhesin That Recognizes Sialylated and Fucosylated Glycans and Functionally Depends on an Essential Binding Domain | C13: Hebert KS, Seidman D, Oki AT, Izac J, Emani S, Oliver LD Jr,, Miller DP, Tegels BK, Kannagi R, Marconi RT, Carlyon JA. | D13: Infect Immun. 2017 Feb 23;85(3):e00968-16. doi: 10.1128/IAI.00968-16. Print 2017 Mar. | E13: Hebert KS | F13: Infect Immun | G13: 2017 | H13: 42725 | I13: PMC5328490 | K13: 10.1128/IAI.00968-16
A14: 28011722 | B14: Evaluation of Doxycycline-Laden Oral Bait and Topical Fipronil Delivered in a Single Bait Box to Control Ixodes scapularis (Acari: Ixodidae) and Reduce Borrelia burgdorferi and Anaplasma phagocytophilum Infection in Small Mammal Reservoirs and Host-Seeking Ticks | C14: Dolan MC, Schulze TL, Jordan RA, Schulze CJ, Ullmann AJ, Hojgaard A, Williams MA, Piesman J. | D14: J Med Entomol. 2017 Mar 1;54(2):403-410. doi: 10.1093/jme/tjw194. | E14: Dolan MC | F14: J Med Entomol | G14: 2017 | H14: 42729 | I14: PMC5968630 | K14: 10.1093/jme/tjw194
A15: 28012903 | B15: Multiple-host pathogens in domestic hunting dogs in Nicaragua's Bosawás Biosphere Reserve | C15: Fiorello CV, Straub MH, Schwartz LM, Liu J, Campbell A, Kownacki AK, Foley JE. | D15: Acta Trop. 2017 Mar;167:183-190. doi: 10.1016/j.actatropica.2016.12.020. Epub 2016 Dec 21. | E15: Fiorello CV | F15: Acta Trop | G15: 2017 | H15: 42730 | K15: 10.1016/j.actatropica.2016.12.020
A16: 28026894 | B16: By their own devices: invasive Argentine ants have shifted diet without clear aid from symbiotic microbes | C16: Hu Y, Holway DA, Łukasik P, Chau L, Kay AD, LeBrun EG, Miller KA, Sanders JG, Suarez AV, Russell JA. | D16: Mol Ecol. 2017 Mar;26(6):1608-1630. doi: 10.1111/mec.13991. Epub 2017 Jan 27. | E16: Hu Y | F16: Mol Ecol | G16: 2017 | H16: 42732 | K16: 10.1111/mec.13991
