Workbook
Name categoria: categorias!$A:$A
Name Estado: categorias!$C$2:$C$65536
Name EXCL: Excluidas!$A:$K
Name EXCLUIDAS: Excluidas!$A$1:$K$463
Name KEYWORDS: 'Palabras claves'!$A:$K
Name NgonorreaePre: '2012-2017'!$A$1:$K$1
Name PalabrasClave: 'Palabras claves'!$K$1:$K$1371
Name POST: '2017-2022'!$A:$K
Name POSTALERTA: '2017-2022'!$A$1:$B$1
Name PRE: '2012-2017'!$A:$K
Name PREALERTA: '2012-2017'!$A$1:$O$1
Name SegmentaciónDeDatos_Alerta1: #REF!
Name SegmentaciónDeDatos_KeyWords: #REF!
Name SegmentaciónDeDatos_PubYear: #REF!
Name subcategoria: categorias!$B:$B
Name TablaNgonoreae: #REF!

Sheet DashBoard
C2: C. trachomatis 2012-2022
C3: Total de publicaciones de | F3: =C2 -> C. trachomatis 2012-2022 | G3: : | H3: =COUNTA('2012-2022'!$B$2:$B$15076) -> 4809
D5: Publicaciones por Año | I5: Categorías y Subcategorías
D17: Publicaciones por mes
C34: =IFERROR(__xludf.DUMMYFUNCTION("UNIQUE('2012-2022'!N:N)"),"Categoria") -> Categoria
C36: =IFERROR(__xludf.DUMMYFUNCTION("""COMPUTED_VALUE""")," 1) Reporte de cepas resistentes") -> 1) Reporte de cepas resistentes
C37: =IFERROR(__xludf.DUMMYFUNCTION("""COMPUTED_VALUE"""),"2) Nuevos tratamientos ") -> 2) Nuevos tratamientos | F37: =COUNTIF('2012-2022'!N:N,C37) -> 74
C38: =IFERROR(__xludf.DUMMYFUNCTION("""COMPUTED_VALUE"""),"4) otros") -> 4) otros | F38: =COUNTIF('2012-2022'!N:N,C38) -> 1627
C39: =IFERROR(__xludf.DUMMYFUNCTION("""COMPUTED_VALUE"""),"3) immunization") -> 3) immunization | F39: =COUNTIF('2012-2022'!N:N,C39) -> 72
C40: =IFERROR(__xludf.DUMMYFUNCTION("""COMPUTED_VALUE"""),"Categorias") -> Categorias | F40: =COUNTIF('2012-2022'!N:N,C40) -> 2
C41: =IFERROR(__xludf.DUMMYFUNCTION("""COMPUTED_VALUE"""),"3) Inmunizacióm") -> 3) Inmunizacióm | F41: =COUNTIF('2012-2022'!N:N,C41) -> 1
F42: =COUNTIF('2012-2022'!N:N,C42) -> 0
F43: =COUNTIF('2012-2022'!N:N,C43) -> 0

Sheet categorias
A1: Categorias | B1: Subcategorias | C1: Estados
A2: 1) Reporte de cepas resistentes | B2: 2a) Productos naturales | C2: Revisar
A3: 2) Nuevos tratamientos | B3: 2b) Péptidos | C3: Listo
A4: 3) Inmunizacióm | B4: 2c) Droga de diseño | C4: Excluir
A5: 4) otros | B5: 2d) Anticuerpos | C5: Otros-A
B6: 2e) Bacteriófagos | C6: Otros-B
B7: 2f) Estrategias antivirulencia | C7: Otros-C
B8: 2g) nueva combinación de ATB | C8: Otros-D

Sheet 2012-2022
A1: PMID | B1: Title | C1: Authors | D1: Citation | E1: First Author | F1: Journal/Book | G1: Publication Year | H1: Create Date | I1: PMCID | J1: NIHMS ID | K1: DOI | L1: Alerta | M1: KeyWords | N1: Categoria | O1: subcategoria | P1: fecha de publicación | Q1: Estado | R1: PubYear | S1: PubMonth | T1: Abstract | U1: 1) Antimicrobial Resistance stain | V1: 2) New treatment | W1: 3) Immunization | X1: Human_summary
A2: 22304240 | B2: O(2)-evolving chlorite dismutase as a tool for studying O(2)-utilizing enzymes | C2: Dassama LM, Yosca TH, Conner DA, Lee MH, Blanc B, Streit BR, Green MT, DuBois JL, Krebs C, Bollinger JM Jr. | D2: Biochemistry. 2012 Feb 28;51(8):1607-16. doi: 10.1021/bi201906x. Epub 2012 Feb 13. | E2: Dassama LM | F2: Biochemistry | G2: 2012 | H2: 40946 | I2: PMC3297476 | J2: NIHMS354219 | K2: 10.1021/bi201906x | L2: =IF(ISNUMBER(VLOOKUP(A2,EXCL,1,FALSE)),"Excluido",IF(ISNUMBER(VLOOKUP(A2,POST,1,FALSE)),"PostAlerta",IF(ISNUMBER(VLOOKUP(A2,PRE,1,FALSE)),"PreAlerta",""))) -> PreAlerta | M2: =IF(ISNUMBER(VLOOKUP(A2,KEYWORDS,1,FALSE)),"C/PalabrasClaves","S/PalabrasClaves") -> S/PalabrasClaves | Q2: Revisar
A3: 21848430 | B3: Differing effects of azithromycin and doxycycline on cytokines in cells from Chlamydia trachomatis-infected women | C3: Srivastava P, Bhengraj AR, Jha HC, Vardhan H, Jha R, Singh LC, Salhan S, Mittal A. | D3: DNA Cell Biol. 2012 Mar;31(3):392-401. doi: 10.1089/dna.2011.1333. Epub 2011 Aug 17. | E3: Srivastava P | F3: DNA Cell Biol | G3: 2012 | H3: 40774 | K3: 10.1089/dna.2011.1333 | L3: =IF(ISNUMBER(VLOOKUP(A3,EXCL,1,FALSE)),"Excluido",IF(ISNUMBER(VLOOKUP(A3,POST,1,FALSE)),"PostAlerta",IF(ISNUMBER(VLOOKUP(A3,PRE,1,FALSE)),"PreAlerta",""))) -> PreAlerta | M3: =IF(ISNUMBER(VLOOKUP(A3,KEYWORDS,1,FALSE)),"C/PalabrasClaves","S/PalabrasClaves") -> S/PalabrasClaves | Q3: Revisar
A4: 22042092 | B4: Absence of Swedish new variant Chlamydia trachomatis (nvCT) and C. trachomatis genotype distribution in Gipuzkoa, Spain, 2009-2010 | C4: Piñeiro L, Unemo M, Cilla G. | D4: Acta Derm Venereol. 2012 Mar;92(2):185-6. doi: 10.2340/00015555-1234. | E4: Piñeiro L | F4: Acta Derm Venereol | G4: 2012 | H4: 40849 | K4: 10.2340/00015555-1234 | L4: =IF(ISNUMBER(VLOOKUP(A4,EXCL,1,FALSE)),"Excluido",IF(ISNUMBER(VLOOKUP(A4,POST,1,FALSE)),"PostAlerta",IF(ISNUMBER(VLOOKUP(A4,PRE,1,FALSE)),"PreAlerta",""))) -> PreAlerta | M4: =IF(ISNUMBER(VLOOKUP(A4,KEYWORDS,1,FALSE)),"C/PalabrasClaves","S/PalabrasClaves") -> S/PalabrasClaves | Q4: Listo
A5: 22122734 | B5: Chlamydial infection during trachoma monitoring: are the most difficult-to-reach children more likely to be infected? | C5: Keenan JD, Moncada J, Gebre T, Ayele B, Chen MC, Yu SN, Emerson PM, Stoller NE, McCulloch CE, Gaynor BD, Schachter J. | D5: Trop Med Int Health. 2012 Mar;17(3):392-6. doi: 10.1111/j.1365-3156.2011.02919.x. Epub 2011 Nov 28. | E5: Keenan JD | F5: Trop Med Int Health | G5: 2012 | H5: 40877 | I5: PMC3292692 | J5: NIHMS334303 | K5: 10.1111/j.1365-3156.2011.02919.x | L5: =IF(ISNUMBER(VLOOKUP(A5,EXCL,1,FALSE)),"Excluido",IF(ISNUMBER(VLOOKUP(A5,POST,1,FALSE)),"PostAlerta",IF(ISNUMBER(VLOOKUP(A5,PRE,1,FALSE)),"PreAlerta",""))) -> Excluido | M5: =IF(ISNUMBER(VLOOKUP(A5,KEYWORDS,1,FALSE)),"C/PalabrasClaves","S/PalabrasClaves") -> S/PalabrasClaves | N5: 1) Reporte de cepas resistentes | Q5: Revisar
A6: 22142497 | B6: Prevalence of genital mycoplasmas and ureaplasmas in men younger than 40 years-of-age with acute epididymitis | C6: Ito S, Tsuchiya T, Yasuda M, Yokoi S, Nakano M, Deguchi T. | D6: Int J Urol. 2012 Mar;19(3):234-8. doi: 10.1111/j.1442-2042.2011.02917.x. Epub 2011 Dec 5. | E6: Ito S | F6: Int J Urol | G6: 2012 | H6: 40884 | K6: 10.1111/j.1442-2042.2011.02917.x | L6: =IF(ISNUMBER(VLOOKUP(A6,EXCL,1,FALSE)),"Excluido",IF(ISNUMBER(VLOOKUP(A6,POST,1,FALSE)),"PostAlerta",IF(ISNUMBER(VLOOKUP(A6,PRE,1,FALSE)),"PreAlerta",""))) -> PreAlerta | M6: =IF(ISNUMBER(VLOOKUP(A6,KEYWORDS,1,FALSE)),"C/PalabrasClaves","S/PalabrasClaves") -> S/PalabrasClaves | Q6: Excluir
A7: 22158739 | B7: Identification of antigen-specific antibody responses associated with upper genital tract pathology in mice infected with Chlamydia muridarum | C7: Zeng H, Gong S, Hou S, Zou Q, Zhong G. | D7: Infect Immun. 2012 Mar;80(3):1098-106. doi: 10.1128/IAI.05894-11. Epub 2011 Dec 12. | E7: Zeng H | F7: Infect Immun | G7: 2012 | H7: 40891 | I7: PMC3294672 | K7: 10.1128/IAI.05894-11 | L7: =IF(ISNUMBER(VLOOKUP(A7,EXCL,1,FALSE)),"Excluido",IF(ISNUMBER(VLOOKUP(A7,POST,1,FALSE)),"PostAlerta",IF(ISNUMBER(VLOOKUP(A7,PRE,1,FALSE)),"PreAlerta",""))) -> PreAlerta | M7: =IF(ISNUMBER(VLOOKUP(A7,KEYWORDS,1,FALSE)),"C/PalabrasClaves","S/PalabrasClaves") -> S/PalabrasClaves | Q7: Excluir
A8: 22203235 | B8: Chlamydia pneumoniae entry into epithelial cells by clathrin-independent endocytosis | C8: Korhonen JT, Puolakkainen M, Haveri A, Tammiruusu A, Sarvas M, Lahesmaa R. | D8: Microb Pathog. 2012 Mar;52(3):157-64. doi: 10.1016/j.micpath.2011.12.002. Epub 2011 Dec 21. | E8: Korhonen JT | F8: Microb Pathog | G8: 2012 | H8: 40906 | K8: 10.1016/j.micpath.2011.12.002 | L8: =IF(ISNUMBER(VLOOKUP(A8,EXCL,1,FALSE)),"Excluido",IF(ISNUMBER(VLOOKUP(A8,POST,1,FALSE)),"PostAlerta",IF(ISNUMBER(VLOOKUP(A8,PRE,1,FALSE)),"PreAlerta",""))) -> PreAlerta | M8: =IF(ISNUMBER(VLOOKUP(A8,KEYWORDS,1,FALSE)),"C/PalabrasClaves","S/PalabrasClaves") -> S/PalabrasClaves | Q8: Listo
A9: 22222354 | B9: High-valent [MnFe] and [FeFe] cofactors in ribonucleotide reductases | C9: Leidel N, Popović-Bijelić A, Havelius KG, Chernev P, Voevodskaya N, Gräslund A, Haumann M. | D9: Biochim Biophys Acta. 2012 Mar;1817(3):430-44. doi: 10.1016/j.bbabio.2011.12.008. Epub 2011 Dec 23. | E9: Leidel N | F9: Biochim Biophys Acta | G9: 2012 | H9: 40915 | K9: 10.1016/j.bbabio.2011.12.008 | L9: =IF(ISNUMBER(VLOOKUP(A9,EXCL,1,FALSE)),"Excluido",IF(ISNUMBER(VLOOKUP(A9,POST,1,FALSE)),"PostAlerta",IF(ISNUMBER(VLOOKUP(A9,PRE,1,FALSE)),"PreAlerta",""))) -> PreAlerta | M9: =IF(ISNUMBER(VLOOKUP(A9,KEYWORDS,1,FALSE)),"C/PalabrasClaves","S/PalabrasClaves") -> S/PalabrasClaves | Q9: Revisar
A10: 22285842 | B10: Trachomatous trichiasis and its management in endemic countries | C10: Rajak SN, Collin JR, Burton MJ. | D10: Surv Ophthalmol. 2012 Mar-Apr;57(2):105-35. doi: 10.1016/j.survophthal.2011.08.002. Epub 2012 Jan 27. | E10: Rajak SN | F10: Surv Ophthalmol | G10: 2012 | H10: 40939 | I10: PMC3316859 | K10: 10.1016/j.survophthal.2011.08.002 | L10: =IF(ISNUMBER(VLOOKUP(A10,EXCL,1,FALSE)),"Excluido",IF(ISNUMBER(VLOOKUP(A10,POST,1,FALSE)),"PostAlerta",IF(ISNUMBER(VLOOKUP(A10,PRE,1,FALSE)),"PreAlerta",""))) -> Excluido | M10: =IF(ISNUMBER(VLOOKUP(A10,KEYWORDS,1,FALSE)),"C/PalabrasClaves","S/PalabrasClaves") -> S/PalabrasClaves | N10: 1) Reporte de cepas resistentes | Q10: Revisar
A11: 22316336 | B11: Treatment of chlamydial infections | C11: Hammerschlag MR, Kohlhoff SA. | D11: Expert Opin Pharmacother. 2012 Mar;13(4):545-52. doi: 10.1517/14656566.2012.658776. Epub 2012 Feb 9. | E11: Hammerschlag MR | F11: Expert Opin Pharmacother | G11: 2012 | H11: 40949 | K11: 10.1517/14656566.2012.658776 | L11: =IF(ISNUMBER(VLOOKUP(A11,EXCL,1,FALSE)),"Excluido",IF(ISNUMBER(VLOOKUP(A11,POST,1,FALSE)),"PostAlerta",IF(ISNUMBER(VLOOKUP(A11,PRE,1,FALSE)),"PreAlerta",""))) -> Excluido | M11: =IF(ISNUMBER(VLOOKUP(A11,KEYWORDS,1,FALSE)),"C/PalabrasClaves","S/PalabrasClaves") -> S/PalabrasClaves | N11: 2) Nuevos tratamientos | Q11: Revisar
A12: 22326056 | B12: Review: Targeting trachoma: Strategies to reduce the leading infectious cause of blindness | C12: Baneke A. | D12: Travel Med Infect Dis. 2012 Mar;10(2):92-6. doi: 10.1016/j.tmaid.2012.01.005. Epub 2012 Feb 9. | E12: Baneke A | F12: Travel Med Infect Dis | G12: 2012 | H12: 40953 | K12: 10.1016/j.tmaid.2012.01.005 | L12: =IF(ISNUMBER(VLOOKUP(A12,EXCL,1,FALSE)),"Excluido",IF(ISNUMBER(VLOOKUP(A12,POST,1,FALSE)),"PostAlerta",IF(ISNUMBER(VLOOKUP(A12,PRE,1,FALSE)),"PreAlerta",""))) -> Excluido | M12: =IF(ISNUMBER(VLOOKUP(A12,KEYWORDS,1,FALSE)),"C/PalabrasClaves","S/PalabrasClaves") -> S/PalabrasClaves | Q12: Excluir
A13: 22337116 | B13: Stable Chlamydia prevalence does not exclude increasing burden of disease | C13: Rekart ML, Brunham RC. | D13: Sex Transm Dis. 2012 Mar;39(3):239; author reply 239-40. doi: 10.1097/OLQ.0b013e318244b79c. | E13: Rekart ML | F13: Sex Transm Dis | G13: 2012 | H13: 40956 | K13: 10.1097/OLQ.0b013e318244b79c | L13: =IF(ISNUMBER(VLOOKUP(A13,EXCL,1,FALSE)),"Excluido",IF(ISNUMBER(VLOOKUP(A13,POST,1,FALSE)),"PostAlerta",IF(ISNUMBER(VLOOKUP(A13,PRE,1,FALSE)),"PreAlerta",""))) -> PreAlerta | M13: =IF(ISNUMBER(VLOOKUP(A13,KEYWORDS,1,FALSE)),"C/PalabrasClaves","S/PalabrasClaves") -> S/PalabrasClaves
A14: 22369307 | B14: The use of polymerase chain reaction assay versus cell culture in detecting neonatal chlamydial conjunctivitis | C14: Rafiei Tabatabaei S, Afjeiee SA, Fallah F, Tahami Zanjani N, Shiva F, Tavakkoly Fard A, Shamshiri AR, Karimi A. | D14: Arch Iran Med. 2012 Mar;15(3):171-5. | E14: Rafiei Tabatabaei S | F14: Arch Iran Med | G14: 2012 | H14: 40968 | L14: =IF(ISNUMBER(VLOOKUP(A14,EXCL,1,FALSE)),"Excluido",IF(ISNUMBER(VLOOKUP(A14,POST,1,FALSE)),"PostAlerta",IF(ISNUMBER(VLOOKUP(A14,PRE,1,FALSE)),"PreAlerta",""))) -> PreAlerta | M14: =IF(ISNUMBER(VLOOKUP(A14,KEYWORDS,1,FALSE)),"C/PalabrasClaves","S/PalabrasClaves") -> S/PalabrasClaves | N14: 4) otros
A15: 22382226 | B15: Frequency of Chlamydia trachomatis among male patients with urethritis in northeast of Iran detected by polymerase chain reaction | C15: Ghazvini K, Ahmadnia H, Ghanaat J. | D15: Saudi J Kidney Dis Transpl. 2012 Mar;23(2):316-20. | E15: Ghazvini K | F15: Saudi J Kidney Dis Transpl | G15: 2012 | H15: 40971 | L15: =IF(ISNUMBER(VLOOKUP(A15,EXCL,1,FALSE)),"Excluido",IF(ISNUMBER(VLOOKUP(A15,POST,1,FALSE)),"PostAlerta",IF(ISNUMBER(VLOOKUP(A15,PRE,1,FALSE)),"PreAlerta",""))) -> PreAlerta | M15: =IF(ISNUMBER(VLOOKUP(A15,KEYWORDS,1,FALSE)),"C/PalabrasClaves","S/PalabrasClaves") -> S/PalabrasClaves | N15: 4) otros
A16: 22386127 | B16: Serum interleukin-1β, interleukin-8 and anti-heat shock 60 Chlamydia trachomatis antibodies as markers of ectopic pregnancy | C16: Daponte A, Pournaras S, Deligeoroglou E, Skentou H, Messinis IE. | D16: J Reprod Immunol. 2012 Mar;93(2):102-8. doi: 10.1016/j.jri.2012.01.003. Epub 2012 Mar 2. | E16: Daponte A | F16: J Reprod Immunol | G16: 2012 | H16: 40974 | K16: 10.1016/j.jri.2012.01.003 | L16: =IF(ISNUMBER(VLOOKUP(A16,EXCL,1,FALSE)),"Excluido",IF(ISNUMBER(VLOOKUP(A16,POST,1,FALSE)),"PostAlerta",IF(ISNUMBER(VLOOKUP(A16,PRE,1,FALSE)),"PreAlerta",""))) -> PreAlerta | M16: =IF(ISNUMBER(VLOOKUP(A16,KEYWORDS,1,FALSE)),"C/PalabrasClaves","S/PalabrasClaves") -> S/PalabrasClaves | N16: 4) otros
A17: 22421458 | B17: [Diagnosis and treatment of Chlamydia-induced reactive arthritis] | C17: Zarco Montejo P. | D17: Reumatol Clin. 2012 Mar;8 Suppl 1:S20-5. doi: 10.1016/j.reuma.2011.11.003. Epub 2012 Mar 14. | E17: Zarco Montejo P | F17: Reumatol Clin | G17: 2012 | H17: 40985 | K17: 10.1016/j.reuma.2011.11.003 | L17: =IF(ISNUMBER(VLOOKUP(A17,EXCL,1,FALSE)),"Excluido",IF(ISNUMBER(VLOOKUP(A17,POST,1,FALSE)),"PostAlerta",IF(ISNUMBER(VLOOKUP(A17,PRE,1,FALSE)),"PreAlerta",""))) -> Excluido | M17: =IF(ISNUMBER(VLOOKUP(A17,KEYWORDS,1,FALSE)),"C/PalabrasClaves","S/PalabrasClaves") -> S/PalabrasClaves
A18: 22422335 | B18: Hemostatic properties of the lymph: relationships with occlusion and thrombosis | C18: Lippi G, Favaloro EJ, Cervellin G. | D18: Semin Thromb Hemost. 2012 Mar;38(2):213-21. doi: 10.1055/s-0032-1301418. Epub 2012 Feb 9. | E18: Lippi G | F18: Semin Thromb Hemost | G18: 2012 | H18: 40985 | K18: 10.1055/s-0032-1301418 | L18: =IF(ISNUMBER(VLOOKUP(A18,EXCL,1,FALSE)),"Excluido",IF(ISNUMBER(VLOOKUP(A18,POST,1,FALSE)),"PostAlerta",IF(ISNUMBER(VLOOKUP(A18,PRE,1,FALSE)),"PreAlerta",""))) -> Excluido | M18: =IF(ISNUMBER(VLOOKUP(A18,KEYWORDS,1,FALSE)),"C/PalabrasClaves","S/PalabrasClaves") -> S/PalabrasClaves
A19: 22552464 | B19: Prevalence of cervical Chlamydia trachomatis infection in sexually active adolescents from Salvador, Brazil | C19: Machado MS, Costa e Silva BF, Gomes IL, Santana IU, Grassi MF. | D19: Braz J Infect Dis. 2012 Mar-Apr;16(2):188-91. doi: 10.1590/s1413-86702012000200015. | E19: Machado MS | F19: Braz J Infect Dis | G19: 2012 | H19: 41033 | K19: 10.1590/s1413-86702012000200015 | L19: =IF(ISNUMBER(VLOOKUP(A19,EXCL,1,FALSE)),"Excluido",IF(ISNUMBER(VLOOKUP(A19,POST,1,FALSE)),"PostAlerta",IF(ISNUMBER(VLOOKUP(A19,PRE,1,FALSE)),"PreAlerta",""))) -> PreAlerta | M19: =IF(ISNUMBER(VLOOKUP(A19,KEYWORDS,1,FALSE)),"C/PalabrasClaves","S/PalabrasClaves") -> S/PalabrasClaves | N19: 4) otros
A20: 22650098 | B20: [Prevalence of Chlamydia trachomatis in adults with chronic conjunctivitis in Nisava district] | C20: Indjić N, Igić L, Veselinović D. | D20: Srp Arh Celok Lek. 2012 Mar-Apr;140(3-4):148-52. doi: 10.2298/sarh1204148i. | E20: Indjić N | F20: Srp Arh Celok Lek | G20: 2012 | H20: 41062 | K20: 10.2298/sarh1204148i | L20: =IF(ISNUMBER(VLOOKUP(A20,EXCL,1,FALSE)),"Excluido",IF(ISNUMBER(VLOOKUP(A20,POST,1,FALSE)),"PostAlerta",IF(ISNUMBER(VLOOKUP(A20,PRE,1,FALSE)),"PreAlerta",""))) -> PreAlerta | M20: =IF(ISNUMBER(VLOOKUP(A20,KEYWORDS,1,FALSE)),"C/PalabrasClaves","S/PalabrasClaves") -> S/PalabrasClaves | N20: 4) otros
A21: 22675852 | B21: Risk behaviors and sexually transmitted diseases in gay and heterosexual men attending an STD clinic in Tel Aviv, Israel: a cross-sectional study | C21: Mor Z, Shohat T, Goor Y, Dan M. | D21: Isr Med Assoc J. 2012 Mar;14(3):147-51. | E21: Mor Z | F21: Isr Med Assoc J | G21: 2012 | H21: 41069 | L21: =IF(ISNUMBER(VLOOKUP(A21,EXCL,1,FALSE)),"Excluido",IF(ISNUMBER(VLOOKUP(A21,POST,1,FALSE)),"PostAlerta",IF(ISNUMBER(VLOOKUP(A21,PRE,1,FALSE)),"PreAlerta",""))) -> PreAlerta | M21: =IF(ISNUMBER(VLOOKUP(A21,KEYWORDS,1,FALSE)),"C/PalabrasClaves","S/PalabrasClaves") -> S/PalabrasClaves | N21: 4) otros
A22: 22812177 | B22: [New genovariantes of Chlamydia trachomatis serovar L2 proctitis causing] | C22: Guerra-Infante FM, López-Hurtado M, Villagrana-Zesati R. | D22: Ginecol Obstet Mex. 2012 Mar;80(3):208-17. | E22: Guerra-Infante FM | F22: Ginecol Obstet Mex | G22: 2012 | H22: 41111 | L22: =IF(ISNUMBER(VLOOKUP(A22,EXCL,1,FALSE)),"Excluido",IF(ISNUMBER(VLOOKUP(A22,POST,1,FALSE)),"PostAlerta",IF(ISNUMBER(VLOOKUP(A22,PRE,1,FALSE)),"PreAlerta",""))) -> Excluido | M22: =IF(ISNUMBER(VLOOKUP(A22,KEYWORDS,1,FALSE)),"C/PalabrasClaves","S/PalabrasClaves") -> S/PalabrasClaves
A23: 22263556 | B23: Dendrimer-enabled modulation of gene expression in Chlamydia trachomatis | C23: Mishra MK, Gérard HC, Whittum-Hudson JA, Hudson AP, Kannan RM. | D23: Mol Pharm. 2012 Mar 5;9(3):413-21. doi: 10.1021/mp200512f. Epub 2012 Jan 30. | E23: Mishra MK | F23: Mol Pharm | G23: 2012 | H23: 40932 | K23: 10.1021/mp200512f | L23: =IF(ISNUMBER(VLOOKUP(A23,EXCL,1,FALSE)),"Excluido",IF(ISNUMBER(VLOOKUP(A23,POST,1,FALSE)),"PostAlerta",IF(ISNUMBER(VLOOKUP(A23,PRE,1,FALSE)),"PreAlerta",""))) -> PreAlerta | M23: =IF(ISNUMBER(VLOOKUP(A23,KEYWORDS,1,FALSE)),"C/PalabrasClaves","S/PalabrasClaves") -> S/PalabrasClaves | N23: 4) otros
A24: 22406642 | B24: Whole-genome analysis of diverse Chlamydia trachomatis strains identifies phylogenetic relationships masked by current clinical typing | C24: Harris SR, Clarke IN, Seth-Smith HM, Solomon AW, Cutcliffe LT, Marsh P, Skilton RJ, Holland MJ, Mabey D, Peeling RW, Lewis DA, Spratt BG, Unemo M, Persson K, Bjartling C, Brunham R, de Vries HJ, Morré SA, Speksnijder A, Bébéar CM, Clerc M, de Barbeyrac B, Parkhill J, Thomson NR. | D24: Nat Genet. 2012 Mar 11;44(4):413-9, S1. doi: 10.1038/ng.2214. | E24: Harris SR | F24: Nat Genet | G24: 2012 | H24: 40981 | I24: PMC3378690 | J24: UKMS41052 | K24: 10.1038/ng.2214 | L24: =IF(ISNUMBER(VLOOKUP(A24,EXCL,1,FALSE)),"Excluido",IF(ISNUMBER(VLOOKUP(A24,POST,1,FALSE)),"PostAlerta",IF(ISNUMBER(VLOOKUP(A24,PRE,1,FALSE)),"PreAlerta",""))) -> PreAlerta | M24: =IF(ISNUMBER(VLOOKUP(A24,KEYWORDS,1,FALSE)),"C/PalabrasClaves","S/PalabrasClaves") -> S/PalabrasClaves | N24: 4) otros
A25: 22210633 | B25: Low prevalence of asymptomatic sexually transmitted infections in HIV-infected heterosexuals visiting an HIV clinic in the Netherlands | C25: Heiligenberg M, van der Loeff MF, de Vries HJ, Speksnijder AG, Geerlings SE, Coutinho R, Prins M, Prins JM. | D25: AIDS. 2012 Mar 13;26(5):646-9. doi: 10.1097/QAD.0b013e3283504bbf. | E25: Heiligenberg M | F25: AIDS | G25: 2012 | H25: 40911 | K25: 10.1097/QAD.0b013e3283504bbf | L25: =IF(ISNUMBER(VLOOKUP(A25,EXCL,1,FALSE)),"Excluido",IF(ISNUMBER(VLOOKUP(A25,POST,1,FALSE)),"PostAlerta",IF(ISNUMBER(VLOOKUP(A25,PRE,1,FALSE)),"PreAlerta",""))) -> PreAlerta | M25: =IF(ISNUMBER(VLOOKUP(A25,KEYWORDS,1,FALSE)),"C/PalabrasClaves","S/PalabrasClaves") -> S/PalabrasClaves | N25: 4) otros
A26: 22436137 | B26: Phenotypic and genetic characterisation of bacterial sexually transmitted infections in Bissau, Guinea-Bissau, West Africa: a prospective cohort study | C26: Olsen B, Månsson F, Camara C, Monteiro M, Biai A, Alves A, Andersson S, Norrgren H, Unemo M. | D26: BMJ Open. 2012 Mar 20;2(2):e000636. doi: 10.1136/bmjopen-2011-000636. Print 2012. | E26: Olsen B | F26: BMJ Open | G26: 2012 | H26: 40991 | I26: PMC3329603 | K26: 10.1136/bmjopen-2011-000636 | L26: =IF(ISNUMBER(VLOOKUP(A26,EXCL,1,FALSE)),"Excluido",IF(ISNUMBER(VLOOKUP(A26,POST,1,FALSE)),"PostAlerta",IF(ISNUMBER(VLOOKUP(A26,PRE,1,FALSE)),"PreAlerta",""))) -> PreAlerta | M26: =IF(ISNUMBER(VLOOKUP(A26,KEYWORDS,1,FALSE)),"C/PalabrasClaves","S/PalabrasClaves") -> C/PalabrasClaves | N26: 1) Reporte de cepas resistentes | Q26: Listo | T26: The direct interrogation of fleeting intermediates by rapid-mixing kinetic methods has significantly advanced our understanding of enzymes that utilize dioxygen. The gas's modest aqueous solubility (<2 mM at 1 atm) presents a technical challenge to this approach, because it limits the rate of formation and extent of accumulation of intermediates. This challenge can be overcome by use of the heme enzyme chlorite dismutase (Cld) for the rapid, in situ generation of O(2) at concentrations far exceeding 2 mM. This method was used to define the O(2) concentration dependence of the reaction of the class Ic ribonucleotide reductase (RNR) from Chlamydia trachomatis, in which the enzyme's Mn(IV)/Fe(III) cofactor forms from a Mn(II)/Fe(II) complex and O(2) via a Mn(IV)/Fe(IV) intermediate, at effective O(2) concentrations as high as ~10 mM. With a more soluble receptor, myoglobin, an O(2) adduct accumulated to a concentration of >6 mM in <15 ms. Finally, the C-H-bond-cleaving Fe(IV)-oxo complex, J, in taurine:α-ketoglutarate dioxygenase and superoxo-Fe(2)(III/III) complex, G, in myo-inositol oxygenase, and the tyrosyl-radical-generating Fe(2)(III/IV) intermediate, X, in Escherichia coli RNR, were all accumulated to yields more than twice those previously attained. This means of in situ O(2) evolution permits a >5 mM "pulse" of O(2) to be generated in <1 ms at the easily accessible Cld concentration of 50 μM. It should therefore significantly extend the range of kinetic and spectroscopic experiments that can routinely be undertaken in the study of these enzymes and could also facilitate resolution of mechanistic pathways in cases of either sluggish or thermodynamically unfavorable O(2) addition steps. | U26: Yes | V26: No | W26: No | X26: They conducted a study of 3 types of bacteria, among which they found and characterized C. trachomatis
A27: 22440143 | B27: [WITHDRAWN: Prevalence and associated factors of Chlamydia trachomatis infection in young prisoners of Catalonia, Spain.] | C27: López Corbeto E, Carnicer-Pont D, Lugo R, Gonzalez V, Bascuñana E, Lleopart N, Barbero L, Humet V, Casabona J; Grupo de Estudio CT Prisiones. | D27: Med Clin (Barc). 2012 Mar 21:S0025-7753(12)00137-6. doi: 10.1016/j.medcli.2012.01.024. Online ahead of print. | E27: López Corbeto E | F27: Med Clin (Barc) | G27: 2012 | H27: 40992 | K27: 10.1016/j.medcli.2012.01.024 | L27: =IF(ISNUMBER(VLOOKUP(A27,EXCL,1,FALSE)),"Excluido",IF(ISNUMBER(VLOOKUP(A27,POST,1,FALSE)),"PostAlerta",IF(ISNUMBER(VLOOKUP(A27,PRE,1,FALSE)),"PreAlerta",""))) -> PreAlerta | M27: =IF(ISNUMBER(VLOOKUP(A27,KEYWORDS,1,FALSE)),"C/PalabrasClaves","S/PalabrasClaves") -> S/PalabrasClaves | N27: 4) otros
A28: 22668947 | B28: Inflammatory pathways in cervical cancer - the UCT contribution | C28: Sales KJ, Katz AA. | D28: S Afr Med J. 2012 Mar 23;102(6):493-6. doi: 10.7196/samj.5532. | E28: Sales KJ | F28: S Afr Med J | G28: 2012 | H28: 41067 | K28: 10.7196/samj.5532 | L28: =IF(ISNUMBER(VLOOKUP(A28,EXCL,1,FALSE)),"Excluido",IF(ISNUMBER(VLOOKUP(A28,POST,1,FALSE)),"PostAlerta",IF(ISNUMBER(VLOOKUP(A28,PRE,1,FALSE)),"PreAlerta",""))) -> Excluido | M28: =IF(ISNUMBER(VLOOKUP(A28,KEYWORDS,1,FALSE)),"C/PalabrasClaves","S/PalabrasClaves") -> S/PalabrasClaves
A29: 22341824 | B29: Prevention of sexually transmitted infections in urban communities (Peru PREVEN): a multicomponent community-randomised controlled trial | C29: García PJ, Holmes KK, Cárcamo CP, Garnett GP, Hughes JP, Campos PE, Whittington WL; Peru PREVEN Study Team. | D29: Lancet. 2012 Mar 24;379(9821):1120-8. doi: 10.1016/S0140-6736(11)61846-1. Epub 2012 Feb 15. | E29: García PJ | F29: Lancet | G29: 2012 | H29: 40960 | I29: PMC3315635 | K29: 10.1016/S0140-6736(11)61846-1 | L29: =IF(ISNUMBER(VLOOKUP(A29,EXCL,1,FALSE)),"Excluido",IF(ISNUMBER(VLOOKUP(A29,POST,1,FALSE)),"PostAlerta",IF(ISNUMBER(VLOOKUP(A29,PRE,1,FALSE)),"PreAlerta",""))) -> Excluido | M29: =IF(ISNUMBER(VLOOKUP(A29,KEYWORDS,1,FALSE)),"C/PalabrasClaves","S/PalabrasClaves") -> S/PalabrasClaves
A30: 22456736 | B30: Genome-wide recombination in Chlamydia trachomatis | C30: Joseph SJ, Read TD. | D30: Nat Genet. 2012 Mar 28;44(4):364-6. doi: 10.1038/ng.2225. | E30: Joseph SJ | F30: Nat Genet | G30: 2012 | H30: 40998 | K30: 10.1038/ng.2225 | L30: =IF(ISNUMBER(VLOOKUP(A30,EXCL,1,FALSE)),"Excluido",IF(ISNUMBER(VLOOKUP(A30,POST,1,FALSE)),"PostAlerta",IF(ISNUMBER(VLOOKUP(A30,PRE,1,FALSE)),"PreAlerta",""))) -> PreAlerta | M30: =IF(ISNUMBER(VLOOKUP(A30,KEYWORDS,1,FALSE)),"C/PalabrasClaves","S/PalabrasClaves") -> S/PalabrasClaves | N30: 4) otros
A31: 21938501 | B31: Chlamydial infection in a high risk population: association with vaginal flora patterns | C31: Marconi C, Donders GG, Martin LF, Ramos BR, Duarte MT, Parada CM, Tristão AR, Silva MG. | D31: Arch Gynecol Obstet. 2012 Apr;285(4):1013-8. doi: 10.1007/s00404-011-2085-5. Epub 2011 Sep 22. | E31: Marconi C | F31: Arch Gynecol Obstet | G31: 2012 | H31: 40809 | K31: 10.1007/s00404-011-2085-5 | L31: =IF(ISNUMBER(VLOOKUP(A31,EXCL,1,FALSE)),"Excluido",IF(ISNUMBER(VLOOKUP(A31,POST,1,FALSE)),"PostAlerta",IF(ISNUMBER(VLOOKUP(A31,PRE,1,FALSE)),"PreAlerta",""))) -> PreAlerta | M31: =IF(ISNUMBER(VLOOKUP(A31,KEYWORDS,1,FALSE)),"C/PalabrasClaves","S/PalabrasClaves") -> S/PalabrasClaves | N31: 4) otros
A32: 22141597 | B32: Amoebal host range, host-free survival and disinfection susceptibility of environmental Chlamydiae as compared to Chlamydia trachomatis | C32: Coulon C, Eterpi M, Greub G, Collignon A, McDonnell G, Thomas V. | D32: FEMS Immunol Med Microbiol. 2012 Apr;64(3):364-73. doi: 10.1111/j.1574-695X.2011.00919.x. Epub 2012 Jan 3. | E32: Coulon C | F32: FEMS Immunol Med Microbiol | G32: 2012 | H32: 40884 | K32: 10.1111/j.1574-695X.2011.00919.x | L32: =IF(ISNUMBER(VLOOKUP(A32,EXCL,1,FALSE)),"Excluido",IF(ISNUMBER(VLOOKUP(A32,POST,1,FALSE)),"PostAlerta",IF(ISNUMBER(VLOOKUP(A32,PRE,1,FALSE)),"PreAlerta",""))) -> PreAlerta | M32: =IF(ISNUMBER(VLOOKUP(A32,KEYWORDS,1,FALSE)),"C/PalabrasClaves","S/PalabrasClaves") -> S/PalabrasClaves | N32: 4) otros
A33: 22199134 | B33: Testing the fathers: carrying out HIV and STI tests on partners of pregnant women | C33: Dhairyawan R, Creighton S, Sivyour L, Anderson J. | D33: Sex Transm Infect. 2012 Apr;88(3):184-6. doi: 10.1136/sextrans-2011-050232. Epub 2011 Dec 23. | E33: Dhairyawan R | F33: Sex Transm Infect | G33: 2012 | H33: 40904 | K33: 10.1136/sextrans-2011-050232 | L33: =IF(ISNUMBER(VLOOKUP(A33,EXCL,1,FALSE)),"Excluido",IF(ISNUMBER(VLOOKUP(A33,POST,1,FALSE)),"PostAlerta",IF(ISNUMBER(VLOOKUP(A33,PRE,1,FALSE)),"PreAlerta",""))) -> PreAlerta | M33: =IF(ISNUMBER(VLOOKUP(A33,KEYWORDS,1,FALSE)),"C/PalabrasClaves","S/PalabrasClaves") -> S/PalabrasClaves | N33: 4) otros
A34: 22213681 | B34: The cost and cost-effectiveness of opportunistic screening for Chlamydia trachomatis in Ireland | C34: Gillespie P, O'Neill C, Adams E, Turner K, O'Donovan D, Brugha R, Vaughan D, O'Connell E, Cormican M, Balfe M, Coleman C, Fitzgerald M, Fleming C. | D34: Sex Transm Infect. 2012 Apr;88(3):222-8. doi: 10.1136/sextrans-2011-050067. Epub 2012 Jan 2. | E34: Gillespie P | F34: Sex Transm Infect | G34: 2012 | H34: 40912 | K34: 10.1136/sextrans-2011-050067 | L34: =IF(ISNUMBER(VLOOKUP(A34,EXCL,1,FALSE)),"Excluido",IF(ISNUMBER(VLOOKUP(A34,POST,1,FALSE)),"PostAlerta",IF(ISNUMBER(VLOOKUP(A34,PRE,1,FALSE)),"PreAlerta",""))) -> PreAlerta | M34: =IF(ISNUMBER(VLOOKUP(A34,KEYWORDS,1,FALSE)),"C/PalabrasClaves","S/PalabrasClaves") -> S/PalabrasClaves | N34: 4) otros
A35: 22215696 | B35: Systematic selection of screening participants by risk score in a Chlamydia screening programme is feasible and effective | C35: van den Broek IV, Brouwers EE, Götz HM, van Bergen JE, Op de Coul EL, Fennema JS, Koekenbier RH, Pars LL, van Ravesteijn SM, Hoebe CJ. | D35: Sex Transm Infect. 2012 Apr;88(3):205-11. doi: 10.1136/sextrans-2011-050219. Epub 2012 Jan 3. | E35: van den Broek IV | F35: Sex Transm Infect | G35: 2012 | H35: 40913 | K35: 10.1136/sextrans-2011-050219 | L35: =IF(ISNUMBER(VLOOKUP(A35,EXCL,1,FALSE)),"Excluido",IF(ISNUMBER(VLOOKUP(A35,POST,1,FALSE)),"PostAlerta",IF(ISNUMBER(VLOOKUP(A35,PRE,1,FALSE)),"PreAlerta",""))) -> PreAlerta | M35: =IF(ISNUMBER(VLOOKUP(A35,KEYWORDS,1,FALSE)),"C/PalabrasClaves","S/PalabrasClaves") -> S/PalabrasClaves | N35: 4) otros
A36: 22259215 | B36: Comparison of three assays for detection of Chlamydia trachomatis and Neisseria gonorrhoeae in SurePath Pap samples and the role of pre- and postcytology testing | C36: Chernesky M, Jang D, Portillo E, Smieja M, Kapala J, Doucette C, Sumner J, Ewert R, MacRitchie C, Gilchrist J. | D36: J Clin Microbiol. 2012 Apr;50(4):1281-4. doi: 10.1128/JCM.06595-11. Epub 2012 Jan 18. | E36: Chernesky M | F36: J Clin Microbiol | G36: 2012 | H36: 40928 | I36: PMC3318522 | K36: 10.1128/JCM.06595-11 | L36: =IF(ISNUMBER(VLOOKUP(A36,EXCL,1,FALSE)),"Excluido",IF(ISNUMBER(VLOOKUP(A36,POST,1,FALSE)),"PostAlerta",IF(ISNUMBER(VLOOKUP(A36,PRE,1,FALSE)),"PreAlerta",""))) -> PreAlerta | M36: =IF(ISNUMBER(VLOOKUP(A36,KEYWORDS,1,FALSE)),"C/PalabrasClaves","S/PalabrasClaves") -> S/PalabrasClaves | N36: 4) otros
A37: 22290151 | B37: Chlamydia muridarum T cell antigens and adjuvants that induce protective immunity in mice | C37: Yu H, Karunakaran KP, Jiang X, Shen C, Andersen P, Brunham RC. | D37: Infect Immun. 2012 Apr;80(4):1510-8. doi: 10.1128/IAI.06338-11. Epub 2012 Jan 30. | E37: Yu H | F37: Infect Immun | G37: 2012 | H37: 40940 | I37: PMC3318408 | K37: 10.1128/IAI.06338-11 | L37: =IF(ISNUMBER(VLOOKUP(A37,EXCL,1,FALSE)),"Excluido",IF(ISNUMBER(VLOOKUP(A37,POST,1,FALSE)),"PostAlerta",IF(ISNUMBER(VLOOKUP(A37,PRE,1,FALSE)),"PreAlerta",""))) -> PreAlerta | M37: =IF(ISNUMBER(VLOOKUP(A37,KEYWORDS,1,FALSE)),"C/PalabrasClaves","S/PalabrasClaves") -> C/PalabrasClaves | N37: 3) immunization | Q37: Listo | T37: Major impediments to a Chlamydia vaccine lie in discovering T cell antigens and polarizing adjuvants that stimulate protective immunity. We previously reported the discovery of three T cell antigens (PmpG, PmpF, and RplF) via immunoproteomics that elicited protective immunity in the murine genital tract infection model against Chlamydia infection after adoptive transfer of antigen-pulsed dendritic cells. To expand the T cell antigen repertoire necessary for a Chlamydia vaccine, we evaluated 10 new Chlamydia T cell antigens discovered via immunoproteomics in addition to the 3 antigens reported earlier as a molecular subunit vaccine. We first tested five adjuvants, including three cationic liposome formulations (dimethyldioctadecylammonium bromide-monophosphoryl lipid A [DDA-MPL], DDA-trehalose 6,6'-dibehenate [DDA-TDB {CAF01}], and DDA-monomycolyl glycerol [DDA-MMG {CAF04}]), Montanide ISA720-CpG-ODN1826, and alum using the PmpG protein as a model T cell antigen in the mouse genital tract infection model. The results showed that the cationic liposomal adjuvants DDA-MPL and DDA-TDB elicited the best protective immune responses, characterized by multifunctional CD4(+) T cells coexpressing gamma interferon (IFN-γ) and tumor necrosis factor alpha (TNF-α), and reduced infection by more than 3 logs. Using DDA-MPL as an adjuvant, we found that 7 of 13 Chlamydia T cell antigens (PmpG, PmpE, PmpF, Aasf, RplF, TC0420, and TC0825) conferred protection better than or equal to that of the reference vaccine antigen, major outer membrane protein (MOMP). Pools of membrane/secreted proteins, cytoplasmic proteins, and hypothetical proteins were tested individually or in combination. Immunization with combinations protected as well as the best individual protein in that combination. The T cell antigens and adjuvants discovered in this study are of further interest in the development of a molecularly defined Chlamydia vaccine. | U37: No | V37: No | W37: Yes | X37: They evaluated 10 novel chlamydia T-cell antigens discovered by immunoproteomics, in addition to the 3 antigens previously reported as a molecular subunit vaccine.
A38: 22371042 | B38: Correlation of Atopobium vaginae Amount With Bacterial Vaginosis Markers | C38: Marconi C, Cruciani F, Vitali B, Donders GG. | D38: J Low Genit Tract Dis. 2012 Apr;16(2):127-32. doi: 10.1097/LGT.0b013e31823c79c4. | E38: Marconi C | F38: J Low Genit Tract Dis | G38: 2012 | H38: 40968 | K38: 10.1097/LGT.0b013e31823c79c4 | L38: =IF(ISNUMBER(VLOOKUP(A38,EXCL,1,FALSE)),"Excluido",IF(ISNUMBER(VLOOKUP(A38,POST,1,FALSE)),"PostAlerta",IF(ISNUMBER(VLOOKUP(A38,PRE,1,FALSE)),"PreAlerta",""))) -> PreAlerta | M38: =IF(ISNUMBER(VLOOKUP(A38,KEYWORDS,1,FALSE)),"C/PalabrasClaves","S/PalabrasClaves") -> S/PalabrasClaves | N38: 4) otros
A39: 22384841 | B39: Potential mechanisms for increased HIV-1 transmission across the endocervical epithelium during C. trachomatis infection | C39: Schust DJ, Ibana JA, Buckner LR, Ficarra M, Sugimoto J, Amedee AM, Quayle AJ. | D39: Curr HIV Res. 2012 Apr;10(3):218-27. doi: 10.2174/157016212800618093. | E39: Schust DJ | F39: Curr HIV Res | G39: 2012 | H39: 40974 | I39: PMC3870887 | J39: NIHMS534767 | K39: 10.2174/157016212800618093 | L39: =IF(ISNUMBER(VLOOKUP(A39,EXCL,1,FALSE)),"Excluido",IF(ISNUMBER(VLOOKUP(A39,POST,1,FALSE)),"PostAlerta",IF(ISNUMBER(VLOOKUP(A39,PRE,1,FALSE)),"PreAlerta",""))) -> Excluido | M39: =IF(ISNUMBER(VLOOKUP(A39,KEYWORDS,1,FALSE)),"C/PalabrasClaves","S/PalabrasClaves") -> S/PalabrasClaves
A40: 22416272 | B40: Azithromycin antimicrobial resistance and genital Chlamydia trachomatis infection: duration of therapy may be the key to improving efficacy | C40: Horner PJ. | D40: Sex Transm Infect. 2012 Apr;88(3):154-6. doi: 10.1136/sextrans-2011-050385. | E40: Horner PJ | F40: Sex Transm Infect | G40: 2012 | H40: 40983 | K40: 10.1136/sextrans-2011-050385 | L40: =IF(ISNUMBER(VLOOKUP(A40,EXCL,1,FALSE)),"Excluido",IF(ISNUMBER(VLOOKUP(A40,POST,1,FALSE)),"PostAlerta",IF(ISNUMBER(VLOOKUP(A40,PRE,1,FALSE)),"PreAlerta",""))) -> PreAlerta | M40: =IF(ISNUMBER(VLOOKUP(A40,KEYWORDS,1,FALSE)),"C/PalabrasClaves","S/PalabrasClaves") -> C/PalabrasClaves | N40: 2) Nuevos tratamientos | Q40: Excluir | U40: No | V40: No | W40: No | X40: It is a publishing house
...

Sheet Test
A1: PMID | B1: Title | C1: Categoria | D1: subcategoria | E1: Estado | F1: Abstract | G1: 1) Antimicrobial Resistance stain | H1: 2) New treatment | I1: 3) Immunization | J1: Human_summary
A2: 22436137 | B2: Phenotypic and genetic characterisation of bacterial sexually transmitted infections in Bissau, Guinea-Bissau, West Africa: a prospective cohort study | C2: 1) Reporte de cepas resistentes | E2: Listo | F2: The direct interrogation of fleeting intermediates by rapid-mixing kinetic methods has significantly advanced our understanding of enzymes that utilize dioxygen. The gas's modest aqueous solubility (<2 mM at 1 atm) presents a technical challenge to this approach, because it limits the rate of formation and extent of accumulation of intermediates. This challenge can be overcome by use of the heme enzyme chlorite dismutase (Cld) for the rapid, in situ generation of O(2) at concentrations far exceeding 2 mM. This method was used to define the O(2) concentration dependence of the reaction of the class Ic ribonucleotide reductase (RNR) from Chlamydia trachomatis, in which the enzyme's Mn(IV)/Fe(III) cofactor forms from a Mn(II)/Fe(II) complex and O(2) via a Mn(IV)/Fe(IV) intermediate, at effective O(2) concentrations as high as ~10 mM. With a more soluble receptor, myoglobin, an O(2) adduct accumulated to a concentration of >6 mM in <15 ms. Finally, the C-H-bond-cleaving Fe(IV)-oxo complex, J, in taurine:α-ketoglutarate dioxygenase and superoxo-Fe(2)(III/III) complex, G, in myo-inositol oxygenase, and the tyrosyl-radical-generating Fe(2)(III/IV) intermediate, X, in Escherichia coli RNR, were all accumulated to yields more than twice those previously attained. This means of in situ O(2) evolution permits a >5 mM "pulse" of O(2) to be generated in <1 ms at the easily accessible Cld concentration of 50 μM. It should therefore significantly extend the range of kinetic and spectroscopic experiments that can routinely be undertaken in the study of these enzymes and could also facilitate resolution of mechanistic pathways in cases of either sluggish or thermodynamically unfavorable O(2) addition steps. | G2: Yes | H2: No | I2: No | J2: They conducted a study of 3 types of bacteria, among which they found and characterized C. trachomatis
A3: 22290151 | B3: Chlamydia muridarum T cell antigens and adjuvants that induce protective immunity in mice | C3: 3) immunization | E3: Listo | F3: Major impediments to a Chlamydia vaccine lie in discovering T cell antigens and polarizing adjuvants that stimulate protective immunity. We previously reported the discovery of three T cell antigens (PmpG, PmpF, and RplF) via immunoproteomics that elicited protective immunity in the murine genital tract infection model against Chlamydia infection after adoptive transfer of antigen-pulsed dendritic cells. To expand the T cell antigen repertoire necessary for a Chlamydia vaccine, we evaluated 10 new Chlamydia T cell antigens discovered via immunoproteomics in addition to the 3 antigens reported earlier as a molecular subunit vaccine. We first tested five adjuvants, including three cationic liposome formulations (dimethyldioctadecylammonium bromide-monophosphoryl lipid A [DDA-MPL], DDA-trehalose 6,6'-dibehenate [DDA-TDB {CAF01}], and DDA-monomycolyl glycerol [DDA-MMG {CAF04}]), Montanide ISA720-CpG-ODN1826, and alum using the PmpG protein as a model T cell antigen in the mouse genital tract infection model. The results showed that the cationic liposomal adjuvants DDA-MPL and DDA-TDB elicited the best protective immune responses, characterized by multifunctional CD4(+) T cells coexpressing gamma interferon (IFN-γ) and tumor necrosis factor alpha (TNF-α), and reduced infection by more than 3 logs. Using DDA-MPL as an adjuvant, we found that 7 of 13 Chlamydia T cell antigens (PmpG, PmpE, PmpF, Aasf, RplF, TC0420, and TC0825) conferred protection better than or equal to that of the reference vaccine antigen, major outer membrane protein (MOMP). Pools of membrane/secreted proteins, cytoplasmic proteins, and hypothetical proteins were tested individually or in combination. Immunization with combinations protected as well as the best individual protein in that combination. The T cell antigens and adjuvants discovered in this study are of further interest in the development of a molecularly defined Chlamydia vaccine. | G3: No | H3: No | I3: Yes | J3: They evaluated 10 novel chlamydia T-cell antigens discovered by immunoproteomics, in addition to the 3 antigens previously reported as a molecular subunit vaccine.
A4: 22387629 | B4: Protection of pigs against genital Chlamydia trachomatis challenge by parenteral or mucosal DNA immunization | C4: 3) immunization | E4: Listo | F4: The current study evaluates combined aerosol-vaginal delivery of a MOMP-based Chlamydia trachomatis (serovar E) DNA vaccine in a pig genital challenge model. Most non-replicating antigens are rather poor mucosal immunogens in comparison to replicating antigens. Therefore, a mucosal administered DNA vaccine, which actually mimics a live vaccine, could be promising. Protection was promoted by plasmids encoding the porcine granulocyte macrophage-colony stimulating factor (pcDNA3.1zeo::GM-CSF), the Escherichia coli thermo-labile enterotoxin (LT) subunit A (plasmid PJV2004::LTa) and subunit B (plasmid PJV2005::LTb). Mucosal C. trachomatis DNA vaccination induced significant protection against genital C. trachomatis challenge although the infection could not be eradicated. Intradermal immunization was significantly less efficient in protecting experimentally infected pigs. Protection was correlated with efficient T cell priming and significantly higher serum IgA titers following primo vaccination. | G4: No | H4: No | I4: Yes | J4: They use different methods (spray, intradermal) to administer a vaccine.
A5: 22564463 | B5: Mycoplasma genitalium presence, resistance and epidemiology in Greenland | C5: 1) Reporte de cepas resistentes | E5: Listo | F5: Objectives: Greenland reports the highest rates of chlamydial infection and gonorrhea in the Arctic. Our objective was to determine the presence, and describe the basic epidemiology, of Mycoplasma genitalium for Greenland. Study design: Cross-sectional study. Methods: 314 residents from Nuuk and Sisimiut, between the ages of 15 and 65 years, participated in "Inuulluataarneq" (the Greenland Sexual Health Project) between July 2008 and November 2009. Participants provided self-collected samples for sexually transmitted infection (STI) testing and completed a sexual health survey. Descriptive statistics and logistic regression were used to summarize the basic characteristics of STI cases overall and M. genitalium and Chlamydia trachomatis specifically. Clinically relevant characteristics in each full model were gender (male or female), age (in years), age at sexual debut (in years), number of sexual partners in the past 3 months (continuous) and history of forced sex and community. Results: The overall prevalence of STIs was 19.0%, specifically: 9.8% for M. genitalium and 9.4% for C. trachomatis; 100% of M. genitalium-positive cases carried macrolide resistance determinants. Being female [OR = 3.2; 95% confidence interval (CI): 1.1-9.8] and younger age (OR = 0.9; 95% CI: 0.9-1.0) were associated with M. genitalium positivity. Age was also associated with C. trachomatis (OR = 0.9; 95% CI: 0.8-0.9) and STI positivity overall (OR = 0.9; 95% CI: 0.9-0.9). Conclusions: We observed a high prevalence of M. genitalium and macrolide resistance in this study. A better understanding of M. genitalium sequelae is needed to inform policy around testing, treatment, control and antibiotic use. | G5: No | H5: No | I5: No | J5: The resistant strain is Mycoplasma
A6: 22293657 | B6: First reported case of the Swedish new variant of Chlamydia trachomatis (nvCT) in Eastern Europe (Russia), and evaluation of Russian nucleic acid amplification tests regarding their ability to detect nvCT | C6: 1) Reporte de cepas resistentes | E6: Listo | F6: Chlamydia trachomatis infections are the most prevalent bacterial sexually transmitted infections (STIs) worldwide, and are associated with considerable morbidity and socio-economic consequences. The Swedish new variant of C. trachomatis (nvCT), first reported in Sweden in late 2006, contains a 377-bp deletion in the cryptic plasmid that covers the single tar-gets originally utilized in the nucleic acid amplification tests (NAATs) manufactured by Roche Diagnostics (Amplicor, Cobas Amplicor, Cobas TaqMan48) and Abbott Laboratories (Abbott m2000), which at the time were used worldwide (1, 2). In Sweden, the proportion of nvCT, compared with wild type CT (wtCT), was high (7–64% in the different counties) (3, 4), and nvCT accordingly caused thousands of falsely negative diag-noses. The nvCT prevalence in Sweden is still relatively high, and nvCT has been frequently detected in Norway, Finland and Denmark (5, 6). Although genome sequen-cing and phenotypic characterization have shown that nvCT, compared with wtCT, has an unaltered biological fitness in vitro (7), nvCT is rarely reported outside the Nordic countries (5, 7–9). However, knowledge of the nvCT presence beyond the Nordic countries is limited because few recent studies have been performed, many laboratories still cannot detect nvCT, and the ones that can detect nvCT mainly do not distinguish it from wtCT (5, 10, 11). The aims of this study were: (i) to investigate the pre-sence of nvCT in St Petersburg, the largest city in the northwest of Russia and in close geographical proximity to Sweden; and (ii) to assess NAATs used in Russia to diagnose C. trachomatisinfections for their ability to detect nvCT | G6: Yes | H6: No | I6: No | J6: New strain found in Russia
A7: 22427578 | B7: Genome-wide identification of Chlamydia trachomatis antigens associated with trachomatous trichiasis | C7: 3) immunization | E7: Listo | F7: Purpose: Chlamydia trachomatis is the leading infectious cause of blindness. The goal of the current study was to search for biomarkers associated with C. trachomatis-induced ocular pathologies. Methods: We used a whole genome scale proteome array to systematically profile antigen specificities of antibody responses to C. trachomatis infection in individuals from trachoma-endemic communities with or without end-stage trachoma (trichiasis) in The Gambia. Results: When 61 trichiasis patients were compared with their control counterparts for overall antibody reactivity with organisms of different chlamydial species, no statistically significant difference was found. Both groups developed significantly higher titers of antibodies against C. trachomatis ocular serovars A and B than ocular serovar C, genital serovar D, or Chlamydia psittaci, whereas the titers of anti-Chlamydia pneumoniae antibodies were the highest. When antisera from 33 trichiasis and 26 control patients (with relatively high titers of antibodies to C. trachomatis ocular serovars) were reacted with 908 C. trachomatis proteins, 447 antigens were recognized by at least 1 of the 59 antisera, and 10 antigens by 50% or more antisera, the latter being designated as immunodominant antigens. More importantly, four antigens were preferentially recognized by the trichiasis group, with antigens CT414, CT667, and CT706 collectively reacting with 30% of trichiasis antisera but none from the normal group, and antigen CT695 reacting with 61% of trichiasis but only 31% of normal antisera. On the other hand, eight antigens were preferentially recognized by the control group, with antigens CT019, CT117, CT301, CT553, CT556, CT571, and CT709 together reacting with 46% of normal antisera and none from the trichiasis group, whereas antigen CT442 reacted with 35% of normal and 19% of trichiasis antisera respectively. Conclusions: The current study, by mapping immunodominant C. trachomatis antigens and identifying antigens associated with both ocular pathology and protection, has provided important information for further understanding chlamydial pathogenesis and the development of subunit vaccines. | G7: No | H7: No | I7: Yes | J7: The current study, by mapping immunodominant C. trachomatis antigens and identifying antigens associated with both ocular pathology and protection, has provided important information for a better understanding of the pathogenesis of chlamydia and the development of subunit vaccines.
A8: 22525317 | B8: Derivatives of 8-hydroxyquinoline--antibacterial agents that target intra- and extracellular Gram-negative pathogens | C8: 2) Nuevos tratamientos | D8: 2c) Droga de diseño | E8: Listo | F8: Small molecule screening identified 5-nitro-7-((4-phenylpiperazine-1-yl-)methyl)quinolin-8-ol INP1750 as a putative inhibitor of type III secretion (T3S) in the Gram-negative pathogen Yersinia pseudotuberculosis. In this study we report structure-activity relationships for inhibition of T3S and show that the most potent compounds target both the extracellular bacterium Y. pseudotuberculosis and the intracellular pathogen Chlamydia trachomatis in cell-based infection models. | G8: No | H8: Yes | I8: No
A9: 22783236 | B9: Genomic and Biochemical Analysis of the Diaminopimelate and Lysine Biosynthesis Pathway in Verrucomicrobium spinosum: Identification and Partial Characterization of L,L-Diaminopimelate Aminotransferase and UDP-N-Acetylmuramoylalanyl-D-glutamyl-2,6-meso-Diaminopimelate Ligase | C9: 2) Nuevos tratamientos | D9: 2c) Droga de diseño | E9: Listo | F9: Small molecule screening identified 5-nitro-7-((4-phenylpiperazine-1-yl-)methyl)quinolin-8-ol INP1750 as a putative inhibitor of type III secretion (T3S) in the Gram-negative pathogen Yersinia pseudotuberculosis. In this study we report structure-activity relationships for inhibition of T3S and show that the most potent compounds target both the extracellular bacterium Y. pseudotuberculosis and the intracellular pathogen Chlamydia trachomatis in cell-based infection models. | G9: No | H9: Yes | I9: No | J9: Designer drug used to treat Yersinia and intracellular chlamydia
A10: 22361459 | B10: Non-thermal argon plasma is bactericidal for the intracellular bacterial pathogen Chlamydia trachomatis | C10: 2) Nuevos tratamientos | E10: Listo | F10: Non-thermal plasma (NTP) is a flow of partially ionized argon gas at an ambient macroscopic temperature and is microbicidal for bacteria, viruses and fungi. Viability of the Gram-negative obligate intracellular bacterial parasite Chlamydia trachomatis and its host cells was investigated after NTP treatment. NTP treatment of C. trachomatis extracellular elementary bodies (EBs) diminished the concentration of infectious bacteria by a factor of 9×10(4), as established by the parallel infection of murine fibroblast McCoy cells with treated and control EBs. NTP treatment of infected McCoy cells caused disruption of membrane-restricted vacuoles (inclusions), where C. trachomatis intracellular reticulate bodies (RBs) multiply, and a 2×10(6)-fold reduction in the concentration of infectious bacteria. When the samples were covered with magnesium fluoride glass to obstruct plasma particles and UV rays alone were applied, the bactericidal effect was reduced 1.4×10(1)-fold and 5×10(4)-fold for EBs and RBs, respectively. NTP treatment caused the viability of host McCoy cells to diminish by 19%. Therefore, the results obtained demonstrated that (i) both extracellular and intracellular forms of C. trachomatis are sensitive to NTP treatment; (ii) the reduction in concentration of infectious bacteria after NTP treatment of infected cells is superior to the reduction in viability of host cells; and (iii) the effect of NTP on intracellular bacteria does not depend on UV rays. | G10: No | H10: Yes | I10: No | J10: Use of physical agents (Non-thermal plasma) for the treatment of intracellular C. trachomatis
A11: 22431649 | B11: The recall response induced by genital challenge with Chlamydia muridarum protects the oviduct from pathology but not from reinfection | C11: 3) immunization | E11: Listo | F11: The significant morbidities of ectopic pregnancy and infertility observed in women after Chlamydia trachomatis genital infection result from ascension of the bacteria from the endocervix to the oviduct, where an overly aggressive inflammatory response leads to chronic scarring and Fallopian tube obstruction. A vaccine to prevent chlamydia-induced disease is urgently needed. An important question for vaccine development is whether sterilizing immunity at the level of the oviduct is essential for protection because of the possibility that a chlamydial component drives a deleterious anamnestic T cell response upon oviduct reinfection. We show that mice inoculated with attenuated plasmid-cured strains of Chlamydia muridarum are protected from oviduct pathology upon challenge with wild-type C. muridarum Nigg despite induction of a response that did not prevent reinfection of the oviduct. Interestingly, repeated abbreviated infections with Nigg also elicited recall responses that protected the oviduct from pathology despite low-level reinfection of this vulnerable tissue site. Challenged mice displayed significant decreases in tissue infiltration of inflammatory leukocytes with marked reductions in frequencies of neutrophils but significant increases in frequencies of CD4 Th1 and CD8 T cells. An anamnestic antibody response was also detected. These data indicate that exposure to a live attenuated chlamydial vaccine or repeated abbreviated genital infection with virulent chlamydiae promotes anamnestic antibody and T cell responses that protect the oviduct from pathology despite a lack of sterilizing immunity at the site. | G11: No | H11: No | I11: Yes | J11: They demonstrated that mice inoculated with attenuated plasmid-cured strains of Chlamydia muridarum are protected from oviduct pathology following challenge with wild-type C. muridarum Nigg despite the induction of a response that did not prevent oviduct reinfection.
A12: 22431650 | B12: PmpG303-311, a protective vaccine epitope that elicits persistent cellular immune responses in Chlamydia muridarum-immune mice | C12: 3) immunization | E12: Listo | F12: Urogenital Chlamydia serovars replicating in reproductive epithelium pose a unique challenge to host immunity and vaccine development. Previous studies have shown that CD4 T cells are necessary and sufficient to clear primary Chlamydia muridarum genital tract infections in the mouse model, making a protective CD4 T cell response a logical endpoint for vaccine development. Our previous proteomics studies identified 13 candidate Chlamydia proteins for subunit vaccines. Of those, PmpG-1 is the most promising vaccine candidate. To further that work, we derived a PmpG(303-311)-specific multifunctional Th1 T cell clone, designated PmpG1.1, from an immune C57BL/6 mouse and used it to investigate the presentation of the PmpG(303-311) epitope by infected epithelial cells. Epithelial presentation of the PmpG(303-311) epitope required bacterial replication, occurred 15 to 18 h postinfection, and was unaffected by gamma interferon (IFN-γ) pretreatment. Unlike epitopes recognized by other Chlamydia-specific CD4 T cell clones, the PmpG(303-311) epitope persisted on splenic antigen-presenting cells (APC) of mice that cleared primary genital tract infections. PmpG1.1 was activated by unmanipulated irradiated splenocytes from immune mice without addition of exogenous Chlamydia antigen, and remarkably, activation of PmpG1.1 by unmanipulated immune splenocytes was stronger 6 months postinfection than it was 3 weeks postinfection. Enhanced presentation of PmpG(303-311) epitope on splenic APC 6 months postinfection reflects some type of "consolidation" of a protective immune response. Understanding the antigen-presenting cell populations responsible for presenting PmpG(303-311) early (3 weeks) and late (6 months) postinfection will likely provide important insights into stable protective immunity against Chlamydia infections of the genital tract. | G12: No | H12: No | I12: Yes | J12: They use a C. protein to trigger immune response
A13: 22296995 | B13: More than classical Chlamydia psittaci in urban pigeons | C13: 1) Reporte de cepas resistentes | E13: Listo | F13: In the literature, studies of Chlamydia infection in birds have usually been confined to the search for Chlamydia (C., formerly Chlamydophila) psittaci, so that little is known about the presence of other chlamydial agents. In the present study, cloacal swabs and faeces samples of urban pigeons have been examined by real-time PCR, DNA microarray assays and partial ompA sequencing. Whilst C. psittaci was the predominant chlamydial agent in this pigeon population (75.8% of all Chlamydiaceae positives), the combined use of highly specific and sensitive molecular assays facilitated the detection of atypical serovars of C. psittaci, as well as other species of Chlamydia, such as C. abortus. Detection of C. pecorum and C. trachomatis from an avian host is reported here for the first time. Rather unexpectedly, 19.5% of all Chlamydiaceae-positive cases turned out to be infected with non-classified organisms. The considerable prevalence of these novel agents raises the question of their epidemiological importance and possible role as pathogens. Future surveys in domestic and wild birds will have to take the extended variety of chlamydial organisms into account. | G13: No | H13: No | I13: No | J13: They find a new strain in birds, but it does not talk about resistance
A14: 22682294 | B14: High-throughput proteomic screening identifies Chlamydia trachomatis antigens that are capable of eliciting T cell and antibody responses that provide protection against vaginal challenge | C14: 3) immunization | E14: Listo | F14: A comprehensive proteomic screening technology was previously used to characterize T cell responses to Chlamydia trachomatis infection. In this study, we demonstrated that T cells specific for protein antigens identified through this comprehensive technology home to the site of infection after mucosal challenge with C. trachomatis. In addition, T cell responses to these proteins were elicited in multiple genetic backgrounds. Two protein antigens, CT823 and CT144, were evaluated as vaccine candidates. When administered with AbISCO-100 adjuvant, these antigens stimulated potent CD8(+) T cell responses, polyfunctional T(H)1-polarized CD4(+) T cell responses, and high titer protein-specific T(H)1-skewed antibody responses. Vaccination with either antigen with AbISCO-100 provided long-lived protection against intravaginal challenge with C. trachomatis. Adoptive transfer of immune T cells also conferred protection in the challenge model whereas passive transfer of immune serum did not, indicating the critical role for T cell responses in control of this infection. The ability of these antigens to induce potent immune responses and provide long-lived protection in response to challenge provides a basis for the rational design of a C. trachomatis subunit vaccine. | G14: No | H14: No | I14: Yes | J14: Using two proteins of C. trachomatis they induce an immune response. They find one with greater effectiveness
