Workbook
Name categoria: categorias!$A:$A
Name Estado: categorias!$C$2:$C$65536
Name EXCL: Excluidas!$A:$K
Name EXCLUIDAS: Excluidas!$A$1:$K$463
Name KEYWORDS: 'Palabras claves'!$A:$K
Name NgonorreaePost: '2017-2022'!#REF!
Name NgonorreaePre: '2012-2017'!$A$1:$K$534
Name PalabrasClave: 'Palabras claves'!$K$1:$K$1371
Name POST: '2017-2022'!$A:$K
Name POSTALERTA: '2017-2022'!$A$1:$B$857
Name PRE: '2012-2017'!$A:$K
Name PREALERTA: '2012-2017'!$A$1:$O$540
Name SegmentaciónDeDatos_Alerta1: #REF!
Name SegmentaciónDeDatos_KeyWords: #REF!
Name SegmentaciónDeDatos_PubYear: #REF!
Name subcategoria: categorias!$B:$B
Name TablaNgonoreae: '2012-2022'!$A$1:$K$4211

Sheet DashBoard
C2: H. influenzae 2012-2022
C3: Total de publicaciones de | F3: =C2 -> H. influenzae 2012-2022 | G3: : | H3: =COUNTA('2012-2022'!A$1:A$4444)-1 -> 4443
D5: Publicaciones por Año | I5: Categorías y Subcategorías
D17: Publicaciones por mes
C37: =IFERROR(__xludf.DUMMYFUNCTION("UNIQUE('2012-2022'!N:N)"),"Categoria") -> Categoria
C39: =IFERROR(__xludf.DUMMYFUNCTION("""COMPUTED_VALUE"""),"")
C40: =IFERROR(__xludf.DUMMYFUNCTION("""COMPUTED_VALUE"""),"3) Inmunización") -> 3) Inmunización | F40: =COUNTIF('2012-2022'!N:N,C40) -> 36
C41: =IFERROR(__xludf.DUMMYFUNCTION("""COMPUTED_VALUE"""),"1) Reporte de cepas resistentes") -> 1) Reporte de cepas resistentes | F41: =COUNTIF('2012-2022'!N:N,C41) -> 172
C42: =IFERROR(__xludf.DUMMYFUNCTION("""COMPUTED_VALUE"""),"2) Nuevos tratamientos ") -> 2) Nuevos tratamientos | F42: =COUNTIF('2012-2022'!N:N,C42) -> 115
F43: =COUNTIF('2012-2022'!N:N,C43) -> 0
F44: =COUNTIF('2012-2022'!N:N,C44) -> 0
F45: =COUNTIF('2012-2022'!N:N,C45) -> 0
F46: =COUNTIF('2012-2022'!N:N,C46) -> 0
F47: =SUM(F40:F45) -> 323

Sheet categorias
A1: Categorias | B1: Subcategorias | C1: Estados
A2: 1) Reporte de cepas resistentes | B2: 2a) Productos naturales | C2: Revisar
A3: 2) Nuevos tratamientos | B3: 2b) Péptidos | C3: Listo
A4: 3) Inmunizacióm | B4: 2c) Droga de diseño | C4: Excluir
A5: 4) otros | B5: 2d) Anticuerpos | C5: Otros-A
B6: 2e) Bacteriófagos | C6: Otros-B
B7: 2f) Estrategias antivirulencia | C7: Otros-C
B8: 2g) nueva combinación de ATB | C8: Otros-D

Sheet TablasDinamicas
B1: Etiquetas de fila | C1: Cuenta de Title | E1: Cuenta de Title | I1: Categoria | J1: subcategoria | K1: Cuenta de Title
B2: PreAlerta | C2: 3059 | E2: PubYear | F2: PubMonth | G2: Total | I2: 1) Reporte de cepas resistentes | J2: (en blanco) | K2: 2 | L2: 1) Interacción huésped-patógeno | M2: (en blanco) | N2: =GETPIVOTDATA("Title",$I$1,"Categoria",L2,"subcategoria",M2) -> #REF!
B3: PostAlerta | C3: 4841 | E3: 2014 | F3: Jan | G3: 33 | I3: Total 1) Reporte de cepas resistentes | K3: 2 | L3: 1) Reporte de cepas resistentes | M3: (en blanco) | N3: =GETPIVOTDATA("Title",$I$1,"Categoria",L3,"subcategoria",M3) -> #REF!
B4: Excluido | C4: 708 | F4: Feb | G4: 30 | I4: 2) Nuevos tratamientos | J4: 4d) Anticuerpos | K4: 1 | L4: 3) Casos clínicos | M4: (en blanco) | N4: =GETPIVOTDATA("Title",$I$1,"Categoria",L4,"subcategoria",M4) -> #REF!
B5: Total general | C5: 8608 | F5: Mar | G5: 27 | J5: 4e) Bacteriófagos | K5: 1 | L5: 2) Nuevos tratamientos | M5: 4a) Productos naturales | N5: =GETPIVOTDATA("Title",$I$1,"Categoria",L5,"subcategoria",M5) -> #REF!
F6: Apr | G6: 33 | I6: Total 2) Nuevos tratamientos | K6: 2 | L6: 2) Nuevos tratamientos | M6: 4b) Péptidos | N6: =GETPIVOTDATA("Title",$I$1,"Categoria",L6,"subcategoria",M6) -> #REF!
B7: Etiquetas de fila | C7: Cuenta de Title | F7: May | G7: 26 | I7: (en blanco) | J7: (en blanco) | K7: 3127 | L7: 2) Nuevos tratamientos | M7: 4c) Droga de diseño | N7: =GETPIVOTDATA("Title",$I$1,"Categoria",L7,"subcategoria",M7) -> #REF!
B8: S/PalabrasClaves | C8: 3131 | F8: Jun | G8: 31 | I8: Total (en blanco) | K8: 3127 | L8: 2) Nuevos tratamientos | M8: 4d) Anticuerpos | N8: =GETPIVOTDATA("Title",$I$1,"Categoria",L8,"subcategoria",M8) -> #REF!
B9: Excluido | C9: 152 | F9: Jul | G9: 32 | I9: Total general | K9: 3131 | L9: 2) Nuevos tratamientos | M9: 4e) Bacteriófagos | N9: =GETPIVOTDATA("Title",$I$1,"Categoria",L9,"subcategoria",M9) -> #REF!
B10: PostAlerta | C10: 1883 | F10: Aug | G10: 26 | L10: 2) Nuevos tratamientos | M10: 4f) Estrategias antivirulencia | N10: =GETPIVOTDATA("Title",$I$1,"Categoria",L10,"subcategoria",M10) -> #REF!
B11: PreAlerta | C11: 1096 | F11: Sep | G11: 35
B12: Total general | C12: 3131 | F12: Oct | G12: 39
F13: Nov | G13: 26
B14: Etiquetas de fila | C14: Cuenta de Title | F14: Dec | G14: 34
C15: 2398 | F15: Fall | G15: 1
B16: 2012 | C16: 85 | F16: VerPaper | G16: 24
B17: 2013 | C17: 150 | E17: Total 2014 | G17: 397
B18: 2014 | C18: 129 | E18: Total general | G18: 397
B19: 2015 | C19: 159
B20: 2016 | C20: 161
B21: 2017 | C21: 49
B22: Total general | C22: 3131
B25: Etiquetas de fila | C25: Cuenta de Title
B26: Revisar | C26: 1
B27: (en blanco) | C27: 8607
B28: Total general | C28: 8608

Sheet 2012-2022
A1: PMID | B1: Title | C1: Authors | D1: Citation | E1: Columna1 | F1: Columna2 | G1: Columna3 | H1: Columna4 | I1: Columna5 | J1: Columna6 | K1: Columna7 | L1: Alerta | M1: KeyWords | N1: Categoria | O1: subcategoria | P1: Columna8 | Q1: Estado | R1: PubYear | S1: Mes | T1: Abstract | U1: 1) Antimicrobial Resistance stain | V1: 2) New treatment | W1: 3) Immunization | X1: Human_summary
A2: 36909845 | B2: Real-time PCR has advantages over culture-based methods in identifying major airway bacterial pathogens in chronic obstructive pulmonary disease: Results from three clinical studies in Europe and North America | C2: Schoonbroodt S, Ichanté JL, Boffé S, Devos N, Devaster JM, Taddei L, Rondini S, Arora AK, Pascal T, Malvaux L. | D2: Front Microbiol. 2023 Feb 24 | E2: Schoonbroodt S | F2: Front Microbiol | G2: 2023 | H2: 44998 | I2: PMC10000296 | K2: 10.3389/fmicb.2022.1098133 | L2: =IF(ISNUMBER(VLOOKUP(A2,EXCL,1,FALSE)),"Excluido",IF(ISNUMBER(VLOOKUP(A2,POST,1,FALSE)),"PostAlerta",IF(ISNUMBER(VLOOKUP(A2,PRE,1,FALSE)),"PreAlerta",""))) -> PostAlerta | M2: =IF(ISNUMBER(VLOOKUP(A2,KEYWORDS,1,FALSE)),"C/PalabrasClaves","S/PalabrasClaves") -> S/PalabrasClaves | P2: 2023 Feb 24 | Q2: Excluir | R2: =LEFT(P2,4) -> 2023 | S2: Feb
A3: 36777029 | B3: Dynamics of community-acquired meningitis syndrome outbreaks in southern France | C3: Morsli M, Salipante F, Kerharo Q, Boudet A, Stephan R, Dunyach-Remy C, Zandotti C, Lavigne JP, Drancourt M. | D3: Front Microbiol. 2023 Jan 26 | E3: Morsli M | F3: Front Microbiol | G3: 2023 | H3: 44970 | I3: PMC9909019 | K3: 10.3389/fmicb.2022.1102130 | L3: =IF(ISNUMBER(VLOOKUP(A3,EXCL,1,FALSE)),"Excluido",IF(ISNUMBER(VLOOKUP(A3,POST,1,FALSE)),"PostAlerta",IF(ISNUMBER(VLOOKUP(A3,PRE,1,FALSE)),"PreAlerta",""))) -> PostAlerta | M3: =IF(ISNUMBER(VLOOKUP(A3,KEYWORDS,1,FALSE)),"C/PalabrasClaves","S/PalabrasClaves") -> S/PalabrasClaves | N3: =IF(ISNUMBER(SEARCH("TREATMENT", B3)), "4) Nuevos tratamientos", "") | P3: 2023 Jan 26 | Q3: Excluir | R3: =LEFT(P3,4) -> 2023 | S3: Jan
A4: 36685526 | B4: Comparing the pertussis antibody levels of healthy children immunized with four doses of DTap-IPV/Hib (Pentaxim) combination vaccine and DTaP vaccine in Quzhou, China | C4: Yin Z, Zheng C, Fang Q, Wen T, Wang S, Li J, Gong X, Xiang Z. | D4: Front Immunol. 2023 Jan 6 | E4: Yin Z | F4: Front Immunol | G4: 2023 | H4: 44949 | I4: PMC9852981 | K4: 10.3389/fimmu.2022.1055677 | L4: =IF(ISNUMBER(VLOOKUP(A4,EXCL,1,FALSE)),"Excluido",IF(ISNUMBER(VLOOKUP(A4,POST,1,FALSE)),"PostAlerta",IF(ISNUMBER(VLOOKUP(A4,PRE,1,FALSE)),"PreAlerta",""))) -> PostAlerta | M4: =IF(ISNUMBER(A4),(IF(ISNUMBER(VLOOKUP(A4,KEYWORDS,1,FALSE)),"C/PalabrasClaves","S/PalabrasClaves")),"") -> S/PalabrasClaves | N4: =IF(ISNUMBER(SEARCH("TREATMENT", B4)), "4) Nuevos tratamientos", "") | P4: 2023 Jan 6 | Q4: Excluir | R4: =LEFT(P4,4) -> 2023 | S4: Jan
A5: 34261660 | B5: Metagenomics of the lacrimal sac in primary acquired nasolacrimal duct obstruction: the Lacriome paper 1 | C5: Ali MJ. | D5: Br J Ophthalmol. 2023 Jan | E5: Ali MJ | F5: Br J Ophthalmol | G5: 2023 | H5: 44392 | K5: 10.1136/bjophthalmol-2021-319677 | L5: =IF(ISNUMBER(VLOOKUP(A5,EXCL,1,FALSE)),"Excluido",IF(ISNUMBER(VLOOKUP(A5,POST,1,FALSE)),"PostAlerta",IF(ISNUMBER(VLOOKUP(A5,PRE,1,FALSE)),"PreAlerta",""))) -> PostAlerta | M5: =IF(ISNUMBER(A5),(IF(ISNUMBER(VLOOKUP(A5,KEYWORDS,1,FALSE)),"C/PalabrasClaves","S/PalabrasClaves")),"") -> S/PalabrasClaves | N5: =IF(ISNUMBER(SEARCH("TREATMENT", B5)), "4) Nuevos tratamientos", "") | O5: 4a) Productos naturales | P5: 2023 Jan | Q5: Excluir | R5: =LEFT(P5,4) -> 2023 | S5: Jan
A6: 34654665 | B6: Occurrence of Haemophilus influenzae type b (Hib) meningitis in a 2 month-old infant in the Hib vaccination era | C6: Cho Y, Tomari K, Nagamine T, Fujiwara N. | D6: J Microbiol Immunol Infect. 2022 Jun | E6: Cho Y | F6: J Microbiol Immunol Infect | G6: 2022 | H6: 44485 | K6: 10.1016/j.jmii.2021.09.012 | L6: =IF(ISNUMBER(VLOOKUP(A6,EXCL,1,FALSE)),"Excluido",IF(ISNUMBER(VLOOKUP(A6,POST,1,FALSE)),"PostAlerta",IF(ISNUMBER(VLOOKUP(A6,PRE,1,FALSE)),"PreAlerta",""))) -> PostAlerta | M6: =IF(ISNUMBER(A6),(IF(ISNUMBER(VLOOKUP(A6,KEYWORDS,1,FALSE)),"C/PalabrasClaves","S/PalabrasClaves")),"") -> S/PalabrasClaves | N6: 3) Inmunización | P6: 2022 Jun | Q6: Excluir | R6: =LEFT(P6,4) -> 2022 | S6: Jun | T6: Occurrence of Haemophilus influenzae type b (Hib) meningitis in a 2 month-old infant in the Hib vaccination era | X6: Case of Hib in infant during vaccination era highlights importance of vaccine coverage and efficacy
A7: 34362705 | B7: Septicemia and meningitis associated with Haemophilus influenzae type b vaccine failure | C7: López López S, Del Rosal T, Jiménez Bueno S, Baquero-Artigao F. | D7: Enferm Infecc Microbiol Clin (Engl Ed). 2021 Oct | E7: López López S | F7: Enferm Infecc Microbiol Clin (Engl Ed) | G7: 2021 | H7: 44415 | K7: 10.1016/j.eimce.2021.07.005 | L7: =IF(ISNUMBER(VLOOKUP(A7,EXCL,1,FALSE)),"Excluido",IF(ISNUMBER(VLOOKUP(A7,POST,1,FALSE)),"PostAlerta",IF(ISNUMBER(VLOOKUP(A7,PRE,1,FALSE)),"PreAlerta",""))) -> PostAlerta | M7: =IF(ISNUMBER(A7),(IF(ISNUMBER(VLOOKUP(A7,KEYWORDS,1,FALSE)),"C/PalabrasClaves","S/PalabrasClaves")),"") -> S/PalabrasClaves | N7: 3) Inmunización | P7: 2021 Oct | Q7: Listo | R7: =LEFT(P7,4) -> 2021 | S7: Oct | T7: Septicemia and meningitis associated with Haemophilus influenzae type b vaccine failure | U7: No | V7: No | W7: Yes | X7: Describes a case of Hib septicemia and meningitis after vaccination, highlighting flaws in vaccine efficacy and the need for surveillance.
A8: 35020530 | B8: Systematic review of the efficacy, effectiveness and impact of high-valency pneumococcal conjugate vaccines on otitis media | C8: Izurieta P, Scherbakov M, Nieto Guevara J, Vetter V, Soumahoro L. | D8: Hum Vaccin Immunother. 2022 Dec 31 | E8: Izurieta P | F8: Hum Vaccin Immunother | G8: 2022 | H8: 44573 | I8: PMC8973322 | K8: 10.1080/21645515.2021.2013693 | L8: =IF(ISNUMBER(VLOOKUP(A8,EXCL,1,FALSE)),"Excluido",IF(ISNUMBER(VLOOKUP(A8,POST,1,FALSE)),"PostAlerta",IF(ISNUMBER(VLOOKUP(A8,PRE,1,FALSE)),"PreAlerta",""))) -> Excluido | M8: =IF(ISNUMBER(A8),(IF(ISNUMBER(VLOOKUP(A8,KEYWORDS,1,FALSE)),"C/PalabrasClaves","S/PalabrasClaves")),"") -> S/PalabrasClaves | O8: 4e) Bacteriófagos | P8: 2022 Dec 31 | Q8: Excluir | R8: =LEFT(P8,4) -> 2022 | S8: Dec
A9: 28506825 | B9: Multiple drug resistance in Haemophilus influenzae isolated from patients in Bangkok, Thailand | C9: Tribuddharat C, Srifuengfung S. | D9: J Glob Antimicrob Resist. 2017 Jun | E9: Tribuddharat C | F9: J Glob Antimicrob Resist | G9: 2017 | H9: 42872 | K9: 10.1016/j.jgar.2017.03.003 | L9: =IF(ISNUMBER(VLOOKUP(A9,EXCL,1,FALSE)),"Excluido",IF(ISNUMBER(VLOOKUP(A9,POST,1,FALSE)),"PostAlerta",IF(ISNUMBER(VLOOKUP(A9,PRE,1,FALSE)),"PreAlerta",""))) -> PostAlerta | M9: =IF(ISNUMBER(A9),(IF(ISNUMBER(VLOOKUP(A9,KEYWORDS,1,FALSE)),"C/PalabrasClaves","S/PalabrasClaves")),"") -> C/PalabrasClaves | N9: 1) Reporte de cepas resistentes | P9: 2017 Jun | Q9: Listo | R9: =LEFT(P9,4) -> 2017 | S9: Jun | T9: Multiple drug resistance in Haemophilus influenzae isolated from patients in Bangkok, Thailand | U9: Yes | V9: No | W9: No | X9: The emergence of multi-resistant H. influenzae strains in Bangkok is documented, warning of the spread of antibiotic resistance.
A10: 34270376 | B10: Gaps in knowledge about the vaccine coverage of immunocompromised children: a scoping review | C10: MacDonald SE, Palichuk A, Slater L, Tripp H, Reifferscheid L, Burton C. | D10: Hum Vaccin Immunother. 2022 Dec 31 | E10: MacDonald SE | F10: Hum Vaccin Immunother | G10: 2022 | H10: 44393 | I10: PMC8920240 | K10: 10.1080/21645515.2021.1935169 | L10: =IF(ISNUMBER(VLOOKUP(A10,EXCL,1,FALSE)),"Excluido",IF(ISNUMBER(VLOOKUP(A10,POST,1,FALSE)),"PostAlerta",IF(ISNUMBER(VLOOKUP(A10,PRE,1,FALSE)),"PreAlerta",""))) -> Excluido | M10: =IF(ISNUMBER(A10),(IF(ISNUMBER(VLOOKUP(A10,KEYWORDS,1,FALSE)),"C/PalabrasClaves","S/PalabrasClaves")),"") -> S/PalabrasClaves | N10: =IF(ISNUMBER(SEARCH("TREATMENT", B10)), "4) Nuevos tratamientos", "") | P10: 2022 Dec 31 | Q10: Excluir | R10: =LEFT(P10,4) -> 2022 | S10: Dec
A11: 33735585 | B11: Impact after 10-year use of pneumococcal conjugate vaccine in the Brazilian national immunization program: an updated systematic literature review from 2015 to 2020 | C11: Guzman-Holst A, de Barros E, Rubio P, DeAntonio R, Cintra O, Abreu A. | D11: Hum Vaccin Immunother. 2022 Dec 31 | E11: Guzman-Holst A | F11: Hum Vaccin Immunother | G11: 2022 | H11: 44273 | I11: PMC8920160 | K11: 10.1080/21645515.2021.1879578 | L11: =IF(ISNUMBER(VLOOKUP(A11,EXCL,1,FALSE)),"Excluido",IF(ISNUMBER(VLOOKUP(A11,POST,1,FALSE)),"PostAlerta",IF(ISNUMBER(VLOOKUP(A11,PRE,1,FALSE)),"PreAlerta",""))) -> Excluido | M11: =IF(ISNUMBER(A11),(IF(ISNUMBER(VLOOKUP(A11,KEYWORDS,1,FALSE)),"C/PalabrasClaves","S/PalabrasClaves")),"") -> S/PalabrasClaves | N11: =IF(ISNUMBER(SEARCH("TREATMENT", B11)), "4) Nuevos tratamientos", "") | P11: 2022 Dec 31 | Q11: Excluir | R11: =LEFT(P11,4) -> 2022 | S11: Dec
A12: 27289531 | B12: Increasing resistance to fluoroquinolones among Haemophilus species in Southern Taiwan | C12: Chang CM, Tang HJ, Wang LR, Shih HI, Huang CC, Lee NY, Lee CC, Ko WC. | D12: J Microbiol Immunol Infect. 2017 Apr | E12: Chang CM | F12: J Microbiol Immunol Infect | G12: 2017 | H12: 42534 | K12: 10.1016/j.jmii.2016.04.002 | L12: =IF(ISNUMBER(VLOOKUP(A12,EXCL,1,FALSE)),"Excluido",IF(ISNUMBER(VLOOKUP(A12,POST,1,FALSE)),"PostAlerta",IF(ISNUMBER(VLOOKUP(A12,PRE,1,FALSE)),"PreAlerta",""))) -> PostAlerta | M12: =IF(ISNUMBER(A12),(IF(ISNUMBER(VLOOKUP(A12,KEYWORDS,1,FALSE)),"C/PalabrasClaves","S/PalabrasClaves")),"") -> C/PalabrasClaves | N12: 1) Reporte de cepas resistentes | P12: 2017 Apr | Q12: Listo | R12: =LEFT(P12,4) -> 2017 | S12: Apr | T12: Increasing resistance to fluoroquinolones among Haemophilus species in Southern Taiwan | U12: Yes | V12: No | W12: No | X12: In southern Taiwan, Haemophilus spp. are showing increasing resistance to fluoroquinolones, compromising standard therapies.
A13: 28332810 | B13: Betalaktamresistens hos Haemophilus influenzae | C13: Skaare D. | D13: Tidsskr Nor Laegeforen. 2017 Mar 21 | E13: Skaare D | F13: Tidsskr Nor Laegeforen | G13: 2017 | H13: 42818 | K13: 10.4045/tidsskr.17.0010 | L13: =IF(ISNUMBER(VLOOKUP(A13,EXCL,1,FALSE)),"Excluido",IF(ISNUMBER(VLOOKUP(A13,POST,1,FALSE)),"PostAlerta",IF(ISNUMBER(VLOOKUP(A13,PRE,1,FALSE)),"PreAlerta",""))) -> PostAlerta | M13: =IF(ISNUMBER(A13),(IF(ISNUMBER(VLOOKUP(A13,KEYWORDS,1,FALSE)),"C/PalabrasClaves","S/PalabrasClaves")),"") -> S/PalabrasClaves | N13: 1) Reporte de cepas resistentes | P13: 2017 Mar 21 | Q13: Listo | R13: =LEFT(P13,4) -> 2017 | S13: Mar | T13: Betalaktamresistens hos Haemophilus influenzae | U13: Yes | V13: No | W13: No | X13: Describes the increase in H. influenzae strains with resistance to β-lactams.
A14: 27181174 | B14: Antimicrobial resistance in cystic fibrosis isolates of Haemophilus influenzae | C14: Atkinson CT, Tristram SG. | D14: Br J Biomed Sci. 2016 | E14: Atkinson CT | F14: Br J Biomed Sci | G14: 2016 | H14: 42507 | K14: 10.1080/09674845.2016.1165408 | L14: =IF(ISNUMBER(VLOOKUP(A14,EXCL,1,FALSE)),"Excluido",IF(ISNUMBER(VLOOKUP(A14,POST,1,FALSE)),"PostAlerta",IF(ISNUMBER(VLOOKUP(A14,PRE,1,FALSE)),"PreAlerta",""))) -> PreAlerta | M14: =IF(ISNUMBER(A14),(IF(ISNUMBER(VLOOKUP(A14,KEYWORDS,1,FALSE)),"C/PalabrasClaves","S/PalabrasClaves")),"") -> C/PalabrasClaves | N14: 1) Reporte de cepas resistentes | P14: 2016 | R14: =LEFT(P14,4) -> 2016 | S14: Sci | T14: Antimicrobial resistance in cystic fibrosis isolates of Haemophilus influenzae | U14: Yes | V14: No | W14: No | X14: Antimicrobial resistance in cystic fibrosis Haemophilus influenzae strains presents challenges in the treatment and management of pulmonary infections.
A15: 36466693 | B15: Evaluation of molecular typing for national surveillance of invasive clinical Haemophilus influenzae isolates from Denmark | C15: Slotved HC, Johannesen TB, Stegger M, Fuursted K. | D15: Front Microbiol. 2022 Nov 17 | E15: Slotved HC | F15: Front Microbiol | G15: 2022 | H15: 44900 | I15: PMC9712784 | K15: 10.3389/fmicb.2022.1030242 | L15: =IF(ISNUMBER(VLOOKUP(A15,EXCL,1,FALSE)),"Excluido",IF(ISNUMBER(VLOOKUP(A15,POST,1,FALSE)),"PostAlerta",IF(ISNUMBER(VLOOKUP(A15,PRE,1,FALSE)),"PreAlerta",""))) -> PostAlerta | M15: =IF(ISNUMBER(A15),(IF(ISNUMBER(VLOOKUP(A15,KEYWORDS,1,FALSE)),"C/PalabrasClaves","S/PalabrasClaves")),"") -> S/PalabrasClaves | N15: =IF(ISNUMBER(SEARCH("TREATMENT", B15)), "4) Nuevos tratamientos", "") | P15: 2022 Nov 17 | Q15: Excluir | R15: =LEFT(P15,4) -> 2022 | S15: Nov
A16: 36466632 | B16: Development and clinical application of a endonuclease restriction real-time loop-mediated isothermal amplification (ERT-LAMP) assay for rapid detection of Haemophilus influenzae | C16: Cheng J, Zhou Y, Zhao X, Lu J, Wu J, Wang Y. | D16: Front Microbiol. 2022 Nov 17 | E16: Cheng J | F16: Front Microbiol | G16: 2022 | H16: 44900 | I16: PMC9712716 | K16: 10.3389/fmicb.2022.1037343 | L16: =IF(ISNUMBER(VLOOKUP(A16,EXCL,1,FALSE)),"Excluido",IF(ISNUMBER(VLOOKUP(A16,POST,1,FALSE)),"PostAlerta",IF(ISNUMBER(VLOOKUP(A16,PRE,1,FALSE)),"PreAlerta",""))) -> PostAlerta | M16: =IF(ISNUMBER(A16),(IF(ISNUMBER(VLOOKUP(A16,KEYWORDS,1,FALSE)),"C/PalabrasClaves","S/PalabrasClaves")),"") -> S/PalabrasClaves | N16: =IF(ISNUMBER(SEARCH("TREATMENT", B16)), "4) Nuevos tratamientos", "") | P16: 2022 Nov 17 | Q16: Excluir | R16: =LEFT(P16,4) -> 2022 | S16: Nov
A17: 36355776 | B17: Household fuel use and its association with potential respiratory pathogens among healthy mothers and children in Ethiopia | C17: Tamire M, Addissie A, Gizaw S, Abebe T, Geravandi S, Nilsson S, Gonzales-Siles L, Nordén R, Andersson R, Skovbjerg S. | D17: PLoS One. 2022 Nov 10 | E17: Tamire M | F17: PLoS One | G17: 2022 | H17: 44875 | I17: PMC9648707 | K17: 10.1371/journal.pone.0277348 | L17: =IF(ISNUMBER(VLOOKUP(A17,EXCL,1,FALSE)),"Excluido",IF(ISNUMBER(VLOOKUP(A17,POST,1,FALSE)),"PostAlerta",IF(ISNUMBER(VLOOKUP(A17,PRE,1,FALSE)),"PreAlerta",""))) -> PostAlerta | M17: =IF(ISNUMBER(A17),(IF(ISNUMBER(VLOOKUP(A17,KEYWORDS,1,FALSE)),"C/PalabrasClaves","S/PalabrasClaves")),"") -> S/PalabrasClaves | N17: =IF(ISNUMBER(SEARCH("TREATMENT", B17)), "4) Nuevos tratamientos", "") | P17: 2022 Nov 10 | Q17: Excluir | R17: =LEFT(P17,4) -> 2022 | S17: Nov
A18: 26369355 | B18: Acquired macrolide resistance genes in Haemophilus influenzae?-authors' response | C18: Atkinson CT, Kunde DA, Tristram SG. | D18: J Antimicrob Chemother. 2015 Dec | E18: Atkinson CT | F18: J Antimicrob Chemother | G18: 2015 | H18: 42263 | K18: 10.1093/jac/dkv290 | L18: =IF(ISNUMBER(VLOOKUP(A18,EXCL,1,FALSE)),"Excluido",IF(ISNUMBER(VLOOKUP(A18,POST,1,FALSE)),"PostAlerta",IF(ISNUMBER(VLOOKUP(A18,PRE,1,FALSE)),"PreAlerta",""))) -> PreAlerta | M18: =IF(ISNUMBER(A18),(IF(ISNUMBER(VLOOKUP(A18,KEYWORDS,1,FALSE)),"C/PalabrasClaves","S/PalabrasClaves")),"") -> C/PalabrasClaves | N18: 1) Reporte de cepas resistentes | P18: 2 Dec | R18: =LEFT(P18,4) -> 2 D | S18: Dec | T18: Acquired macrolide resistance genes in Haemophilus influenzae?-authors' response | U18: Yes | V18: No | W18: No | X18: Describes acquired macrolide resistance genes in H. influenzae, key to monitoring and managing resistant strains
A19: 36389175 | B19: Diagnostic value of bronchoalveolar lavage fluid metagenomic next-generation sequencing in pediatric pneumonia | C19: Deng W, Xu H, Wu Y, Li J. | D19: Front Cell Infect Microbiol. 2022 Oct 27 | E19: Deng W | F19: Front Cell Infect Microbiol | G19: 2022 | H19: 44882 | I19: PMC9648200 | K19: 10.3389/fcimb.2022.950531 | L19: =IF(ISNUMBER(VLOOKUP(A19,EXCL,1,FALSE)),"Excluido",IF(ISNUMBER(VLOOKUP(A19,POST,1,FALSE)),"PostAlerta",IF(ISNUMBER(VLOOKUP(A19,PRE,1,FALSE)),"PreAlerta",""))) -> PostAlerta | M19: =IF(ISNUMBER(A19),(IF(ISNUMBER(VLOOKUP(A19,KEYWORDS,1,FALSE)),"C/PalabrasClaves","S/PalabrasClaves")),"") -> S/PalabrasClaves | N19: =IF(ISNUMBER(SEARCH("TREATMENT", B19)), "4) Nuevos tratamientos", "") | P19: 2022 Oct 27 | Q19: Excluir | R19: =LEFT(P19,4) -> 2022 | S19: Oct
A20: 36262970 | B20: Changes in Respiratory Pathogens before and after the COVID-19 Pandemic (2018-2021) | C20: Kim KY, Kim JS, Lee YK, Kim GY, Jung BK. | D20: Biomed Res Int. 2022 Oct 10 | E20: Kim KY | F20: Biomed Res Int | G20: 2022 | H20: 44854 | I20: PMC9576381 | K20: 10.1155/2022/1324052 | L20: =IF(ISNUMBER(VLOOKUP(A20,EXCL,1,FALSE)),"Excluido",IF(ISNUMBER(VLOOKUP(A20,POST,1,FALSE)),"PostAlerta",IF(ISNUMBER(VLOOKUP(A20,PRE,1,FALSE)),"PreAlerta",""))) -> PostAlerta | M20: =IF(ISNUMBER(A20),(IF(ISNUMBER(VLOOKUP(A20,KEYWORDS,1,FALSE)),"C/PalabrasClaves","S/PalabrasClaves")),"") -> S/PalabrasClaves | N20: =IF(ISNUMBER(SEARCH("TREATMENT", B20)), "4) Nuevos tratamientos", "") | P20: 2022 Oct 10 | Q20: Excluir | R20: =LEFT(P20,4) -> 2022 | S20: Oct
A21: 36275016 | B21: Protein domain-dependent vesiculation of Lipoprotein A, a protein that is important in cell wall synthesis and fitness of the human respiratory pathogen Haemophilus influenzae | C21: Jalalvand F, Su YC, Manat G, Chernobrovkin A, Kadari M, Jonsson S, Janousková M, Rutishauser D, Semsey S, Løbner-Olesen A, Sandblad L, Flärdh K, Mengin-Lecreulx D, Zubarev RA, Riesbeck K. | D21: Front Cell Infect Microbiol. 2022 Oct 7 | E21: Jalalvand F | F21: Front Cell Infect Microbiol | G21: 2022 | H21: 44858 | I21: PMC9585305 | K21: 10.3389/fcimb.2022.984955 | L21: =IF(ISNUMBER(VLOOKUP(A21,EXCL,1,FALSE)),"Excluido",IF(ISNUMBER(VLOOKUP(A21,POST,1,FALSE)),"PostAlerta",IF(ISNUMBER(VLOOKUP(A21,PRE,1,FALSE)),"PreAlerta",""))) -> PostAlerta | M21: =IF(ISNUMBER(A21),(IF(ISNUMBER(VLOOKUP(A21,KEYWORDS,1,FALSE)),"C/PalabrasClaves","S/PalabrasClaves")),"") -> S/PalabrasClaves | N21: =IF(ISNUMBER(SEARCH("TREATMENT", B21)), "4) Nuevos tratamientos", "") | P21: 2022 Oct 7 | Q21: Excluir | R21: =LEFT(P21,4) -> 2022 | S21: Oct
A22: 34455901 | B22: Bacterial dacryoadenitis: clinical features, microbiology, and management of 45 cases, with a recent uptick in incidence | C22: Wai KM, Locascio JJ, Wolkow N. | D22: Orbit. 2022 Oct | E22: Wai KM | F22: Orbit | G22: 2022 | H22: 44438 | K22: 10.1080/01676830.2021.1966813 | L22: =IF(ISNUMBER(VLOOKUP(A22,EXCL,1,FALSE)),"Excluido",IF(ISNUMBER(VLOOKUP(A22,POST,1,FALSE)),"PostAlerta",IF(ISNUMBER(VLOOKUP(A22,PRE,1,FALSE)),"PreAlerta",""))) -> PostAlerta | M22: =IF(ISNUMBER(A22),(IF(ISNUMBER(VLOOKUP(A22,KEYWORDS,1,FALSE)),"C/PalabrasClaves","S/PalabrasClaves")),"") -> S/PalabrasClaves | N22: =IF(ISNUMBER(SEARCH("TREATMENT", B22)), "4) Nuevos tratamientos", "") | P22: 2022 Oct | Q22: Excluir | R22: =LEFT(P22,4) -> 2022 | S22: Oct
A23: 26318192 | B23: Comment on: Acquired macrolide resistance genes in Haemophilus influenzae? | C23: Roberts MC, No DB, Soge OO. | D23: J Antimicrob Chemother. 2015 Dec | E23: Roberts MC | F23: J Antimicrob Chemother | G23: 2015 | H23: 42247 | K23: 10.1093/jac/dkv258 | L23: =IF(ISNUMBER(VLOOKUP(A23,EXCL,1,FALSE)),"Excluido",IF(ISNUMBER(VLOOKUP(A23,POST,1,FALSE)),"PostAlerta",IF(ISNUMBER(VLOOKUP(A23,PRE,1,FALSE)),"PreAlerta",""))) -> PreAlerta | M23: =IF(ISNUMBER(A23),(IF(ISNUMBER(VLOOKUP(A23,KEYWORDS,1,FALSE)),"C/PalabrasClaves","S/PalabrasClaves")),"") -> C/PalabrasClaves | N23: 1) Reporte de cepas resistentes | P23: 2 Dec | R23: =LEFT(P23,4) -> 2 D | S23: Dec | T23: Comment on: Acquired macrolide resistance genes in Haemophilus influenzae? | U23: Yes | V23: No | W23: No | X23: Analyzes acquired resistance genes, key to managing macrolide-resistant strains.
A24: 36237430 | B24: Real-time multiple cross displacement amplification assay for rapid and sensitive detection of Haemophilus influenzae | C24: Sun C, Jia N, Huang X, Xiao F, Zhou J, Zhang Y, Fu J, Xu Z, Qu D, Cui X, Wang Y. | D24: Front Cell Infect Microbiol. 2022 Sep 27 | E24: Sun C | F24: Front Cell Infect Microbiol | G24: 2022 | H24: 44848 | I24: PMC9551287 | K24: 10.3389/fcimb.2022.1004183 | L24: =IF(ISNUMBER(VLOOKUP(A24,EXCL,1,FALSE)),"Excluido",IF(ISNUMBER(VLOOKUP(A24,POST,1,FALSE)),"PostAlerta",IF(ISNUMBER(VLOOKUP(A24,PRE,1,FALSE)),"PreAlerta",""))) -> PostAlerta | M24: =IF(ISNUMBER(A24),(IF(ISNUMBER(VLOOKUP(A24,KEYWORDS,1,FALSE)),"C/PalabrasClaves","S/PalabrasClaves")),"") -> S/PalabrasClaves | N24: =IF(ISNUMBER(SEARCH("TREATMENT", B24)), "4) Nuevos tratamientos", "") | P24: 2022 Sep 27 | Q24: Excluir | R24: =LEFT(P24,4) -> 2022 | S24: Sep
A25: 36211411 | B25: Evidence of maternal transfer of antigen-specific antibodies in serum and breast milk to infants at high-risk of S. pneumoniae and H. influenzae disease | C25: Martinovich KM, Seppanen EJ, Bleakley AS, Clark SL, Andrews RM, Richmond PC, Binks MJ, Thornton RB, Kirkham LS. | D25: Front Immunol. 2022 Sep 21 | E25: Martinovich KM | F25: Front Immunol | G25: 2022 | H25: 44844 | I25: PMC9535341 | K25: 10.3389/fimmu.2022.1005344 | L25: =IF(ISNUMBER(VLOOKUP(A25,EXCL,1,FALSE)),"Excluido",IF(ISNUMBER(VLOOKUP(A25,POST,1,FALSE)),"PostAlerta",IF(ISNUMBER(VLOOKUP(A25,PRE,1,FALSE)),"PreAlerta",""))) -> Excluido | M25: =IF(ISNUMBER(A25),(IF(ISNUMBER(VLOOKUP(A25,KEYWORDS,1,FALSE)),"C/PalabrasClaves","S/PalabrasClaves")),"") -> S/PalabrasClaves | N25: =IF(ISNUMBER(SEARCH("TREATMENT", B25)), "4) Nuevos tratamientos", "") | P25: 2022 Sep 21 | Q25: Excluir | R25: =LEFT(P25,4) -> 2022 | S25: Sep
A26: 24826882 | B26: Beware and be aware, haemophilus influenzae betalactamase-negative-ampicillin-resistant is not rare | C26: Abraham PS, Ledochowski S, Rulliat E, Mottard N, Friggeri A. | D26: Minerva Anestesiol. 2014 Nov | E26: Abraham PS | F26: Minerva Anestesiol | G26: 2014 | H26: 41775 | L26: =IF(ISNUMBER(VLOOKUP(A26,EXCL,1,FALSE)),"Excluido",IF(ISNUMBER(VLOOKUP(A26,POST,1,FALSE)),"PostAlerta",IF(ISNUMBER(VLOOKUP(A26,PRE,1,FALSE)),"PreAlerta",""))) -> PreAlerta | M26: =IF(ISNUMBER(A26),(IF(ISNUMBER(VLOOKUP(A26,KEYWORDS,1,FALSE)),"C/PalabrasClaves","S/PalabrasClaves")),"") -> C/PalabrasClaves | N26: 1) Reporte de cepas resistentes | P26: 2014 Nov | R26: =LEFT(P26,4) -> 2014 | S26: Nov | T26: Beware and be aware, haemophilus influenzae betalactamase-negative-ampicillin-resistant is not rare | U26: Yes | V26: No | W26: No | X26: Warns about the resistance of Haemophilus influenzae to ampicillin, highlighting its prevalence despite the absence of beta-lactamase.
A27: 35192786 | B27: Product review on the IMD serogroup B vaccine Bexsero® | C27: Deghmane AE, Taha MK. | D27: Hum Vaccin Immunother. 2022 Dec 31 | E27: Deghmane AE | F27: Hum Vaccin Immunother | G27: 2022 | H27: 44614 | I27: PMC8986181 | K27: 10.1080/21645515.2021.2020043 | L27: =IF(ISNUMBER(VLOOKUP(A27,EXCL,1,FALSE)),"Excluido",IF(ISNUMBER(VLOOKUP(A27,POST,1,FALSE)),"PostAlerta",IF(ISNUMBER(VLOOKUP(A27,PRE,1,FALSE)),"PreAlerta",""))) -> PostAlerta | M27: =IF(ISNUMBER(A27),(IF(ISNUMBER(VLOOKUP(A27,KEYWORDS,1,FALSE)),"C/PalabrasClaves","S/PalabrasClaves")),"") -> S/PalabrasClaves | N27: 3) Inmunización | P27: 2022 Dec 31 | Q27: Listo | R27: =LEFT(P27,4) -> 2022 | S27: Dec | T27: Bexsero® is a multicomponent vaccine composed of four major proteins of Neisseria meningitidis: the fHbp, NHBA, NadA and PorA. This vaccine was licensed against invasive meningococcal disease (IMD) due to serogroup B isolates. When administered alone, Bexsero® showed a safety profile similar to other childhood vaccines. It provides an excellent immunogenicity but that requires booster doses in infants and young children. Although the vaccine does not seem to impact on acquisition of carriage of serogroup B isolates, it confers protection against isolates of serogroup B harboring distinct but cross-reactive variants of fHbp, NadA and NHBA. Primary vaccination schemes in infancy underwent a rapid increase after a toddler booster suggesting an anamnestic response and the establishment of a memory response. As Bexsero® targets sub-capsular proteins that can be conserved regardless the capsule, the vaccine can be effective against non-B isolates such as isolates of serogroups W and X. | U27: No | V27: No | W27: Yes | X27: Because it describes the composition, efficacy, safety profile and immunological response of Bexsero®, a vaccine against invasive meningococcal disease caused by Neisseria meningitidis serogroup B, and its potential effectiveness against other serogroups through immunization directed at conserved subcapsular proteins
A28: 35108152 | B28: Surveillance on the adverse events following immunization with the pentavalent vaccine in Zhejiang, China | C28: Pan X, Lv H, Liang H, Wang Y, Shen L, Chen F, Chen Y, Hu Y. | D28: Hum Vaccin Immunother. 2022 Dec 31 | E28: Pan X | F28: Hum Vaccin Immunother | G28: 2022 | H28: 44594 | I28: PMC8986187 | K28: 10.1080/21645515.2021.2021711 | L28: =IF(ISNUMBER(VLOOKUP(A28,EXCL,1,FALSE)),"Excluido",IF(ISNUMBER(VLOOKUP(A28,POST,1,FALSE)),"PostAlerta",IF(ISNUMBER(VLOOKUP(A28,PRE,1,FALSE)),"PreAlerta",""))) -> PostAlerta | M28: =IF(ISNUMBER(A28),(IF(ISNUMBER(VLOOKUP(A28,KEYWORDS,1,FALSE)),"C/PalabrasClaves","S/PalabrasClaves")),"") -> S/PalabrasClaves | N28: 3) Inmunización | P28: 2022 Dec 31 | Q28: Revisar | R28: =LEFT(P28,4) -> 2022 | S28: Dec | T28: Objectives: The aim of this study is to describe the reporting rate of adverse events following immunization (AEFI) with pentavalent vaccine: diphtheria-pertussis-tetanus-poliomyelitis-Haemophilus influenzae type b (DPT-IPV/Hib), and to determine whether the reporting rate of AEFI following DPT-IPV/Hib was higher than the average level of the other vaccines. Methods: Review and describe the AEFI reported to national adverse event following immunization surveillance system (NAEFISS) in Zhejiang province from 2015 to 2020. Reporting rates of AEFI were calculated by age, city, severity of AEFI, categories of AEFI, and reaction categories. The data mining algorithm used in this study was reporting odds ratio (ROR). A value of ROR‑1.96SE >1 (standard error [SE]) was considered as positive signal. Results: NAEFISS received 5726 AEFI reports following DTP-IPV/Hib, with a reporting rate of 20.01/10000 doses. Of the reported AEFI, 202 were serious vaccine product-related reactions, including two cases of anaphylactic shock, five cases of Guillain Barre Syndrome (GBS) and two cases of acute disseminated encephalomyelitis. The reporting rate of fever/redness/induration was the highest among all the clinical diagnosis (14.97/10000 doses). The positive signals were obtained for allergic rash (ROR-1.96SE: 1.36), febrile convulsion (ROR-1.96SE: 1.32) and GBS (ROR-1.96SE: 1.16). Conclusion: The present findings bolstered that the DTP-IPV/Hib administered as the four-dose schedule was generally well tolerated in Chinese infants as we did not identify any new/unexpected safety concern from the NAEFISS during a six-year timespan. Keywords: AEFI (adverse events following immunization); DPT-IPV/Hib(diphtheria-pertussis-tetanus-poliomyelitis-Hib combined vaccine); safety; surveillance; vaccination. | U28: No | V28: No | W28: Yes | X28: Study on safety and adverse event reporting after vaccine administration key to immunization programs
A29: 34319865 | B29: Impact of pneumococcal conjugate vaccines on healthcare utilization and direct costs for otitis media in children ≤2 years of age in two Swedish regions | C29: Edmondson-Jones M, Dibbern T, Hultberg M, Anell B, Medin E, Feng Y, Talarico C. | D29: Hum Vaccin Immunother. 2022 Dec 31 | E29: Edmondson-Jones M | F29: Hum Vaccin Immunother | G29: 2022 | H29: 44405 | I29: PMC8920213 | K29: 10.1080/21645515.2021.1942712 | L29: =IF(ISNUMBER(VLOOKUP(A29,EXCL,1,FALSE)),"Excluido",IF(ISNUMBER(VLOOKUP(A29,POST,1,FALSE)),"PostAlerta",IF(ISNUMBER(VLOOKUP(A29,PRE,1,FALSE)),"PreAlerta",""))) -> PostAlerta | M29: =IF(ISNUMBER(A29),(IF(ISNUMBER(VLOOKUP(A29,KEYWORDS,1,FALSE)),"C/PalabrasClaves","S/PalabrasClaves")),"") -> S/PalabrasClaves | N29: 3) Inmunización | P29: 2022 Dec 31 | Q29: Listo | R29: =LEFT(P29,4) -> 2022 | S29: Dec | T29: In Sweden, the 7-valent pneumococcal conjugate vaccine (PCV7) was introduced in 2009 and replaced by the pneumococcal non-typeable Haemophilus influenzae protein D conjugate vaccine (PHiD-CV) or the 13- valent PCV (PCV13) from late 2009. We assessed the impact of PCVs on rates of antibiotic prescribing, tympanostomy tube placement (TTP), and healthcare resource utilization and direct costs of physician- diagnosed otitis media/acute otitis media (OM) in children ≤2 years of age living in Skåne (PCV7 then PHiD- CV) or Västra Götalandsregionen (VGR; PCV7 then PCV13). Retrospective cohort study using linked patient- level data from national and regional (Skåne and VGR) healthcare databases in Sweden from July 1, 2005, to December 31, 2013 (NCT02742753). Descriptive time-series analyses showed antibiotic prescriptions and TTP incidence declined after PHiD-CV/PCV13 introduction versus the pre-PCV period. The annualized mean frequencies of antibiotic use, primary care visits, outpatient visits, TTP and myringotomy procedures all decreased after PHiD-CV/PCV13 compared with pre-PCV cohorts. Annualized mean total OM-associated healthcare costs decreased in the PCV7 versus pre-PCV cohorts by 20.0% in Skåne and 10.2% in VGR, and further declined in the PHiD-CV and PCV13 cohorts (20.7% and 15.3%, respectively, relative to the PCV7 cohort), although the duration of PCV7 use differed between regions. Decreases in adjusted annualized cost ratios between cohorts per child susceptible to OM were statistically significant after PCV7 introduction and again with either PHiD-CV or PCV13 introduction in both regions. Following sequential PCV introduction, OM-related healthcare utilization and associated costs decreased in the study regions in Sweden. Plain language summary: What is the context?Otitis media is one of the most frequent reasons for healthcare visits and antibiotic use among young children. Although it is considered as a mild illness, the overall economic burden is substantial due to its high frequency.Otitis media can be caused by different bacteria including Streptococcus pneumoniae, which is also responsible for pneumonia and meningitis. Pneumococcal conjugate vaccines Prevenar (Pfizer Inc.), Synflorix (GSK), and Prevenar 13 (Pfizer Inc.) protect against pneumococcal diseases and reduce its occurrence.However, it is not known how the routine use of these vaccines may affect otitis media-related healthcare resources and costs.What is new?In this study, we assessed trends in rates of healthcare utilization and associated costs due to otitis media in young children before (2005-2008) and after (2009-2013) use of pneumococcal conjugate vaccines. The study was conducted in two Swedish regions; one used Prevenar then Synflorix, while the other used Prevenar then Prevenar 13.We found that compared to the period before pneumococcal conjugate vaccine implementation, the postpneumococcal conjugate vaccine period was associated with:What is the impact on current thinking?The use of pneumococcal conjugate vaccines effectively reduces healthcare utilization and resources associated with otitis mediaThis indirect effect on the reduction of otitis media burden provides further benefit to the implementation of pneumococcal vaccination. Keywords: Cost; Sweden; antibiotics; otitis media; pneumococcal conjugate vaccines. | U29: No | V29: No | W29: Yes | X29: This work is classified in immunization because it evaluates the impact of penumococcal vaccines on the reduction of infections and health resources in children.
A30: 33605846 | B30: Exploring the evidence behind the comparable impact of the pneumococcal conjugate vaccines PHiD-CV and PCV13 on overall pneumococcal disease | C30: Izurieta P, Nieto Guevara J. | D30: Hum Vaccin Immunother. 2022 Dec 31 | E30: Izurieta P | F30: Hum Vaccin Immunother | G30: 2022 | H30: 44246 | I30: PMC8920200 | K30: 10.1080/21645515.2021.1872341 | L30: =IF(ISNUMBER(VLOOKUP(A30,EXCL,1,FALSE)),"Excluido",IF(ISNUMBER(VLOOKUP(A30,POST,1,FALSE)),"PostAlerta",IF(ISNUMBER(VLOOKUP(A30,PRE,1,FALSE)),"PreAlerta",""))) -> PostAlerta | M30: =IF(ISNUMBER(A30),(IF(ISNUMBER(VLOOKUP(A30,KEYWORDS,1,FALSE)),"C/PalabrasClaves","S/PalabrasClaves")),"") -> S/PalabrasClaves | N30: 3) Inmunización | P30: 2022 Dec 31 | Q30: Listo | R30: =LEFT(P30,4) -> 2022 | S30: Dec | T30: The worldwide implementation of pneumococcal conjugate vaccines (PCVs) in children has reduced the overall pneumococcal disease burden. Two PCVs are widely available for infant vaccination: the pneumococcal non-typeable Haemophilus influenzae protein D conjugate vaccine (PHiD-CV) and the 13-valent PCV (PCV13). While these PCVs differ in serotype composition (PCV13 includes polysaccharides of serotypes 3, 6A and 19A; PHiD-CV does not), their impact on the overall pneumococcal disease burden in children is comparable. This commentary summarizes the evidence of comparability between PHiD-CV and PCV13 and explores why differences in serotype composition may not necessarily translate into a differential clinical impact. Both vaccines confer similarly high protection against disease caused by vaccine serotypes and lead to a partial replacement by non-vaccine serotypes. PHiD-CV does not protect against serotype 3 disease (not included in the vaccine) and PCV13's effect on this serotype has been inconsistent. PHiD-CV provides some cross-protection against disease caused by vaccine-related serotype 19A but neither vaccine has fully controlled 19A disease. While protection against 19A is higher for PCV13 than PHiD-CV, replacement by non-PCV13 serotypes in settings with a PCV13 program appears to compensate for this difference. This results in a similar residual overall disease burden with both vaccines. Keywords: PCV10; PCV13; PHiD-CV; Pneumococcal conjugate vaccine; children; invasive pneumococcal disease; otitis media; pneumonia; replacement; serotypes. | U30: No | V30: No | W30: Yes | X30: This work is classified in immunization because it analyzes and compares the effectiveness of two pneumococcal conjugate vaccines, focusing on their impact on disease reduction and protection in children.
A31: 36105805 | B31: The collectin SP-A and its trimeric recombinant fragment protect alveolar epithelial cells from the cytotoxic and proinflammatory effects of human cathelicidin in vitro | C31: de Tapia L, García-Fojeda B, Kronqvist N, Johansson J, Casals C. | D31: Front Immunol. 2022 Aug 29 | E31: de Tapia L | F31: Front Immunol | G31: 2022 | H31: 44819 | I31: PMC9464622 | K31: 10.3389/fimmu.2022.994328 | L31: =IF(ISNUMBER(VLOOKUP(A31,EXCL,1,FALSE)),"Excluido",IF(ISNUMBER(VLOOKUP(A31,POST,1,FALSE)),"PostAlerta",IF(ISNUMBER(VLOOKUP(A31,PRE,1,FALSE)),"PreAlerta",""))) -> PostAlerta | M31: =IF(ISNUMBER(A31),(IF(ISNUMBER(VLOOKUP(A31,KEYWORDS,1,FALSE)),"C/PalabrasClaves","S/PalabrasClaves")),"") -> S/PalabrasClaves | N31: =IF(ISNUMBER(SEARCH("TREATMENT", B31)), "4) Nuevos tratamientos", "") | P31: 2022 Aug 29 | Q31: Excluir | R31: =LEFT(P31,4) -> 2022 | S31: Aug
A32: 36081767 | B32: Biofilm aggregates and the host airway-microbial interface | C32: Hall-Stoodley L, McCoy KS. | D32: Front Cell Infect Microbiol. 2022 Aug 23 | E32: Hall-Stoodley L | F32: Front Cell Infect Microbiol | G32: 2022 | H32: 44813 | I32: PMC9445362 | K32: 10.3389/fcimb.2022.969326 | L32: =IF(ISNUMBER(VLOOKUP(A32,EXCL,1,FALSE)),"Excluido",IF(ISNUMBER(VLOOKUP(A32,POST,1,FALSE)),"PostAlerta",IF(ISNUMBER(VLOOKUP(A32,PRE,1,FALSE)),"PreAlerta",""))) -> Excluido | M32: =IF(ISNUMBER(A32),(IF(ISNUMBER(VLOOKUP(A32,KEYWORDS,1,FALSE)),"C/PalabrasClaves","S/PalabrasClaves")),"") -> S/PalabrasClaves | N32: =IF(ISNUMBER(SEARCH("TREATMENT", B32)), "4) Nuevos tratamientos", "") | P32: 2022 Aug 23 | Q32: Excluir | R32: =LEFT(P32,4) -> 2022 | S32: Aug
A33: 36051551 | B33: Gut microbiome characteristics of comorbid generalized anxiety disorder and functional gastrointestinal disease: Correlation with alexithymia and personality traits | C33: Guo X, Lin F, Yang F, Chen J, Cai W, Zou T. | D33: Front Psychiatry. 2022 Aug 16 | E33: Guo X | F33: Front Psychiatry | G33: 2022 | H33: 44806 | I33: PMC9424665 | K33: 10.3389/fpsyt.2022.946808 | L33: =IF(ISNUMBER(VLOOKUP(A33,EXCL,1,FALSE)),"Excluido",IF(ISNUMBER(VLOOKUP(A33,POST,1,FALSE)),"PostAlerta",IF(ISNUMBER(VLOOKUP(A33,PRE,1,FALSE)),"PreAlerta",""))) -> PostAlerta | M33: =IF(ISNUMBER(A33),(IF(ISNUMBER(VLOOKUP(A33,KEYWORDS,1,FALSE)),"C/PalabrasClaves","S/PalabrasClaves")),"") -> S/PalabrasClaves | N33: =IF(ISNUMBER(SEARCH("TREATMENT", B33)), "4) Nuevos tratamientos", "") | P33: 2022 Aug 16 | Q33: Excluir | R33: =LEFT(P33,4) -> 2022 | S33: Aug
A34: 35983167 | B34: The Microbiome in COPD: Emerging Potential for Microbiome-Targeted Interventions | C34: Millares L, Monso E. | D34: Int J Chron Obstruct Pulmon Dis. 2022 Aug 12 | E34: Millares L | F34: Int J Chron Obstruct Pulmon Dis | G34: 2022 | H34: 44792 | I34: PMC9380728 | K34: 10.2147/COPD.S371958 | L34: =IF(ISNUMBER(VLOOKUP(A34,EXCL,1,FALSE)),"Excluido",IF(ISNUMBER(VLOOKUP(A34,POST,1,FALSE)),"PostAlerta",IF(ISNUMBER(VLOOKUP(A34,PRE,1,FALSE)),"PreAlerta",""))) -> Excluido | M34: =IF(ISNUMBER(A34),(IF(ISNUMBER(VLOOKUP(A34,KEYWORDS,1,FALSE)),"C/PalabrasClaves","S/PalabrasClaves")),"") -> S/PalabrasClaves | N34: =IF(ISNUMBER(SEARCH("TREATMENT", B34)), "4) Nuevos tratamientos", "") | P34: 2022 Aug 12 | Q34: Excluir | R34: =LEFT(P34,4) -> 2022 | S34: Aug
A35: 36034696 | B35: Differentiation of otitis media-causing bacteria and biofilms via Raman spectroscopy and optical coherence tomography | C35: Locke AK, Zaki FR, Fitzgerald ST, Sudhir K, Monroy GL, Choi H, Won J, Mahadevan-Jansen A, Boppart SA. | D35: Front Cell Infect Microbiol. 2022 Aug 10 | E35: Locke AK | F35: Front Cell Infect Microbiol | G35: 2022 | H35: 44802 | I35: PMC9400059 | K35: 10.3389/fcimb.2022.869761 | L35: =IF(ISNUMBER(VLOOKUP(A35,EXCL,1,FALSE)),"Excluido",IF(ISNUMBER(VLOOKUP(A35,POST,1,FALSE)),"PostAlerta",IF(ISNUMBER(VLOOKUP(A35,PRE,1,FALSE)),"PreAlerta",""))) -> PostAlerta | M35: =IF(ISNUMBER(A35),(IF(ISNUMBER(VLOOKUP(A35,KEYWORDS,1,FALSE)),"C/PalabrasClaves","S/PalabrasClaves")),"") -> S/PalabrasClaves | N35: =IF(ISNUMBER(SEARCH("TREATMENT", B35)), "4) Nuevos tratamientos", "") | P35: 2022 Aug 10 | Q35: Excluir | R35: =LEFT(P35,4) -> 2022 | S35: Aug
A36: 36032729 | B36: Bioproduction of propionic acid using levulinic acid by engineered Pseudomonas putida | C36: Tiwari R, Sathesh-Prabu C, Lee SK. | D36: Front Bioeng Biotechnol. 2022 Aug 10 | E36: Tiwari R | F36: Front Bioeng Biotechnol | G36: 2022 | H36: 44802 | I36: PMC9399607 | K36: 10.3389/fbioe.2022.939248 | L36: =IF(ISNUMBER(VLOOKUP(A36,EXCL,1,FALSE)),"Excluido",IF(ISNUMBER(VLOOKUP(A36,POST,1,FALSE)),"PostAlerta",IF(ISNUMBER(VLOOKUP(A36,PRE,1,FALSE)),"PreAlerta",""))) -> PostAlerta | M36: =IF(ISNUMBER(A36),(IF(ISNUMBER(VLOOKUP(A36,KEYWORDS,1,FALSE)),"C/PalabrasClaves","S/PalabrasClaves")),"") -> S/PalabrasClaves | N36: =IF(ISNUMBER(SEARCH("TREATMENT", B36)), "4) Nuevos tratamientos", "") | P36: 2022 Aug 10 | Q36: Excluir | R36: =LEFT(P36,4) -> 2022 | S36: Aug
A37: 35947593 | B37: Childhood meningitis in rural Gambia: 10 years of population-based surveillance | C37: Ikumapayi UN, Hill PC, Hossain I, Olatunji Y, Ndiaye M, Badji H, Manjang A, Salaudeen R, Ceesay L, Adegbola RA, Greenwood BM, Mackenzie GA. | D37: PLoS One. 2022 Aug 10 | E37: Ikumapayi UN | F37: PLoS One | G37: 2022 | H37: 44783 | I37: PMC9365145 | K37: 10.1371/journal.pone.0265299 | L37: =IF(ISNUMBER(VLOOKUP(A37,EXCL,1,FALSE)),"Excluido",IF(ISNUMBER(VLOOKUP(A37,POST,1,FALSE)),"PostAlerta",IF(ISNUMBER(VLOOKUP(A37,PRE,1,FALSE)),"PreAlerta",""))) -> PostAlerta | M37: =IF(ISNUMBER(A37),(IF(ISNUMBER(VLOOKUP(A37,KEYWORDS,1,FALSE)),"C/PalabrasClaves","S/PalabrasClaves")),"") -> S/PalabrasClaves | N37: =IF(ISNUMBER(SEARCH("TREATMENT", B37)), "4) Nuevos tratamientos", "") | P37: 2022 Aug 10 | Q37: Excluir | R37: =LEFT(P37,4) -> 2022 | S37: Aug
A38: 36043149 | B38: Common Pathogens and Drug Resistance of Neonatal Pneumonia with New Multichannel Sensor | C38: Dong X, Zhou P, Zhu G. | D38: Contrast Media Mol Imaging. 2022 Aug 8 | E38: Dong X | F38: Contrast Media Mol Imaging | G38: 2022 | H38: 44804 | I38: PMC9377937 | K38: 10.1155/2022/2208636 | L38: =IF(ISNUMBER(VLOOKUP(A38,EXCL,1,FALSE)),"Excluido",IF(ISNUMBER(VLOOKUP(A38,POST,1,FALSE)),"PostAlerta",IF(ISNUMBER(VLOOKUP(A38,PRE,1,FALSE)),"PreAlerta",""))) -> PostAlerta | M38: =IF(ISNUMBER(A38),(IF(ISNUMBER(VLOOKUP(A38,KEYWORDS,1,FALSE)),"C/PalabrasClaves","S/PalabrasClaves")),"") -> C/PalabrasClaves | N38: 1) Reporte de cepas resistentes | P38: 2022 Aug 8 | Q38: Excluir | R38: =LEFT(P38,4) -> 2022 | S38: Aug
A39: 35881575 | B39: Occurrence of influenza and bacterial infections in cancer patients receiving radiotherapy in Ghana | C39: Arjarquah AK, Obodai E, Anie HA, Osei MA, Odoom JK, Bonney JHK, Behene E, Kotey EN, Aboagye J, Nyarko SO, Bentum J, Yeboah C, Kumordjie S, Agbodzi B, Attiku K, Mawuli G, Letizia A, Ampofo WK, Quaye O. | D39: PLoS One. 2022 Jul 26 | E39: Arjarquah AK | F39: PLoS One | G39: 2022 | H39: 44768 | I39: PMC9321433 | K39: 10.1371/journal.pone.0271877 | L39: =IF(ISNUMBER(VLOOKUP(A39,EXCL,1,FALSE)),"Excluido",IF(ISNUMBER(VLOOKUP(A39,POST,1,FALSE)),"PostAlerta",IF(ISNUMBER(VLOOKUP(A39,PRE,1,FALSE)),"PreAlerta",""))) -> PostAlerta | M39: =IF(ISNUMBER(A39),(IF(ISNUMBER(VLOOKUP(A39,KEYWORDS,1,FALSE)),"C/PalabrasClaves","S/PalabrasClaves")),"") -> S/PalabrasClaves | N39: =IF(ISNUMBER(SEARCH("TREATMENT", B39)), "4) Nuevos tratamientos", "") | P39: 2022 Jul 26 | Q39: Excluir | R39: =LEFT(P39,4) -> 2022 | S39: Jul
A40: 36578495 | B40: Inhibition of the different complement pathways has varying impacts on the serum bactericidal activity and opsonophagocytosis against Haemophilus influenzae type b | C40: Muri L, Schubart A, Thorburn C, Zamurovic N, Holbro T, Kammüller M, Pluschke G, Ispasanie E. | D40: Front Immunol. 2022 Dec 12 | E40: Muri L | F40: Front Immunol | G40: 2022 | H40: 44924 | I40: PMC9791579 | K40: 10.3389/fimmu.2022.1020580 | L40: =IF(ISNUMBER(VLOOKUP(A40,EXCL,1,FALSE)),"Excluido",IF(ISNUMBER(VLOOKUP(A40,POST,1,FALSE)),"PostAlerta",IF(ISNUMBER(VLOOKUP(A40,PRE,1,FALSE)),"PreAlerta",""))) -> PostAlerta | M40: =IF(ISNUMBER(A40),(IF(ISNUMBER(VLOOKUP(A40,KEYWORDS,1,FALSE)),"C/PalabrasClaves","S/PalabrasClaves")),"") -> C/PalabrasClaves | N40: 3) Inmunización | P40: 2022 Dec 12 | Q40: Revisar | R40: =LEFT(P40,4) -> 2022 | S40: Dec | T40: Defense against Haemophilus influenzae type b (Hib) is dependent on antibodies and complement, which mediate both serum bactericidal activity (SBA) and opsonophagocytosis. Here we evaluated the influence of capsule-specific antibodies and complement inhibitors targeting the central component C3, the alternative pathway (AP; fB, fD), the lectin pathway (LP; MASP-2) and the terminal pathway (C5) on both effector functions. Findings may be relevant for the treatment of certain diseases caused by dysregulation of the complement system, where inhibitors of complement factors C3 or C5 are used. Inhibitors against other complement components are being evaluated as potential alternative treatment options that may carry a reduced risk of infection by encapsulated bacteria. Serum and reconstituted blood of healthy adults were tested for bactericidal activity before and after vaccination with the Hib capsule-conjugate vaccine ActHIB. Most sera had bactericidal activity prior to vaccination, but vaccination significantly enhanced SBA titers. Independently of the vaccination status, both C3 and C5 inhibition abrogated SBA, whereas inhibition of the LP had no effect. AP inhibition had a major inhibitory effect on SBA of pre- vaccination serum, but vaccination mitigated this inhibition for all disease isolates tested. Despite this, SBA-mediated killing of some Hib isolates remained retarded. Even for the most serum-resistant isolate, SBA was the dominating defense mechanism in reconstituted whole blood, as addition of blood cells to the serum did not enhance bacterial killing. Limited Fc receptor-mediated opsonophagocytosis was unmasked when bacterial killing by the membrane attack complex was blocked. In the presence of C3 or C5 inhibitors, addition of post-vaccination, but not of pre-vaccination serum to the blood cells triggered opsonophagocytosis, leading to suppression of bacterial multiplication. Taken together, our data indicate that for host defense against Hib, killing by SBA is more efficient than by blood cell opsonophagocytosis. However, additional defense mechanisms, such as bacterial clearance by spleen and liver, may play an important role in preventing Hib-mediated sepsis, in particular for Hib isolates with increased serum-resistance. Results indicate potentially improved safety profile of AP inhibitors over C3 and C5 inhibitors as alternative therapeutic agents in patients with increased susceptibility to Hib infection. Keywords: Haemophilus influenzae type b; alternative pathway (AP); complement inhibitors; immunotherapy; opsonophagocytosis; serum bactericidal activity (SBA); vaccination. | U40: No | V40: No | W40: Yes | X40: This work is classified in immunization because it analyzes how vaccination with Hib enhances the immune response, potentiating the antibody- and complement-mediated bactericidal activity against Haemophilus influenzae type b.
...

Sheet Test
A1: PMID | B1: Title | C1: Categoria | D1: subcategoria | E1: Estado | F1: Abstract | G1: 1) Antimicrobial Resistance stain | H1: 2) New treatment | I1: 3) Immunization | J1: Human_summary
A2: 34362705 | B2: Septicemia and meningitis associated with Haemophilus influenzae type b vaccine failure | C2: 3) Inmunización | E2: Listo | F2: Septicemia and meningitis associated with Haemophilus influenzae type b vaccine failure | G2: No | H2: No | I2: Yes | J2: Describes a case of Hib septicemia and meningitis after vaccination, highlighting flaws in vaccine efficacy and the need for surveillance.
A3: 28506825 | B3: Multiple drug resistance in Haemophilus influenzae isolated from patients in Bangkok, Thailand | C3: 1) Reporte de cepas resistentes | E3: Listo | F3: Multiple drug resistance in Haemophilus influenzae isolated from patients in Bangkok, Thailand | G3: Yes | H3: No | I3: No | J3: The emergence of multi-resistant H. influenzae strains in Bangkok is documented, warning of the spread of antibiotic resistance.
A4: 27289531 | B4: Increasing resistance to fluoroquinolones among Haemophilus species in Southern Taiwan | C4: 1) Reporte de cepas resistentes | E4: Listo | F4: Increasing resistance to fluoroquinolones among Haemophilus species in Southern Taiwan | G4: Yes | H4: No | I4: No | J4: In southern Taiwan, Haemophilus spp. are showing increasing resistance to fluoroquinolones, compromising standard therapies.
A5: 28332810 | B5: Betalaktamresistens hos Haemophilus influenzae | C5: 1) Reporte de cepas resistentes | E5: Listo | F5: Betalaktamresistens hos Haemophilus influenzae | G5: Yes | H5: No | I5: No | J5: Describes the increase in H. influenzae strains with resistance to β-lactams.
A6: 27181174 | B6: Antimicrobial resistance in cystic fibrosis isolates of Haemophilus influenzae | C6: 1) Reporte de cepas resistentes | F6: Antimicrobial resistance in cystic fibrosis isolates of Haemophilus influenzae | G6: Yes | H6: No | I6: No | J6: Antimicrobial resistance in cystic fibrosis Haemophilus influenzae strains presents challenges in the treatment and management of pulmonary infections.
A7: 26369355 | B7: Acquired macrolide resistance genes in Haemophilus influenzae?-authors' response | C7: 1) Reporte de cepas resistentes | F7: Acquired macrolide resistance genes in Haemophilus influenzae?-authors' response | G7: Yes | H7: No | I7: No | J7: Describes acquired macrolide resistance genes in H. influenzae, key to monitoring and managing resistant strains
A8: 26318192 | B8: Comment on: Acquired macrolide resistance genes in Haemophilus influenzae? | C8: 1) Reporte de cepas resistentes | F8: Comment on: Acquired macrolide resistance genes in Haemophilus influenzae? | G8: Yes | H8: No | I8: No | J8: Analyzes acquired resistance genes, key to managing macrolide-resistant strains.
A9: 24826882 | B9: Beware and be aware, haemophilus influenzae betalactamase-negative-ampicillin-resistant is not rare | C9: 1) Reporte de cepas resistentes | F9: Beware and be aware, haemophilus influenzae betalactamase-negative-ampicillin-resistant is not rare | G9: Yes | H9: No | I9: No | J9: Warns about the resistance of Haemophilus influenzae to ampicillin, highlighting its prevalence despite the absence of beta-lactamase.
A10: 35192786 | B10: Product review on the IMD serogroup B vaccine Bexsero® | C10: 3) Inmunización | E10: Listo | F10: Bexsero® is a multicomponent vaccine composed of four major proteins of Neisseria meningitidis: the fHbp, NHBA, NadA and PorA. This vaccine was licensed against invasive meningococcal disease (IMD) due to serogroup B isolates. When administered alone, Bexsero® showed a safety profile similar to other childhood vaccines. It provides an excellent immunogenicity but that requires booster doses in infants and young children. Although the vaccine does not seem to impact on acquisition of carriage of serogroup B isolates, it confers protection against isolates of serogroup B harboring distinct but cross-reactive variants of fHbp, NadA and NHBA. Primary vaccination schemes in infancy underwent a rapid increase after a toddler booster suggesting an anamnestic response and the establishment of a memory response. As Bexsero® targets sub-capsular proteins that can be conserved regardless the capsule, the vaccine can be effective against non-B isolates such as isolates of serogroups W and X. | G10: No | H10: No | I10: Yes | J10: Because it describes the composition, efficacy, safety profile and immunological response of Bexsero®, a vaccine against invasive meningococcal disease caused by Neisseria meningitidis serogroup B, and its potential effectiveness against other serogroups through immunization directed at conserved subcapsular proteins
A11: 35108152 | B11: Surveillance on the adverse events following immunization with the pentavalent vaccine in Zhejiang, China | C11: 3) Inmunización | E11: Revisar | F11: Objectives: The aim of this study is to describe the reporting rate of adverse events following immunization (AEFI) with pentavalent vaccine: diphtheria-pertussis-tetanus-poliomyelitis-Haemophilus influenzae type b (DPT-IPV/Hib), and to determine whether the reporting rate of AEFI following DPT-IPV/Hib was higher than the average level of the other vaccines. Methods: Review and describe the AEFI reported to national adverse event following immunization surveillance system (NAEFISS) in Zhejiang province from 2015 to 2020. Reporting rates of AEFI were calculated by age, city, severity of AEFI, categories of AEFI, and reaction categories. The data mining algorithm used in this study was reporting odds ratio (ROR). A value of ROR‑1.96SE >1 (standard error [SE]) was considered as positive signal. Results: NAEFISS received 5726 AEFI reports following DTP-IPV/Hib, with a reporting rate of 20.01/10000 doses. Of the reported AEFI, 202 were serious vaccine product-related reactions, including two cases of anaphylactic shock, five cases of Guillain Barre Syndrome (GBS) and two cases of acute disseminated encephalomyelitis. The reporting rate of fever/redness/induration was the highest among all the clinical diagnosis (14.97/10000 doses). The positive signals were obtained for allergic rash (ROR-1.96SE: 1.36), febrile convulsion (ROR-1.96SE: 1.32) and GBS (ROR-1.96SE: 1.16). Conclusion: The present findings bolstered that the DTP-IPV/Hib administered as the four-dose schedule was generally well tolerated in Chinese infants as we did not identify any new/unexpected safety concern from the NAEFISS during a six-year timespan. Keywords: AEFI (adverse events following immunization); DPT-IPV/Hib(diphtheria-pertussis-tetanus-poliomyelitis-Hib combined vaccine); safety; surveillance; vaccination. | G11: No | H11: No | I11: Yes | J11: Study on safety and adverse event reporting after vaccine administration key to immunization programs
