Workbook
Name BD_aux: #REF!
Name categoria: categorias!$A:$A
Name Estado: categorias!$C$2:$C$65536
Name EXCL: Excluidas!$A:$K
Name EXCLUIDAS: Excluidas!$A$1:$K$463
Name KEYWORDS: 'Palabras claves'!$A:$K
Name NgonorreaePost: '2017-2022'!#REF!
Name NgonorreaePre: '2012-2017'!$A$1:$K$534
Name PalabrasClave: 'Palabras claves'!$K$1:$K$1371
Name POST: '2017-2022'!$A:$K
Name POSTALERTA: '2017-2022'!$A$1:$B$857
Name PRE: '2012-2017'!$A:$K
Name PREALERTA: '2012-2017'!$A$1:$O$540
Name SegmentaciónDeDatos_Alerta1: #REF!
Name SegmentaciónDeDatos_KeyWords: #REF!
Name SegmentaciónDeDatos_PubYear: #REF!
Name subcategoria: categorias!$B:$B
Name TablaNgonoreae: '2012-2022'!$A$1:$K$3740

Sheet DashBoard
C2: Neisseria gonorrhoeae 2012-2022
C3: Total de publicaciones de | F3: =C2 -> Neisseria gonorrhoeae 2012-2022 | G3: : | H3: =COUNTA('2012-2022'!A$1:A$869572)-1 -> 3740
D5: Publicaciones por Año | I5: Categorías y Subcategorías
D17: Publicaciones por mes

Sheet categorias
A1: Categorias | B1: Subcategorias | C1: Estados
A2: 1) Reporte de cepas resistentes | B2: 2a) Productos naturales | C2: Revisar
A3: 2) Nuevos tratamientos | B3: 2b) Péptidos | C3: Listo
A4: 3) Inmunizacióm | B4: 2c) Droga de diseño | C4: Excluir
A5: 4) otros | B5: 2d) Anticuerpos | C5: Otros-A
B6: 2e) Bacteriófagos | C6: Otros-B
B7: 2f) Estrategias antivirulencia | C7: Otros-C
B8: 2g) nueva combinación de ATB | C8: Otros-D

Sheet TablasDinamicas
B1: Etiquetas de fila | C1: Cuenta de Title | E1: Cuenta de Title | I1: Categoria | J1: subcategoria | K1: Cuenta de Title
B2: PreAlerta | C2: 1363 | E2: PubYear | F2: PubMonth | G2: Total | I2: 1) Interacción huésped-patógeno | J2: (en blanco) | K2: 1 | L2: 1) Interacción huésped-patógeno | M2: (en blanco) | N2: =GETPIVOTDATA("Title",$I$1,"Categoria",L2,"subcategoria",M2) -> #REF! | P2: Etiquetas de fila | Q2: Cuenta de Title | S2: Etiquetas de fila | T2: Cuenta de Title | V2: Etiquetas de fila | W2: Cuenta de Title
B3: PostAlerta | C3: 1915 | E3: 2017 | F3: Jan | G3: 18 | I3: Total 1) Interacción huésped-patógeno | K3: 1 | L3: 2) Reporte de cepas resistentes | M3: (en blanco) | N3: =GETPIVOTDATA("Title",$I$1,"Categoria",L3,"subcategoria",M3) -> #REF! | P3: (en blanco) | Q3: 3740 | S3: 2012 | T3: 139 | V3: S/PalabrasClaves | W3: 2369
B4: Excluido | C4: 461 | F4: Feb | G4: 27 | I4: (en blanco) | J4: (en blanco) | K4: 2368 | L4: 3) Casos clínicos | M4: (en blanco) | N4: =GETPIVOTDATA("Title",$I$1,"Categoria",L4,"subcategoria",M4) -> #REF! | P4: Total general | Q4: 3740 | S4: 2013 | T4: 216 | V4: Excluido | W4: 254
B5: Total general | C5: 3739 | F5: Mar | G5: 27 | I5: Total (en blanco) | K5: 2368 | L5: 4) Nuevos tratamientos | M5: 4a) Productos naturales | N5: =GETPIVOTDATA("Title",$I$1,"Categoria",L5,"subcategoria",M5) -> #REF! | S5: 2014 | T5: 213 | V5: PostAlerta | W5: 1186
F6: Apr | G6: 21 | I6: Total general | K6: 2369 | L6: 4) Nuevos tratamientos | M6: 4b) Péptidos | N6: =GETPIVOTDATA("Title",$I$1,"Categoria",L6,"subcategoria",M6) -> #REF! | S6: 2015 | T6: 222 | V6: PreAlerta | W6: 929
F7: May | G7: 24 | L7: 4) Nuevos tratamientos | M7: 4c) Droga de diseño | N7: =GETPIVOTDATA("Title",$I$1,"Categoria",L7,"subcategoria",M7) -> #REF! | S7: 2016 | T7: 204 | V7: Total general | W7: 2369
F8: Jun | G8: 35 | L8: 4) Nuevos tratamientos | M8: 4d) Anticuerpos | N8: =GETPIVOTDATA("Title",$I$1,"Categoria",L8,"subcategoria",M8) -> #REF! | S8: 2017 | T8: 198
F9: Jul | G9: 38 | L9: 4) Nuevos tratamientos | M9: 4e) Bacteriófagos | N9: =GETPIVOTDATA("Title",$I$1,"Categoria",L9,"subcategoria",M9) -> #REF! | S9: 2018 | T9: 227
F10: Aug | G10: 28 | L10: 4) Nuevos tratamientos | M10: 4f) Estrategias antivirulencia | N10: =GETPIVOTDATA("Title",$I$1,"Categoria",L10,"subcategoria",M10) -> #REF! | S10: 2019 | T10: 264
F11: Sep | G11: 34 | S11: 2020 | T11: 254
F12: Oct | G12: 24 | S12: 2021 | T12: 306
F13: Nov | G13: 23 | S13: 2022 | T13: 121
F14: Dec | G14: 27 | S14: 2023 | T14: 1
F15: (en blanco) | G15: 6 | S15: Live | T15: 4
E16: Total 2017 | G16: 332 | S16: Total general | T16: 2369
E17: (en blanco) | F17: Apr | G17: 1
F18: (en blanco)
E19: Total (en blanco) | G19: 1
E20: Live | F20: LiverTox | G20: 5
E21: Total Live | G21: 5
E22: Total general | G22: 338

Sheet 2012-2022
A1: PMID | B1: Title | C1: Authors | D1: Citation | E1: First Author | F1: Journal/Book | G1: Publication Year | H1: Create Date | I1: PMCID | J1: NIHMS ID | K1: DOI | L1: Alerta | M1: KeyWords | N1: Categoria | O1: subcategoria | P1: fecha de publicación | Q1: Estado | R1: PubYear | S1: PubMonth | T1: Abstract | U1: 1) Antimicrobial Resistance stain | V1: 2) New treatment | W1: 3) Immunization | X1: Human_summary
A2: 29430011 | B2: Neisseria gonorrhoeae host adaptation and pathogenesis | C2: Quillin SJ; Seifert HS. | D2: Nat Rev Microbiol. 2018 Apr;16(4):226-240. doi: 10.1038/nrmicro.2017.169. Epub 2018 Feb 12. | E2: Quillin SJ | F2: Nat Rev Microbiol | G2: 2018 | H2: 43144 | I2: PMC6329377 | J2: NIHMS1003492 | K2: 10.1038/nrmicro.2017.169 | L2: =IF(ISNUMBER(VLOOKUP(A2,EXCL,1,FALSE)),"Excluido",IF(ISNUMBER(VLOOKUP(A2,POST,1,FALSE)),"PostAlerta",IF(ISNUMBER(VLOOKUP(A2,PRE,1,FALSE)),"PreAlerta",""))) -> Excluido | M2: =IF(ISNUMBER(VLOOKUP(A2,KEYWORDS,1,FALSE)),"C/PalabrasClaves","S/PalabrasClaves") -> C/PalabrasClaves | N2: =IF(ISNUMBER(SEARCH("TREATMENT", B2)), "4) Nuevos tratamientos", "") | P2: 2018 Apr | R2: =LEFT('2012-2022'!$P2,4) -> 2018 | S2: Apr | T2: =IFERROR(VLOOKUP(A2,BD_aux,2,FALSE),"")
A3: 28991324 | B3: [Neisseria gonorrhoeae] | C3: García-Mendiola R, Aguilera-Arreola MG, Contreras-Rodríguez A. | D3: Rev Chilena Infectol. 2017 Jun;34(3):263-264. doi: 10.4067/S0716-10182017000300010. | E3: García-Mendiola R | F3: Rev Chilena Infectol | G3: 2017 | H3: 43018 | K3: 10.4067/S0716-10182017000300010 | L3: =IF(ISNUMBER(VLOOKUP(A3,EXCL,1,FALSE)),"Excluido",IF(ISNUMBER(VLOOKUP(A3,POST,1,FALSE)),"PostAlerta",IF(ISNUMBER(VLOOKUP(A3,PRE,1,FALSE)),"PreAlerta",""))) -> PostAlerta | M3: =IF(ISNUMBER(VLOOKUP(A3,KEYWORDS,1,FALSE)),"C/PalabrasClaves","S/PalabrasClaves") -> S/PalabrasClaves | N3: =IF(ISNUMBER(SEARCH("TREATMENT", B3)), "4) Nuevos tratamientos", "") | P3: 2017 Jun | R3: =LEFT('2012-2022'!$P3,4) -> 2017 | S3: Jun | T3: =IFERROR(VLOOKUP(A3,BD_aux,2,FALSE),"")
A4: 31119616 | B4: Antimicrobial Resistance in Neisseria gonorrhoeae and Treatment of Gonorrhea | C4: Unemo M, Golparian D, Eyre DW. | D4: Methods Mol Biol. 2019;1997:37-58. doi: 10.1007/978-1-4939-9496-0_3. | E4: Unemo M | F4: Methods Mol Biol | G4: 2019 | H4: 43609 | K4: 10.1007/978-1-4939-9496-0_3 | L4: =IF(ISNUMBER(VLOOKUP(A4,EXCL,1,FALSE)),"Excluido",IF(ISNUMBER(VLOOKUP(A4,POST,1,FALSE)),"PostAlerta",IF(ISNUMBER(VLOOKUP(A4,PRE,1,FALSE)),"PreAlerta",""))) -> PostAlerta | M4: =IF(ISNUMBER(A4),(IF(ISNUMBER(VLOOKUP(A4,KEYWORDS,1,FALSE)),"C/PalabrasClaves","S/PalabrasClaves")),"") -> C/PalabrasClaves | N4: 2) Nuevos tratamientos | O4: 2g) nueva combinación de ATB | P4: 2019 | R4: =LEFT('2012-2022'!$P4,4) -> 2019 | T4: This review highlights the global threat of antimicrobial-resistant Neisseria gonorrhoeae. | U4: Yes | V4: No | W4: No | X4: This review highlights the global threat of antimicrobial-resistant Neisseria gonorrhoeae. | Y4: =IFERROR(VLOOKUP(A2,BD_aux,3,FALSE),"")
A5: 31802195 | B5: Multiresistant Neisseria gonorrhoeae: a new threat in second decade of the XXI century | C5: Młynarczyk-Bonikowska B, Majewska A, Malejczyk M, Młynarczyk G, Majewski S. | D5: Med Microbiol Immunol. 2020 Apr;209(2):95-108. doi: 10.1007/s00430-019-00651-4. Epub 2019 Dec 4. | E5: Młynarczyk-Bonikowska B | F5: Med Microbiol Immunol | G5: 2020 | H5: 43805 | I5: PMC7125254 | K5: 10.1007/s00430-019-00651-4 | L5: =IF(ISNUMBER(VLOOKUP(A5,EXCL,1,FALSE)),"Excluido",IF(ISNUMBER(VLOOKUP(A5,POST,1,FALSE)),"PostAlerta",IF(ISNUMBER(VLOOKUP(A5,PRE,1,FALSE)),"PreAlerta",""))) -> Excluido | M5: =IF(ISNUMBER(A5),(IF(ISNUMBER(VLOOKUP(A5,KEYWORDS,1,FALSE)),"C/PalabrasClaves","S/PalabrasClaves")),"") -> C/PalabrasClaves | N5: =IF(ISNUMBER(SEARCH("TREATMENT", B5)), "4) Nuevos tratamientos", "") | O5: 4c) Droga de diseño | P5: 2020 Apr | R5: =LEFT('2012-2022'!$P5,4) -> 2020 | S5: Apr | T5: =IFERROR(VLOOKUP(A5,BD_aux,2,FALSE),"")
A6: 28754299 | B6: Antimicrobial resistance in Neisseria gonorrhoeae: history, molecular mechanisms and epidemiological aspects of an emerging global threat | C6: Costa-Lourenço APRD, Barros Dos Santos KT, Moreira BM, Fracalanzza SEL, Bonelli RR. | D6: Braz J Microbiol. 2017 Oct-Dec;48(4):617-628. doi: 10.1016/j.bjm.2017.06.001. Epub 2017 Jul 12. | E6: Costa-Lourenço APRD | F6: Braz J Microbiol | G6: 2017 | H6: 42946 | I6: PMC5628311 | K6: 10.1016/j.bjm.2017.06.001 | L6: =IF(ISNUMBER(VLOOKUP(A6,EXCL,1,FALSE)),"Excluido",IF(ISNUMBER(VLOOKUP(A6,POST,1,FALSE)),"PostAlerta",IF(ISNUMBER(VLOOKUP(A6,PRE,1,FALSE)),"PreAlerta",""))) -> Excluido | M6: =IF(ISNUMBER(A6),(IF(ISNUMBER(VLOOKUP(A6,KEYWORDS,1,FALSE)),"C/PalabrasClaves","S/PalabrasClaves")),"") -> C/PalabrasClaves | N6: =IF(ISNUMBER(SEARCH("TREATMENT", B6)), "4) Nuevos tratamientos", "") | O6: 4b) Péptidos | P6: 2017 Oct-Dec | R6: =LEFT('2012-2022'!$P6,4) -> 2017 | S6: Oct | T6: =IFERROR(VLOOKUP(A6,BD_aux,2,FALSE),"")
A7: 30900979 | B7: Identification of Internationally Disseminated Ceftriaxone-Resistant Neisseria gonorrhoeae Strain FC428, China | C7: Chen SC, Han Y, Yuan LF, Zhu XY, Yin YP. | D7: Emerg Infect Dis. 2019 Jul;25(7):1427-1429. doi: 10.3201/eid2507.190172. Epub 2019 Jul 17. | E7: Chen SC | F7: Emerg Infect Dis | G7: 2019 | H7: 43547 | I7: PMC6590750 | K7: 10.3201/eid2507.190172 | L7: =IF(ISNUMBER(VLOOKUP(A7,EXCL,1,FALSE)),"Excluido",IF(ISNUMBER(VLOOKUP(A7,POST,1,FALSE)),"PostAlerta",IF(ISNUMBER(VLOOKUP(A7,PRE,1,FALSE)),"PreAlerta",""))) -> PostAlerta | M7: =IF(ISNUMBER(A7),(IF(ISNUMBER(VLOOKUP(A7,KEYWORDS,1,FALSE)),"C/PalabrasClaves","S/PalabrasClaves")),"") -> C/PalabrasClaves | N7: 1) Reporte de cepas resistentes | P7: 2019 Jul | R7: =LEFT('2012-2022'!$P7,4) -> 2019 | S7: Jul | T7: In 2016, we identified a ceftriaxone-resistant Neisseria gonorrhoeae isolate in China. The strain genotype was identical to the resistant clone FC428 that originated in Japan. Enhanced international collaborative surveillance programs are crucial to track the transmission of the ceftriaxone-resistant clones. | U7: Yes | V7: No | W7: No | X7: Detect a ceftriaxone-resistant Neisseria gonorrhoeae strain in China. | Y7: =IFERROR(VLOOKUP(A5,BD_aux,3,FALSE),"")
A8: 31661379 | B8: Identification of multidrug-resistant Neisseria gonorrhoeae isolates with combined resistance to both ceftriaxone and azithromycin, China, 2017-2018 | C8: Yuan Q, Li Y, Xiu L, Zhang C, Fu Y, Jiang C, Tang L, Peng J. | D8: Emerg Microbes Infect. 2019;8(1):1546-1549. doi: 10.1080/22221751.2019.1681242. | E8: Yuan Q | F8: Emerg Microbes Infect | G8: 2019 | H8: 43768 | I8: PMC6830194 | K8: 10.1080/22221751.2019.1681242 | L8: =IF(ISNUMBER(VLOOKUP(A8,EXCL,1,FALSE)),"Excluido",IF(ISNUMBER(VLOOKUP(A8,POST,1,FALSE)),"PostAlerta",IF(ISNUMBER(VLOOKUP(A8,PRE,1,FALSE)),"PreAlerta",""))) -> PostAlerta | M8: =IF(ISNUMBER(A8),(IF(ISNUMBER(VLOOKUP(A8,KEYWORDS,1,FALSE)),"C/PalabrasClaves","S/PalabrasClaves")),"") -> C/PalabrasClaves | N8: 1) Reporte de cepas resistentes | P8: 2019 | R8: =LEFT('2012-2022'!$P8,4) -> 2019 | T8: The growing multidrug-resistant Neisseria gonorrhoeae is a serious global threat to gonococcal therapy. During 2017-2018, we identified a rare multidrug-resistant (ceftriaxone and azithromycin) strain (GC250) and four strains (GC185, GC195, GC196 and GC249) with both resistance to ceftriaxone and decreased susceptibility to azithromycin. All strains belonged to NG-STAR ST1143, including the mosaic penA-60.001, which is closely related to ceftriaxone resistance. The characterization of antimicrobial resistance (AMR) determinants and phylogenetic analysis showed these five strains were closely related to internationally spreading ceftriaxone-resistant N. gonorrhoeae FC428, but with higher azithromycin MIC. Findings here demonstrated that this clone not only initiated clonal expansion in China, but acquired azithromycin resistance. | U8: Yes | V8: No | W8: No | X8: This study identified five multidrug-resistant Neisseria gonorrhoeae strains in China | Y8: =IFERROR(VLOOKUP(A6,BD_aux,3,FALSE),"")
A9: 28210887 | B9: Drug-resistant Neisseria gonorrhoeae: latest developments | C9: Suay-García B, Pérez-Gracia MT. | D9: Eur J Clin Microbiol Infect Dis. 2017 Jul;36(7):1065-1071. doi: 10.1007/s10096-017-2931-x. Epub 2017 Feb 16. | E9: Suay-García B | F9: Eur J Clin Microbiol Infect Dis | G9: 2017 | H9: 42784 | K9: 10.1007/s10096-017-2931-x | L9: =IF(ISNUMBER(VLOOKUP(A9,EXCL,1,FALSE)),"Excluido",IF(ISNUMBER(VLOOKUP(A9,POST,1,FALSE)),"PostAlerta",IF(ISNUMBER(VLOOKUP(A9,PRE,1,FALSE)),"PreAlerta",""))) -> Excluido | M9: =IF(ISNUMBER(A9),(IF(ISNUMBER(VLOOKUP(A9,KEYWORDS,1,FALSE)),"C/PalabrasClaves","S/PalabrasClaves")),"") -> C/PalabrasClaves | N9: =IF(ISNUMBER(SEARCH("TREATMENT", B9)), "4) Nuevos tratamientos", "") | O9: 4e) Bacteriófagos | P9: 2017 Jul | R9: =LEFT('2012-2022'!$P9,4) -> 2017 | S9: Jul | T9: =IFERROR(VLOOKUP(A9,BD_aux,2,FALSE),"")
A10: 32119845 | B10: The frontiers of addressing antibiotic resistance in Neisseria gonorrhoeae | C10: Rubin DHF, Ross JDC, Grad YH. | D10: Transl Res. 2020 Jun;220:122-137. doi: 10.1016/j.trsl.2020.02.002. Epub 2020 Feb 29. | E10: Rubin DHF | F10: Transl Res | G10: 2020 | H10: 43893 | I10: PMC7293957 | J10: NIHMS1580697 | K10: 10.1016/j.trsl.2020.02.002 | L10: =IF(ISNUMBER(VLOOKUP(A10,EXCL,1,FALSE)),"Excluido",IF(ISNUMBER(VLOOKUP(A10,POST,1,FALSE)),"PostAlerta",IF(ISNUMBER(VLOOKUP(A10,PRE,1,FALSE)),"PreAlerta",""))) -> Excluido | M10: =IF(ISNUMBER(A10),(IF(ISNUMBER(VLOOKUP(A10,KEYWORDS,1,FALSE)),"C/PalabrasClaves","S/PalabrasClaves")),"") -> C/PalabrasClaves | N10: =IF(ISNUMBER(SEARCH("TREATMENT", B10)), "4) Nuevos tratamientos", "") | P10: 2020 Jun | R10: =LEFT('2012-2022'!$P10,4) -> 2020 | S10: Jun | T10: =IFERROR(VLOOKUP(A10,BD_aux,2,FALSE),"")
A11: 33720324 | B11: The Next-Generation of Neisseria gonorrhoeae Antimicrobial Resistance Testing | C11: Potter RF, Ransom EM, Burnham CD. | D11: Clin Chem. 2021 Mar 31;67(4):573-575. doi: 10.1093/clinchem/hvab026. | E11: Potter RF | F11: Clin Chem | G11: 2021 | H11: 44270 | K11: 10.1093/clinchem/hvab026 | L11: =IF(ISNUMBER(VLOOKUP(A11,EXCL,1,FALSE)),"Excluido",IF(ISNUMBER(VLOOKUP(A11,POST,1,FALSE)),"PostAlerta",IF(ISNUMBER(VLOOKUP(A11,PRE,1,FALSE)),"PreAlerta",""))) -> PostAlerta | M11: =IF(ISNUMBER(A11),(IF(ISNUMBER(VLOOKUP(A11,KEYWORDS,1,FALSE)),"C/PalabrasClaves","S/PalabrasClaves")),"") -> C/PalabrasClaves | N11: EDITORIAL | P11: 2021 Mar 31 | R11: =LEFT('2012-2022'!$P11,4) -> 2021 | S11: Mar
A12: 28645177 | B12: Mobile genetic elements in Neisseria gonorrhoeae: movement for change | C12: Cehovin A, Lewis SB. | D12: Pathog Dis. 2017 Aug 31;75(6). doi: 10.1093/femspd/ftx071. | E12: Cehovin A | F12: Pathog Dis | G12: 2017 | H12: 42911 | K12: 10.1093/femspd/ftx071 | L12: =IF(ISNUMBER(VLOOKUP(A12,EXCL,1,FALSE)),"Excluido",IF(ISNUMBER(VLOOKUP(A12,POST,1,FALSE)),"PostAlerta",IF(ISNUMBER(VLOOKUP(A12,PRE,1,FALSE)),"PreAlerta",""))) -> Excluido | M12: =IF(ISNUMBER(A12),(IF(ISNUMBER(VLOOKUP(A12,KEYWORDS,1,FALSE)),"C/PalabrasClaves","S/PalabrasClaves")),"") -> C/PalabrasClaves | N12: =IF(ISNUMBER(SEARCH("TREATMENT", B12)), "4) Nuevos tratamientos", "") | O12: 4c) Droga de diseño | P12: 2017 Aug 31 | R12: =LEFT('2012-2022'!$P12,4) -> 2017 | S12: Aug | T12: =IFERROR(VLOOKUP(A12,BD_aux,2,FALSE),"")
A13: 32779717 | B13: Establishing Novel Molecular Algorithms to Predict Decreased Susceptibility to Ceftriaxone in Neisseria gonorrhoeae Strains | C13: Lin EY, Adamson PC, Deng X, Klausner JD. | D13: J Infect Dis. 2021 Apr 8;223(7):1232-1240. doi: 10.1093/infdis/jiaa495. | E13: Lin EY | F13: J Infect Dis | G13: 2021 | H13: 44055 | I13: PMC8030720 | K13: 10.1093/infdis/jiaa495 | L13: =IF(ISNUMBER(VLOOKUP(A13,EXCL,1,FALSE)),"Excluido",IF(ISNUMBER(VLOOKUP(A13,POST,1,FALSE)),"PostAlerta",IF(ISNUMBER(VLOOKUP(A13,PRE,1,FALSE)),"PreAlerta",""))) -> Excluido | M13: =IF(ISNUMBER(A13),(IF(ISNUMBER(VLOOKUP(A13,KEYWORDS,1,FALSE)),"C/PalabrasClaves","S/PalabrasClaves")),"") -> C/PalabrasClaves | N13: =IF(ISNUMBER(SEARCH("TREATMENT", B13)), "4) Nuevos tratamientos", "") | P13: 2021 Apr 8 | R13: =LEFT('2012-2022'!$P13,4) -> 2021 | S13: Apr | T13: =IFERROR(VLOOKUP(A13,BD_aux,2,FALSE),"")
A14: 25410409 | B14: History and epidemiology of antibiotic susceptibilities of Neisseria gonorrhoeae | C14: Shigemura K, Fujisawa M. | D14: Curr Drug Targets. 2015;16(3):272-80. doi: 10.2174/1389450115666141120110724. | E14: Shigemura K | F14: Curr Drug Targets | G14: 2015 | H14: 41964 | K14: 10.2174/1389450115666141120110724 | L14: =IF(ISNUMBER(VLOOKUP(A14,EXCL,1,FALSE)),"Excluido",IF(ISNUMBER(VLOOKUP(A14,POST,1,FALSE)),"PostAlerta",IF(ISNUMBER(VLOOKUP(A14,PRE,1,FALSE)),"PreAlerta",""))) -> Excluido | M14: =IF(ISNUMBER(A14),(IF(ISNUMBER(VLOOKUP(A14,KEYWORDS,1,FALSE)),"C/PalabrasClaves","S/PalabrasClaves")),"") -> C/PalabrasClaves | N14: =IF(ISNUMBER(SEARCH("TREATMENT", B14)), "4) Nuevos tratamientos", "") | O14: 4c) Droga de diseño | P14: 2015 | R14: =LEFT('2012-2022'!$P14,4) -> 2015 | T14: =IFERROR(VLOOKUP(A14,BD_aux,2,FALSE),"")
A15: 34402689 | B15: Large Increase in Azithromycin-Resistant Neisseria gonorrhoeae in Northern Spain | C15: Carballo R, Povoa MC, Abad R, Navarro C, Martin E, Alvarez M, Salgado A, Potel C. | D15: Microb Drug Resist. 2022 Jan;28(1):81-86. doi: 10.1089/mdr.2020.0594. Epub 2021 Aug 16. | E15: Carballo R | F15: Microb Drug Resist | G15: 2022 | H15: 44425 | K15: 10.1089/mdr.2020.0594 | L15: =IF(ISNUMBER(VLOOKUP(A15,EXCL,1,FALSE)),"Excluido",IF(ISNUMBER(VLOOKUP(A15,POST,1,FALSE)),"PostAlerta",IF(ISNUMBER(VLOOKUP(A15,PRE,1,FALSE)),"PreAlerta",""))) -> PostAlerta | M15: =IF(ISNUMBER(A15),(IF(ISNUMBER(VLOOKUP(A15,KEYWORDS,1,FALSE)),"C/PalabrasClaves","S/PalabrasClaves")),"") -> C/PalabrasClaves | N15: 1) Reporte de cepas resistentes | P15: 2022 Jan | R15: =LEFT('2012-2022'!$P15,4) -> 2022 | S15: Jan | T15: The aim of this study was to characterize the evolution of gonorrhea in the general population by correlating epidemiological, genotypic, and antimicrobial resistance data of Neisseria gonorrhoeae isolates collected in northern Spain from 2014 to 2018. One hundred ninety-four strains underwent antimicrobial susceptibility testing and were genetically analyzed by N. gonorrhoeae multiantigen sequence typing. Increasing cases of gonococcal infections have been observed after 2015. Most occurred in male with urethritis. Sequence type (ST)-9972 and ST-1576, the predominant genotypes identified, have not been previously described as epidemic clones. Of great concern was the significant increase in azithromycin-resistant N. gonorrhoeae. More than 30% of these isolates were obtained from men who have sex with men (MSM). ST-12302 was the most prevalent clone among the azithromycin-resistant strains, and was also resistant to penicillin, ciprofloxacin, and tetracycline. This multidrug-resistant clone was exclusively isolated from MSM during 2018. The incidence rates of gonorrhea and azithromycin-resistant N. gonorrhoeae have significantly increased due to the emergence of new clones. ST-12302 has recently been recognized as an epidemic clone; therefore, its surveillance could be the key in controlling further dissemination of azithromycin resistance. These data highlight the need to perform local studies to update treatment guidelines and reinforce preventive measures against gonorrhea. | U15: Yes | V15: No | W15: No | X15: This study characterized the epidemiological and antimicrobial resistance trends of Neisseria gonorrhoeae in northern Spain The spread of ST-12302 and rising resistance rates stress the importance of local surveillance, updated treatment guidelines, and targeted prevention strategies. | Y15: =IFERROR(VLOOKUP(A13,BD_aux,3,FALSE),"")
A16: 31182853 | B16: Neisseria gonorrhoeae resistance driven by antibiotic use | C16: Dong HV, Klausner JD. | D16: Nat Rev Urol. 2019 Sep;16(9):509-510. doi: 10.1038/s41585-019-0206-2. | E16: Dong HV | F16: Nat Rev Urol | G16: 2019 | H16: 43628 | K16: 10.1038/s41585-019-0206-2 | L16: =IF(ISNUMBER(VLOOKUP(A16,EXCL,1,FALSE)),"Excluido",IF(ISNUMBER(VLOOKUP(A16,POST,1,FALSE)),"PostAlerta",IF(ISNUMBER(VLOOKUP(A16,PRE,1,FALSE)),"PreAlerta",""))) -> PostAlerta | M16: =IF(ISNUMBER(A16),(IF(ISNUMBER(VLOOKUP(A16,KEYWORDS,1,FALSE)),"C/PalabrasClaves","S/PalabrasClaves")),"") -> C/PalabrasClaves | N16: =IF(ISNUMBER(SEARCH("TREATMENT", B16)), "4) Nuevos tratamientos", "") | P16: 2019 Sep | R16: =LEFT('2012-2022'!$P16,4) -> 2019 | S16: Sep | T16: =IFERROR(VLOOKUP(A16,BD_aux,2,FALSE),"")
A17: 31378677 | B17: Commensal Neisseria Kill Neisseria gonorrhoeae through a DNA-Dependent Mechanism | C17: Kim WJ, Higashi D, Goytia M, Rendón MA, Pilligua-Lucas M, Bronnimann M, McLean JA, Duncan J, Trees D, Jerse AE, So M. | D17: Cell Host Microbe. 2019 Aug 14;26(2):228-239.e8. doi: 10.1016/j.chom.2019.07.003. Epub 2019 Aug 1. | E17: Kim WJ | F17: Cell Host Microbe | G17: 2019 | H17: 43683 | I17: PMC6728082 | J17: NIHMS1535495 | K17: 10.1016/j.chom.2019.07.003 | L17: =IF(ISNUMBER(VLOOKUP(A17,EXCL,1,FALSE)),"Excluido",IF(ISNUMBER(VLOOKUP(A17,POST,1,FALSE)),"PostAlerta",IF(ISNUMBER(VLOOKUP(A17,PRE,1,FALSE)),"PreAlerta",""))) -> PostAlerta | M17: =IF(ISNUMBER(A17),(IF(ISNUMBER(VLOOKUP(A17,KEYWORDS,1,FALSE)),"C/PalabrasClaves","S/PalabrasClaves")),"") -> C/PalabrasClaves | N17: =IF(ISNUMBER(SEARCH("TREATMENT", B17)), "4) Nuevos tratamientos", "") | P17: 2019 Aug 14 | R17: =LEFT('2012-2022'!$P17,4) -> 2019 | S17: Aug | T17: =IFERROR(VLOOKUP(A17,BD_aux,2,FALSE),"")
A18: 28387837 | B18: Genomic sequencing of Neisseria gonorrhoeae to respond to the urgent threat of antimicrobial-resistant gonorrhea | C18: Abrams AJ, Trees DL. | D18: Pathog Dis. 2017 Jun 1;75(4):10.1093/femspd/ftx041. doi: 10.1093/femspd/ftx041. | E18: Abrams AJ | F18: Pathog Dis | G18: 2017 | H18: 42833 | I18: PMC6956991 | J18: NIHMS1062768 | K18: 10.1093/femspd/ftx041 | L18: =IF(ISNUMBER(VLOOKUP(A18,EXCL,1,FALSE)),"Excluido",IF(ISNUMBER(VLOOKUP(A18,POST,1,FALSE)),"PostAlerta",IF(ISNUMBER(VLOOKUP(A18,PRE,1,FALSE)),"PreAlerta",""))) -> Excluido | M18: =IF(ISNUMBER(A18),(IF(ISNUMBER(VLOOKUP(A18,KEYWORDS,1,FALSE)),"C/PalabrasClaves","S/PalabrasClaves")),"") -> C/PalabrasClaves | N18: =IF(ISNUMBER(SEARCH("TREATMENT", B18)), "4) Nuevos tratamientos", "") | P18: 2017 Jun 1 | R18: =LEFT('2012-2022'!$P18,4) -> 2017 | S18: Jun | T18: =IFERROR(VLOOKUP(A18,BD_aux,2,FALSE),"")
A19: 29553336 | B19: Cephalosporin-Resistant Neisseria gonorrhoeae Clone, China | C19: Chen SC, Yin YP, Chen XS. | D19: Emerg Infect Dis. 2018 Apr;24(4):804-806. doi: 10.3201/eid2404.171817. | E19: Chen SC | F19: Emerg Infect Dis | G19: 2018 | H19: 43179 | I19: PMC5875255 | K19: 10.3201/eid2404.171817 | L19: =IF(ISNUMBER(VLOOKUP(A19,EXCL,1,FALSE)),"Excluido",IF(ISNUMBER(VLOOKUP(A19,POST,1,FALSE)),"PostAlerta",IF(ISNUMBER(VLOOKUP(A19,PRE,1,FALSE)),"PreAlerta",""))) -> PostAlerta | M19: =IF(ISNUMBER(A19),(IF(ISNUMBER(VLOOKUP(A19,KEYWORDS,1,FALSE)),"C/PalabrasClaves","S/PalabrasClaves")),"") -> C/PalabrasClaves | N19: 1) Reporte de cepas resistentes | P19: 2018 Apr | R19: =LEFT('2012-2022'!$P19,4) -> 2018 | S19: Apr | T19: Cephalosporin-resistant Neisseria gonorrhoeae is a major public health concern. N. gonorrhoeae of multiantigen sequence type G1407 and multilocus sequence type 1901 is an internationally spreading cephalosporin-resistant clone. We detected 4 cases of infection with this clone in China and analyzed resistance determinants by using N. gonorrhoeae sequence typing for antimicrobial resistance. | U19: Yes | V19: No | W19: No | X19: This report describes 4 cases in China of Neisseria gonorrhoeae infection caused by the cephalosporin-resistant international clone G1407 (MLST ST1901). | Y19: =IFERROR(VLOOKUP(A17,BD_aux,3,FALSE),"")
A20: 33245688 | B20: Neisseria gonorrhoeae clustering to reveal major European whole-genome-sequencing-based genogroups in association with antimicrobial resistance | C20: Pinto M, Borges V, Isidro J, Rodrigues JC, Vieira L, Borrego MJ, Gomes JP. | D20: Microb Genom. 2021 Feb;7(2):000481. doi: 10.1099/mgen.0.000481. | E20: Pinto M | F20: Microb Genom | G20: 2021 | H20: 44162 | I20: PMC8208699 | K20: 10.1099/mgen.0.000481 | L20: =IF(ISNUMBER(VLOOKUP(A20,EXCL,1,FALSE)),"Excluido",IF(ISNUMBER(VLOOKUP(A20,POST,1,FALSE)),"PostAlerta",IF(ISNUMBER(VLOOKUP(A20,PRE,1,FALSE)),"PreAlerta",""))) -> PostAlerta | M20: =IF(ISNUMBER(A20),(IF(ISNUMBER(VLOOKUP(A20,KEYWORDS,1,FALSE)),"C/PalabrasClaves","S/PalabrasClaves")),"") -> C/PalabrasClaves | N20: =IF(ISNUMBER(SEARCH("TREATMENT", B20)), "4) Nuevos tratamientos", "") | P20: 2021 Feb | R20: =LEFT('2012-2022'!$P20,4) -> 2021 | S20: Feb | T20: =IFERROR(VLOOKUP(A20,BD_aux,2,FALSE),"")
A21: 24275696 | B21: Global resistance of Neisseria gonorrhoeae: when theory becomes reality | C21: Lewis DA. | D21: Curr Opin Infect Dis. 2014 Feb;27(1):62-7. doi: 10.1097/QCO.0000000000000025. | E21: Lewis DA | F21: Curr Opin Infect Dis | G21: 2014 | H21: 41605 | K21: 10.1097/QCO.0000000000000025 | L21: =IF(ISNUMBER(VLOOKUP(A21,EXCL,1,FALSE)),"Excluido",IF(ISNUMBER(VLOOKUP(A21,POST,1,FALSE)),"PostAlerta",IF(ISNUMBER(VLOOKUP(A21,PRE,1,FALSE)),"PreAlerta",""))) -> Excluido | M21: =IF(ISNUMBER(A21),(IF(ISNUMBER(VLOOKUP(A21,KEYWORDS,1,FALSE)),"C/PalabrasClaves","S/PalabrasClaves")),"") -> C/PalabrasClaves | N21: =IF(ISNUMBER(SEARCH("TREATMENT", B21)), "4) Nuevos tratamientos", "") | P21: 2014 Feb | R21: =LEFT('2012-2022'!$P21,4) -> 2014 | S21: Feb | T21: =IFERROR(VLOOKUP(A21,BD_aux,2,FALSE),"")
A22: 34094619 | B22: Genomic surveillance of Neisseria gonorrhoeae in the Philippines, 2013-2014 | C22: Jamoralin MC Jr, Argimón S, Lagrada ML, Villamin AS, Masim ML, Gayeta JM, Boehme KD, Olorosa AM, Sia SB, Hufano CM, Cohen V, Hernandez LT, Jeffrey B, Abudahab K, Stelling J, Holden MTG, Aanensenb DM; e,*; Carlosa CC; Philippines Antimicrobial Resistance Surveillance Program. | D22: Western Pac Surveill Response J. 2021 Feb 26;12(1):17-25. doi: 10.5365/wpsar.2020.11.1.005. eCollection 2021 Jan-Mar. | E22: Jamoralin MC Jr | F22: Western Pac Surveill Response J | G22: 2021 | H22: 44354 | I22: PMC8143934 | K22: 10.5365/wpsar.2020.11.1.005 | L22: =IF(ISNUMBER(VLOOKUP(A22,EXCL,1,FALSE)),"Excluido",IF(ISNUMBER(VLOOKUP(A22,POST,1,FALSE)),"PostAlerta",IF(ISNUMBER(VLOOKUP(A22,PRE,1,FALSE)),"PreAlerta",""))) -> PostAlerta | M22: =IF(ISNUMBER(A22),(IF(ISNUMBER(VLOOKUP(A22,KEYWORDS,1,FALSE)),"C/PalabrasClaves","S/PalabrasClaves")),"") -> S/PalabrasClaves | N22: =IF(ISNUMBER(SEARCH("TREATMENT", B22)), "4) Nuevos tratamientos", "") | P22: 2021 Feb 26 | R22: =LEFT('2012-2022'!$P22,4) -> 2021 | S22: Feb | T22: =IFERROR(VLOOKUP(A22,BD_aux,2,FALSE),"")
A23: 31119637 | B23: Female Mouse Model of Neisseria gonorrhoeae Infection | C23: Raterman EL, Jerse AE. | D23: Methods Mol Biol. 2019;1997:413-429. doi: 10.1007/978-1-4939-9496-0_24. | E23: Raterman EL | F23: Methods Mol Biol | G23: 2019 | H23: 43609 | K23: 10.1007/978-1-4939-9496-0_24 | L23: =IF(ISNUMBER(VLOOKUP(A23,EXCL,1,FALSE)),"Excluido",IF(ISNUMBER(VLOOKUP(A23,POST,1,FALSE)),"PostAlerta",IF(ISNUMBER(VLOOKUP(A23,PRE,1,FALSE)),"PreAlerta",""))) -> PostAlerta | M23: =IF(ISNUMBER(A23),(IF(ISNUMBER(VLOOKUP(A23,KEYWORDS,1,FALSE)),"C/PalabrasClaves","S/PalabrasClaves")),"") -> C/PalabrasClaves | N23: =IF(ISNUMBER(SEARCH("TREATMENT", B23)), "4) Nuevos tratamientos", "") | P23: 2019 | R23: =LEFT('2012-2022'!$P23,4) -> 2019 | T23: =IFERROR(VLOOKUP(A23,BD_aux,2,FALSE),"")
A24: 34060328 | B24: Challenges and Controversies Concerning Neisseria gonorrhoeae-Neutrophil Interactions in Pathogenesis | C24: Criss AK, Genco CA, Gray-Owen SD, Jerse AE, Seifert HS. | D24: mBio. 2021 Jun 29;12(3):e0072121. doi: 10.1128/mBio.00721-21. Epub 2021 Jun 1. | E24: Criss AK | F24: mBio | G24: 2021 | H24: 44348 | I24: PMC8262874 | K24: 10.1128/mBio.00721-21 | L24: =IF(ISNUMBER(VLOOKUP(A24,EXCL,1,FALSE)),"Excluido",IF(ISNUMBER(VLOOKUP(A24,POST,1,FALSE)),"PostAlerta",IF(ISNUMBER(VLOOKUP(A24,PRE,1,FALSE)),"PreAlerta",""))) -> PostAlerta | M24: =IF(ISNUMBER(A24),(IF(ISNUMBER(VLOOKUP(A24,KEYWORDS,1,FALSE)),"C/PalabrasClaves","S/PalabrasClaves")),"") -> S/PalabrasClaves | N24: =IF(ISNUMBER(SEARCH("TREATMENT", B24)), "4) Nuevos tratamientos", "") | P24: 2021 Jun 29 | R24: =LEFT('2012-2022'!$P24,4) -> 2021 | S24: Jun | T24: =IFERROR(VLOOKUP(A24,BD_aux,2,FALSE),"")
A25: 34871932 | B25: Antimicrobial susceptibility testing of Neisseria gonorrhoeae using a phenotypic-molecular assay and lyophilized antimicrobials | C25: Melendez JH, Chen FE, Wang TH. | D25: Diagn Microbiol Infect Dis. 2022 Feb;102(2):115590. doi: 10.1016/j.diagmicrobio.2021.115590. Epub 2021 Oct 29. | E25: Melendez JH | F25: Diagn Microbiol Infect Dis | G25: 2022 | H25: 44536 | I25: PMC9241851 | J25: NIHMS1806938 | K25: 10.1016/j.diagmicrobio.2021.115590 | L25: =IF(ISNUMBER(VLOOKUP(A25,EXCL,1,FALSE)),"Excluido",IF(ISNUMBER(VLOOKUP(A25,POST,1,FALSE)),"PostAlerta",IF(ISNUMBER(VLOOKUP(A25,PRE,1,FALSE)),"PreAlerta",""))) -> PostAlerta | M25: =IF(ISNUMBER(A25),(IF(ISNUMBER(VLOOKUP(A25,KEYWORDS,1,FALSE)),"C/PalabrasClaves","S/PalabrasClaves")),"") -> C/PalabrasClaves | N25: 2) Nuevos tratamientos | O25: 2g) nueva combinación de ATB | P25: 2022 Feb | R25: =LEFT('2012-2022'!$P25,4) -> 2022 | S25: Feb | T25: Gonorrhea is an urgent global public health threat as Neisseria gonorrhoeae (Ng) has progressively developed resistance to all antibiotics commonly used for treatment. Surveillance of antimicrobial susceptibility trends is critical to monitor the emergence and spread of antimicrobial resistance. The gold standard methods for antimicrobial susceptibility testing (AST) of Ng are laborious and time-consuming. We evaluated a phenotypic molecular approach, involving a short cultivation step and quantitative PCR, with lyophilized antimicrobials to characterize antimicrobial susceptibility in Ng. There was excellent concordance between AST performed with liquid and lyophilized ciprofloxacin, penicillin, and tetracycline using the pheno-molecular assay, following a 4-hour incubation step. The categorical agreement between the pheno-molecular assay and the gold standard AST results was 92.4% for characterization of antimicrobial susceptibility. Essential agreement between the 2 methods was 91.9%. Characterization of ceftriaxone susceptibility in Ng using the pheno-molecular assay required a 6-hour incubation step. | U25: No | V25: No | W25: No | X25: This study assessed a rapid phenotypic molecular assay to test antimicrobial susceptibility in Neisseria gonorrhoeae, combining short incubation and qPCR with lyophilized antibiotics. | Y25: =IFERROR(VLOOKUP(A23,BD_aux,3,FALSE),"")
A26: 33536323 | B26: Comprehensive Bioinformatic Assessments of the Variability of Neisseria gonorrhoeae Vaccine Candidates | C26: Baarda BI, Zielke RA, Holm AK, Sikora AE. | D26: mSphere. 2021 Feb 3;6(1):e00977-20. doi: 10.1128/mSphere.00977-20. | E26: Baarda BI | F26: mSphere | G26: 2021 | H26: 44231 | I26: PMC7860988 | K26: 10.1128/mSphere.00977-20 | L26: =IF(ISNUMBER(VLOOKUP(A26,EXCL,1,FALSE)),"Excluido",IF(ISNUMBER(VLOOKUP(A26,POST,1,FALSE)),"PostAlerta",IF(ISNUMBER(VLOOKUP(A26,PRE,1,FALSE)),"PreAlerta",""))) -> PostAlerta | M26: =IF(ISNUMBER(A26),(IF(ISNUMBER(VLOOKUP(A26,KEYWORDS,1,FALSE)),"C/PalabrasClaves","S/PalabrasClaves")),"") -> C/PalabrasClaves | N26: =IF(ISNUMBER(SEARCH("TREATMENT", B26)), "4) Nuevos tratamientos", "") | P26: 2021 Feb 3 | R26: =LEFT('2012-2022'!$P26,4) -> 2021 | S26: Feb | T26: =IFERROR(VLOOKUP(A26,BD_aux,2,FALSE),"")
A27: 28407640 | B27: Wild-Type Gyrase A Genotype of Neisseria gonorrhoeae Predicts In Vitro Susceptibility to Ciprofloxacin: A Systematic Review of the Literature and Meta-Analysis | C27: Allan-Blitz LT, Wang X, Klausner JD. | D27: Sex Transm Dis. 2017 May;44(5):261-265. doi: 10.1097/OLQ.0000000000000591. | E27: Allan-Blitz LT | F27: Sex Transm Dis | G27: 2017 | H27: 42839 | I27: PMC5407314 | J27: NIHMS841754 | K27: 10.1097/OLQ.0000000000000591 | L27: =IF(ISNUMBER(VLOOKUP(A27,EXCL,1,FALSE)),"Excluido",IF(ISNUMBER(VLOOKUP(A27,POST,1,FALSE)),"PostAlerta",IF(ISNUMBER(VLOOKUP(A27,PRE,1,FALSE)),"PreAlerta",""))) -> Excluido | M27: =IF(ISNUMBER(A27),(IF(ISNUMBER(VLOOKUP(A27,KEYWORDS,1,FALSE)),"C/PalabrasClaves","S/PalabrasClaves")),"") -> C/PalabrasClaves | N27: =IF(ISNUMBER(SEARCH("TREATMENT", B27)), "4) Nuevos tratamientos", "") | P27: 2017 May | R27: =LEFT('2012-2022'!$P27,4) -> 2017 | S27: May | T27: =IFERROR(VLOOKUP(A27,BD_aux,2,FALSE),"")
A28: 27337478 | B28: Antimicrobial Resistance Expressed by Neisseria gonorrhoeae: A Major Global Public Health Problem in the 21st Century | C28: Unemo M, Del Rio C, Shafer WM. | D28: Microbiol Spectr. 2016 Jun;4(3):10.1128/microbiolspec.EI10-0009-2015. doi: 10.1128/microbiolspec.EI10-0009-2015. | E28: Unemo M | F28: Microbiol Spectr | G28: 2016 | H28: 42545 | I28: PMC4920088 | J28: NIHMS752938 | K28: 10.1128/microbiolspec.EI10-0009-2015 | L28: =IF(ISNUMBER(VLOOKUP(A28,EXCL,1,FALSE)),"Excluido",IF(ISNUMBER(VLOOKUP(A28,POST,1,FALSE)),"PostAlerta",IF(ISNUMBER(VLOOKUP(A28,PRE,1,FALSE)),"PreAlerta",""))) -> Excluido | M28: =IF(ISNUMBER(A28),(IF(ISNUMBER(VLOOKUP(A28,KEYWORDS,1,FALSE)),"C/PalabrasClaves","S/PalabrasClaves")),"") -> C/PalabrasClaves | N28: =IF(ISNUMBER(SEARCH("TREATMENT", B28)), "4) Nuevos tratamientos", "") | P28: 2016 Jun | R28: =LEFT('2012-2022'!$P28,4) -> 2016 | S28: Jun | T28: =IFERROR(VLOOKUP(A28,BD_aux,2,FALSE),"")
A29: 32149957 | B29: Reconsidering Presumptive Neisseria gonorrhoeae Treatment For Women With Cervicitis | C29: Nsuami MJ, Lillis RA, Martin DH. | D29: Sex Transm Dis. 2020 Jun;47(6):383-386. doi: 10.1097/OLQ.0000000000001156. | E29: Nsuami MJ | F29: Sex Transm Dis | G29: 2020 | H29: 43900 | K29: 10.1097/OLQ.0000000000001156 | L29: =IF(ISNUMBER(VLOOKUP(A29,EXCL,1,FALSE)),"Excluido",IF(ISNUMBER(VLOOKUP(A29,POST,1,FALSE)),"PostAlerta",IF(ISNUMBER(VLOOKUP(A29,PRE,1,FALSE)),"PreAlerta",""))) -> PostAlerta | M29: =IF(ISNUMBER(A29),(IF(ISNUMBER(VLOOKUP(A29,KEYWORDS,1,FALSE)),"C/PalabrasClaves","S/PalabrasClaves")),"") -> S/PalabrasClaves | N29: 2) Nuevos tratamientos | O29: change treatment | P29: 2020 Jun | R29: =LEFT('2012-2022'!$P29,4) -> 2020 | S29: Jun | T29: - | U29: No | V29: No | W29: No | X29: Not available | Y29: =IFERROR(VLOOKUP(A27,BD_aux,3,FALSE),"")
A30: 31119619 | B30: Preparation of Lipooligosaccharide (LOS) from Neisseria gonorrhoeae | C30: Christodoulides M. | D30: Methods Mol Biol. 2019;1997:87-96. doi: 10.1007/978-1-4939-9496-0_6. | E30: Christodoulides M | F30: Methods Mol Biol | G30: 2019 | H30: 43609 | K30: 10.1007/978-1-4939-9496-0_6 | L30: =IF(ISNUMBER(VLOOKUP(A30,EXCL,1,FALSE)),"Excluido",IF(ISNUMBER(VLOOKUP(A30,POST,1,FALSE)),"PostAlerta",IF(ISNUMBER(VLOOKUP(A30,PRE,1,FALSE)),"PreAlerta",""))) -> PostAlerta | M30: =IF(ISNUMBER(A30),(IF(ISNUMBER(VLOOKUP(A30,KEYWORDS,1,FALSE)),"C/PalabrasClaves","S/PalabrasClaves")),"") -> S/PalabrasClaves | N30: =IF(ISNUMBER(SEARCH("TREATMENT", B30)), "4) Nuevos tratamientos", "") | P30: 2019 | R30: =LEFT('2012-2022'!$P30,4) -> 2019 | T30: =IFERROR(VLOOKUP(A30,BD_aux,2,FALSE),"")
A31: 32091356 | B31: Genomic and Phenotypic Variability in Neisseria gonorrhoeae Antimicrobial Susceptibility, England | C31: Town K, Harris S, Sánchez-Busó L, Cole MJ, Pitt R, Fifer H, Mohammed H, Field N, Hughes G. | D31: Emerg Infect Dis. 2020 Mar;26(3):505-515. doi: 10.3201/eid2603.190732. | E31: Town K | F31: Emerg Infect Dis | G31: 2020 | H31: 43886 | I31: PMC7045833 | K31: 10.3201/eid2603.190732 | L31: =IF(ISNUMBER(VLOOKUP(A31,EXCL,1,FALSE)),"Excluido",IF(ISNUMBER(VLOOKUP(A31,POST,1,FALSE)),"PostAlerta",IF(ISNUMBER(VLOOKUP(A31,PRE,1,FALSE)),"PreAlerta",""))) -> PostAlerta | M31: =IF(ISNUMBER(A31),(IF(ISNUMBER(VLOOKUP(A31,KEYWORDS,1,FALSE)),"C/PalabrasClaves","S/PalabrasClaves")),"") -> C/PalabrasClaves | N31: =IF(ISNUMBER(SEARCH("TREATMENT", B31)), "4) Nuevos tratamientos", "") | P31: 2020 Mar | R31: =LEFT('2012-2022'!$P31,4) -> 2020 | S31: Mar | T31: =IFERROR(VLOOKUP(A31,BD_aux,2,FALSE),"")
A32: 32530860 | B32: Cephalosporin-Resistant Neisseria gonorrhoeae Isolated in Portugal, 2019 | C32: Pinto M, Matias R, Rodrigues JC, Duarte S, Vieira L, Gonçalves I, Gonçalves MJ, Ramos MH, Gomes JP, Borrego MJ. | D32: Sex Transm Dis. 2020 Nov;47(11):e54-e56. doi: 10.1097/OLQ.0000000000001218. | E32: Pinto M | F32: Sex Transm Dis | G32: 2020 | H32: 43995 | K32: 10.1097/OLQ.0000000000001218 | L32: =IF(ISNUMBER(VLOOKUP(A32,EXCL,1,FALSE)),"Excluido",IF(ISNUMBER(VLOOKUP(A32,POST,1,FALSE)),"PostAlerta",IF(ISNUMBER(VLOOKUP(A32,PRE,1,FALSE)),"PreAlerta",""))) -> PostAlerta | M32: =IF(ISNUMBER(A32),(IF(ISNUMBER(VLOOKUP(A32,KEYWORDS,1,FALSE)),"C/PalabrasClaves","S/PalabrasClaves")),"") -> C/PalabrasClaves | N32: 1) Reporte de cepas resistentes | P32: 2020 Nov | R32: =LEFT('2012-2022'!$P32,4) -> 2020 | S32: Nov | T32: We report a multidrug-resistant Neisseria gonorrhoeae exhibiting resistance to ceftriaxone and cefixime, isolated in Portugal in 2019. Whole-genome sequencing was performed for typing and identification of genetic determinants of antimicrobial resistance. Because of its antimicrobial susceptibility profile, awareness should be raised for the circulation of this strain. | U32: Yes | V32: No | W32: No | X32: This study reports a multidrug-resistant Neisseria gonorrhoeae strain isolated in Portugal in 2019, resistant to ceftriaxone and cefixime. | Y32: =IFERROR(VLOOKUP(A30,BD_aux,3,FALSE),"")
A33: 29131780 | B33: Ceftriaxone-Resistant Neisseria gonorrhoeae, Canada, 2017 | C33: Lefebvre B, Martin I, Demczuk W, Deshaies L, Michaud S, Labbé AC, Beaudoin MC, Longtin J. | D33: Emerg Infect Dis. 2018 Feb;24(2):381-3. doi: 10.3201/eid2402.171756. Epub 2018 Feb 17. | E33: Lefebvre B | F33: Emerg Infect Dis | G33: 2018 | H33: 43053 | I33: PMC5782888 | K33: 10.3201/eid2402.171756 | L33: =IF(ISNUMBER(VLOOKUP(A33,EXCL,1,FALSE)),"Excluido",IF(ISNUMBER(VLOOKUP(A33,POST,1,FALSE)),"PostAlerta",IF(ISNUMBER(VLOOKUP(A33,PRE,1,FALSE)),"PreAlerta",""))) -> PostAlerta | M33: =IF(ISNUMBER(A33),(IF(ISNUMBER(VLOOKUP(A33,KEYWORDS,1,FALSE)),"C/PalabrasClaves","S/PalabrasClaves")),"") -> C/PalabrasClaves | N33: =IF(ISNUMBER(SEARCH("TREATMENT", B33)), "4) Nuevos tratamientos", "") | P33: 2018 Feb | R33: =LEFT('2012-2022'!$P33,4) -> 2018 | S33: Feb | T33: =IFERROR(VLOOKUP(A33,BD_aux,2,FALSE),"")
A34: 33807121 | B34: Neisseria gonorrhoeae Multivalent Maxibody with a Broad Spectrum of Strain Specificity and Sensitivity for Gonorrhea Diagnosis | C34: Jeong J, Kim JS, Lee J, Seo YR, Yi EC, Kim KM. | D34: Biomolecules. 2021 Mar 23;11(3):484. doi: 10.3390/biom11030484. | E34: Jeong J | F34: Biomolecules | G34: 2021 | H34: 44289 | I34: PMC8004885 | K34: 10.3390/biom11030484 | L34: =IF(ISNUMBER(VLOOKUP(A34,EXCL,1,FALSE)),"Excluido",IF(ISNUMBER(VLOOKUP(A34,POST,1,FALSE)),"PostAlerta",IF(ISNUMBER(VLOOKUP(A34,PRE,1,FALSE)),"PreAlerta",""))) -> PostAlerta | M34: =IF(ISNUMBER(A34),(IF(ISNUMBER(VLOOKUP(A34,KEYWORDS,1,FALSE)),"C/PalabrasClaves","S/PalabrasClaves")),"") -> C/PalabrasClaves | N34: =IF(ISNUMBER(SEARCH("TREATMENT", B34)), "4) Nuevos tratamientos", "") | P34: 2021 Mar 23 | R34: =LEFT('2012-2022'!$P34,4) -> 2021 | S34: Mar | T34: =IFERROR(VLOOKUP(A34,BD_aux,2,FALSE),"")
A35: 30629196 | B35: Photoinactivation of Neisseria gonorrhoeae: A Paradigm-Changing Approach for Combating Antibiotic-Resistant Gonococcal Infection | C35: Wang Y, Ferrer-Espada R, Baglo Y, Goh XS, Held KD, Grad YH, Gu Y, Gelfand JA, Dai T. | D35: J Infect Dis. 2019 Jul 31;220(5):873-881. doi: 10.1093/infdis/jiz018. | E35: Wang Y | F35: J Infect Dis | G35: 2019 | H35: 43476 | I35: PMC6667797 | K35: 10.1093/infdis/jiz018 | L35: =IF(ISNUMBER(VLOOKUP(A35,EXCL,1,FALSE)),"Excluido",IF(ISNUMBER(VLOOKUP(A35,POST,1,FALSE)),"PostAlerta",IF(ISNUMBER(VLOOKUP(A35,PRE,1,FALSE)),"PreAlerta",""))) -> PostAlerta | M35: =IF(ISNUMBER(A35),(IF(ISNUMBER(VLOOKUP(A35,KEYWORDS,1,FALSE)),"C/PalabrasClaves","S/PalabrasClaves")),"") -> C/PalabrasClaves | N35: 2) Nuevos tratamientos | O35: No farmacológico (UV) | P35: 2019 Jul 31 | R35: =LEFT('2012-2022'!$P35,4) -> 2019 | S35: Jul | T35: Antimicrobial resistance in Neisseria gonorrhoeae is a major issue of public health, and there is a critical need for the development of new antigonococcal strategies. In this study, we investigated the effectiveness of antimicrobial blue light (aBL; wavelength, 405 nm), an innovative nonpharmacological approach, for the inactivation of N. gonorrhoeae. Our findings indicated that aBL preferentially inactivated N. gonorrhoeae, including antibiotic-resistant strains, over human vaginal epithelial cells in vitro. Furthermore, no aBL-induced genotoxicity to the vaginal epithelial cells was observed at the radiant exposure used to inactivate N. gonorrhoeae. aBL also effectively inactivated N. gonorrhoeae that had attached to and invaded into the vaginal epithelial cells in their cocultures. No gonococcal resistance to aBL developed after 15 successive cycles of inactivation induced by subtherapeutic exposure to aBL. Endogenous aBL-activatable photosensitizing porphyrins in N. gonorrhoeae were identified and quantified using ultraperformance liquid chromatography, with coproporphyrin being the most abundant species in all N. gonorrhoeae strains studied. Singlet oxygen was involved in aBL inactivation of N. gonorrhoeae. Together, these findings show that aBL represents a potential potent treatment for antibiotic-resistant gonococcal infection. | U35: No | V35: Yes | W35: No | X35: This study explored the efficacy of antimicrobial blue light (aBL, 405 nm) as a non-antibiotic treatment for Neisseria gonorrhoeae, including drug-resistant strains. aBL is a promising, resistance-proof therapeutic for gonorrhea, especially against antibiotic-resistant strains. | Y35: =IFERROR(VLOOKUP(A33,BD_aux,3,FALSE),"")
A36: 27551020 | B36: Neisseria gonorrhoeae Crippled Its Peptidoglycan Fragment Permease To Facilitate Toxic Peptidoglycan Monomer Release | C36: Chan JM, Dillard JP. | D36: J Bacteriol. 2016 Oct 7;198(21):3029-3040. doi: 10.1128/JB.00437-16. Print 2016 Nov 1. | E36: Chan JM | F36: J Bacteriol | G36: 2016 | H36: 42606 | I36: PMC5055606 | K36: 10.1128/JB.00437-16 | L36: =IF(ISNUMBER(VLOOKUP(A36,EXCL,1,FALSE)),"Excluido",IF(ISNUMBER(VLOOKUP(A36,POST,1,FALSE)),"PostAlerta",IF(ISNUMBER(VLOOKUP(A36,PRE,1,FALSE)),"PreAlerta",""))) -> PreAlerta | M36: =IF(ISNUMBER(A36),(IF(ISNUMBER(VLOOKUP(A36,KEYWORDS,1,FALSE)),"C/PalabrasClaves","S/PalabrasClaves")),"") -> S/PalabrasClaves | N36: =IF(ISNUMBER(SEARCH("TREATMENT", B36)), "4) Nuevos tratamientos", "") | P36: 2016 Oct 7 | R36: =LEFT('2012-2022'!$P36,4) -> 2016 | S36: Oct | T36: =IFERROR(VLOOKUP(A36,BD_aux,2,FALSE),"")
A37: 26063097 | B37: Review of 2005 Public Health Laboratory Network Neisseria gonorrhoeae nucleic acid amplification tests guidelines | C37: Whiley DM, Lahra MM; National Neisseria Network. | D37: Commun Dis Intell Q Rep. 2015 Mar 31;39(1):E42-5. | E37: Whiley DM | F37: Commun Dis Intell Q Rep | G37: 2015 | H37: 42167 | L37: =IF(ISNUMBER(VLOOKUP(A37,EXCL,1,FALSE)),"Excluido",IF(ISNUMBER(VLOOKUP(A37,POST,1,FALSE)),"PostAlerta",IF(ISNUMBER(VLOOKUP(A37,PRE,1,FALSE)),"PreAlerta",""))) -> Excluido | M37: =IF(ISNUMBER(A37),(IF(ISNUMBER(VLOOKUP(A37,KEYWORDS,1,FALSE)),"C/PalabrasClaves","S/PalabrasClaves")),"") -> S/PalabrasClaves | N37: =IF(ISNUMBER(SEARCH("TREATMENT", B37)), "4) Nuevos tratamientos", "") | P37: 2015 Mar 31 | R37: =LEFT('2012-2022'!$P37,4) -> 2015 | S37: Mar | T37: =IFERROR(VLOOKUP(A37,BD_aux,2,FALSE),"")
A38: 24074904 | B38: [Multiresistant Neisseria gonorrhoeae: back to the past?] | C38: Otero Guerra L, Vazquez F. | D38: Enferm Infecc Microbiol Clin. 2013 Nov;31(9):565-7. doi: 10.1016/j.eimc.2013.07.002. Epub 2013 Sep 26. | E38: Otero Guerra L | F38: Enferm Infecc Microbiol Clin | G38: 2013 | H38: 41548 | K38: 10.1016/j.eimc.2013.07.002 | L38: =IF(ISNUMBER(VLOOKUP(A38,EXCL,1,FALSE)),"Excluido",IF(ISNUMBER(VLOOKUP(A38,POST,1,FALSE)),"PostAlerta",IF(ISNUMBER(VLOOKUP(A38,PRE,1,FALSE)),"PreAlerta",""))) -> PreAlerta | M38: =IF(ISNUMBER(A38),(IF(ISNUMBER(VLOOKUP(A38,KEYWORDS,1,FALSE)),"C/PalabrasClaves","S/PalabrasClaves")),"") -> C/PalabrasClaves | N38: 1) Reporte de cepas resistentes | P38: 2013 Nov | Q38: Excluir | R38: =LEFT('2012-2022'!$P38,4) -> 2013 | S38: Nov | T38: - | U38: No | V38: No | W38: No | X38: Editorial | Y38: =IFERROR(VLOOKUP(A36,BD_aux,3,FALSE),"")
A39: 31289109 | B39: Disentangling the tangled web of Neisseria gonorrhoeae transmission: how important are oropharyngeal infections? | C39: Lewis DA. | D39: Sex Transm Infect. 2019 Sep;95(6):395-396. doi: 10.1136/sextrans-2019-054030. Epub 2019 Jul 9. | E39: Lewis DA | F39: Sex Transm Infect | G39: 2019 | H39: 43657 | K39: 10.1136/sextrans-2019-054030 | L39: =IF(ISNUMBER(VLOOKUP(A39,EXCL,1,FALSE)),"Excluido",IF(ISNUMBER(VLOOKUP(A39,POST,1,FALSE)),"PostAlerta",IF(ISNUMBER(VLOOKUP(A39,PRE,1,FALSE)),"PreAlerta",""))) -> PostAlerta | M39: =IF(ISNUMBER(A39),(IF(ISNUMBER(VLOOKUP(A39,KEYWORDS,1,FALSE)),"C/PalabrasClaves","S/PalabrasClaves")),"") -> S/PalabrasClaves | N39: =IF(ISNUMBER(SEARCH("TREATMENT", B39)), "4) Nuevos tratamientos", "") | P39: 2019 Sep | R39: =LEFT('2012-2022'!$P39,4) -> 2019 | S39: Sep | T39: =IFERROR(VLOOKUP(A39,BD_aux,2,FALSE),"")
A40: 26426083 | B40: Neisseria gonorrhoeae survives within and modulates apoptosis and inflammatory cytokine production of human macrophages | C40: Château A, Seifert HS. | D40: Cell Microbiol. 2016 Apr;18(4):546-60. doi: 10.1111/cmi.12529. Epub 2015 Oct 26. | E40: Château A | F40: Cell Microbiol | G40: 2016 | H40: 42279 | I40: PMC5240846 | J40: NIHMS841362 | K40: 10.1111/cmi.12529 | L40: =IF(ISNUMBER(VLOOKUP(A40,EXCL,1,FALSE)),"Excluido",IF(ISNUMBER(VLOOKUP(A40,POST,1,FALSE)),"PostAlerta",IF(ISNUMBER(VLOOKUP(A40,PRE,1,FALSE)),"PreAlerta",""))) -> PreAlerta | M40: =IF(ISNUMBER(A40),(IF(ISNUMBER(VLOOKUP(A40,KEYWORDS,1,FALSE)),"C/PalabrasClaves","S/PalabrasClaves")),"") -> S/PalabrasClaves | N40: =IF(ISNUMBER(SEARCH("TREATMENT", B40)), "4) Nuevos tratamientos", "") | P40: 2016 Apr | R40: =LEFT('2012-2022'!$P40,4) -> 2016 | S40: Apr | T40: =IFERROR(VLOOKUP(A40,BD_aux,2,FALSE),"")
...

Sheet Test
A1: PMID | B1: Title | C1: Categoria | D1: subcategoria | E1: Estado | F1: Abstract | G1: 1) Antimicrobial Resistance stain | H1: 2) New treatment | I1: 3) Immunization | J1: Human_summary
A2: 31119616 | B2: Antimicrobial Resistance in Neisseria gonorrhoeae and Treatment of Gonorrhea | C2: 2) Nuevos tratamientos | D2: 2g) nueva combinación de ATB | F2: This review highlights the global threat of antimicrobial-resistant Neisseria gonorrhoeae. | G2: Yes | H2: No | I2: No | J2: This review highlights the global threat of antimicrobial-resistant Neisseria gonorrhoeae.
A3: 30900979 | B3: Identification of Internationally Disseminated Ceftriaxone-Resistant Neisseria gonorrhoeae Strain FC428, China | C3: 1) Reporte de cepas resistentes | F3: In 2016, we identified a ceftriaxone-resistant Neisseria gonorrhoeae isolate in China. The strain genotype was identical to the resistant clone FC428 that originated in Japan. Enhanced international collaborative surveillance programs are crucial to track the transmission of the ceftriaxone-resistant clones. | G3: Yes | H3: No | I3: No | J3: Detect a ceftriaxone-resistant Neisseria gonorrhoeae strain in China.
A4: 31661379 | B4: Identification of multidrug-resistant Neisseria gonorrhoeae isolates with combined resistance to both ceftriaxone and azithromycin, China, 2017-2018 | C4: 1) Reporte de cepas resistentes | F4: The growing multidrug-resistant Neisseria gonorrhoeae is a serious global threat to gonococcal therapy. During 2017-2018, we identified a rare multidrug-resistant (ceftriaxone and azithromycin) strain (GC250) and four strains (GC185, GC195, GC196 and GC249) with both resistance to ceftriaxone and decreased susceptibility to azithromycin. All strains belonged to NG-STAR ST1143, including the mosaic penA-60.001, which is closely related to ceftriaxone resistance. The characterization of antimicrobial resistance (AMR) determinants and phylogenetic analysis showed these five strains were closely related to internationally spreading ceftriaxone-resistant N. gonorrhoeae FC428, but with higher azithromycin MIC. Findings here demonstrated that this clone not only initiated clonal expansion in China, but acquired azithromycin resistance. | G4: Yes | H4: No | I4: No | J4: This study identified five multidrug-resistant Neisseria gonorrhoeae strains in China
A5: 34402689 | B5: Large Increase in Azithromycin-Resistant Neisseria gonorrhoeae in Northern Spain | C5: 1) Reporte de cepas resistentes | F5: The aim of this study was to characterize the evolution of gonorrhea in the general population by correlating epidemiological, genotypic, and antimicrobial resistance data of Neisseria gonorrhoeae isolates collected in northern Spain from 2014 to 2018. One hundred ninety-four strains underwent antimicrobial susceptibility testing and were genetically analyzed by N. gonorrhoeae multiantigen sequence typing. Increasing cases of gonococcal infections have been observed after 2015. Most occurred in male with urethritis. Sequence type (ST)-9972 and ST-1576, the predominant genotypes identified, have not been previously described as epidemic clones. Of great concern was the significant increase in azithromycin-resistant N. gonorrhoeae. More than 30% of these isolates were obtained from men who have sex with men (MSM). ST-12302 was the most prevalent clone among the azithromycin-resistant strains, and was also resistant to penicillin, ciprofloxacin, and tetracycline. This multidrug-resistant clone was exclusively isolated from MSM during 2018. The incidence rates of gonorrhea and azithromycin-resistant N. gonorrhoeae have significantly increased due to the emergence of new clones. ST-12302 has recently been recognized as an epidemic clone; therefore, its surveillance could be the key in controlling further dissemination of azithromycin resistance. These data highlight the need to perform local studies to update treatment guidelines and reinforce preventive measures against gonorrhea. | G5: Yes | H5: No | I5: No | J5: This study characterized the epidemiological and antimicrobial resistance trends of Neisseria gonorrhoeae in northern Spain The spread of ST-12302 and rising resistance rates stress the importance of local surveillance, updated treatment guidelines, and targeted prevention strategies.
A6: 29553336 | B6: Cephalosporin-Resistant Neisseria gonorrhoeae Clone, China | C6: 1) Reporte de cepas resistentes | F6: Cephalosporin-resistant Neisseria gonorrhoeae is a major public health concern. N. gonorrhoeae of multiantigen sequence type G1407 and multilocus sequence type 1901 is an internationally spreading cephalosporin-resistant clone. We detected 4 cases of infection with this clone in China and analyzed resistance determinants by using N. gonorrhoeae sequence typing for antimicrobial resistance. | G6: Yes | H6: No | I6: No | J6: This report describes 4 cases in China of Neisseria gonorrhoeae infection caused by the cephalosporin-resistant international clone G1407 (MLST ST1901).
A7: 34871932 | B7: Antimicrobial susceptibility testing of Neisseria gonorrhoeae using a phenotypic-molecular assay and lyophilized antimicrobials | C7: 2) Nuevos tratamientos | D7: 2g) nueva combinación de ATB | F7: Gonorrhea is an urgent global public health threat as Neisseria gonorrhoeae (Ng) has progressively developed resistance to all antibiotics commonly used for treatment. Surveillance of antimicrobial susceptibility trends is critical to monitor the emergence and spread of antimicrobial resistance. The gold standard methods for antimicrobial susceptibility testing (AST) of Ng are laborious and time-consuming. We evaluated a phenotypic molecular approach, involving a short cultivation step and quantitative PCR, with lyophilized antimicrobials to characterize antimicrobial susceptibility in Ng. There was excellent concordance between AST performed with liquid and lyophilized ciprofloxacin, penicillin, and tetracycline using the pheno-molecular assay, following a 4-hour incubation step. The categorical agreement between the pheno-molecular assay and the gold standard AST results was 92.4% for characterization of antimicrobial susceptibility. Essential agreement between the 2 methods was 91.9%. Characterization of ceftriaxone susceptibility in Ng using the pheno-molecular assay required a 6-hour incubation step. | G7: No | H7: No | I7: No | J7: This study assessed a rapid phenotypic molecular assay to test antimicrobial susceptibility in Neisseria gonorrhoeae, combining short incubation and qPCR with lyophilized antibiotics.
A8: 32149957 | B8: Reconsidering Presumptive Neisseria gonorrhoeae Treatment For Women With Cervicitis | C8: 2) Nuevos tratamientos | D8: change treatment | F8: - | G8: No | H8: No | I8: No | J8: Not available
A9: 32530860 | B9: Cephalosporin-Resistant Neisseria gonorrhoeae Isolated in Portugal, 2019 | C9: 1) Reporte de cepas resistentes | F9: We report a multidrug-resistant Neisseria gonorrhoeae exhibiting resistance to ceftriaxone and cefixime, isolated in Portugal in 2019. Whole-genome sequencing was performed for typing and identification of genetic determinants of antimicrobial resistance. Because of its antimicrobial susceptibility profile, awareness should be raised for the circulation of this strain. | G9: Yes | H9: No | I9: No | J9: This study reports a multidrug-resistant Neisseria gonorrhoeae strain isolated in Portugal in 2019, resistant to ceftriaxone and cefixime.
A10: 30629196 | B10: Photoinactivation of Neisseria gonorrhoeae: A Paradigm-Changing Approach for Combating Antibiotic-Resistant Gonococcal Infection | C10: 2) Nuevos tratamientos | D10: No farmacológico (UV) | F10: Antimicrobial resistance in Neisseria gonorrhoeae is a major issue of public health, and there is a critical need for the development of new antigonococcal strategies. In this study, we investigated the effectiveness of antimicrobial blue light (aBL; wavelength, 405 nm), an innovative nonpharmacological approach, for the inactivation of N. gonorrhoeae. Our findings indicated that aBL preferentially inactivated N. gonorrhoeae, including antibiotic-resistant strains, over human vaginal epithelial cells in vitro. Furthermore, no aBL-induced genotoxicity to the vaginal epithelial cells was observed at the radiant exposure used to inactivate N. gonorrhoeae. aBL also effectively inactivated N. gonorrhoeae that had attached to and invaded into the vaginal epithelial cells in their cocultures. No gonococcal resistance to aBL developed after 15 successive cycles of inactivation induced by subtherapeutic exposure to aBL. Endogenous aBL-activatable photosensitizing porphyrins in N. gonorrhoeae were identified and quantified using ultraperformance liquid chromatography, with coproporphyrin being the most abundant species in all N. gonorrhoeae strains studied. Singlet oxygen was involved in aBL inactivation of N. gonorrhoeae. Together, these findings show that aBL represents a potential potent treatment for antibiotic-resistant gonococcal infection. | G10: No | H10: Yes | I10: No | J10: This study explored the efficacy of antimicrobial blue light (aBL, 405 nm) as a non-antibiotic treatment for Neisseria gonorrhoeae, including drug-resistant strains. aBL is a promising, resistance-proof therapeutic for gonorrhea, especially against antibiotic-resistant strains.
A11: 24074904 | B11: [Multiresistant Neisseria gonorrhoeae: back to the past?] | C11: 1) Reporte de cepas resistentes | E11: Excluir | F11: - | G11: No | H11: No | I11: No | J11: Editorial
A12: 29883770 | B12: Tetracycline resistance of Neisseria gonorrhoeae in Russia, 2015-2017 | C12: 1) Reporte de cepas resistentes | F12: The objective of this study was to estimate the tetracycline resistance level in the modern population of Neisseria gonorrhoeae in the Russian Federation, where this drug was removed from the treatment regimen for gonococcal infections in 2003. A total of 401 isolates collected between 2015 and 2017 were analyzed for genetic markers (chromosomal porB, rpsJ and mtrR gene mutations and the plasmid-located tetM gene) involved in tetracycline resistance. Antibiotic susceptibility testing revealed that 19% of the strains were tetracycline resistant (MIC > 1 mg/L) and that 10% of the strains had intermediate susceptibility (0.5 < MIC ≤ 1 mg/L). Various combinations of mutations identified in the rpsJ (Val57Met/Leu), porB (Gly120Lys/Asp/Asn/Thr and Ala121/Asp/Asn/Gly), and mtrR (-35 del A) genes resulted in MIC increases of up to 1.47 mg/L (geometric mean value). The presence of the tetM gene was detected in 29 strains, including 18 tetM genes of the American type and 11 of the Dutch type. The tetM gene was associated with a strong increase in resistance (MIC > 8 mg/L). One N. gonorrhoeae isolate was found to carry a defective tetM gene with an AG deletion at position 1239-1240, а new stop codon was introduced that caused a defect in TetM protein synthesis and decrease in the tetracycline resistance. Phylogenetic trees constructed using N. gonorrhoeae NG-MAST and tetM loci were compared. Complex relationship was observed between the N. gonorrhoeae sequence type and the tetM plasmid type. Partial recovery of N. gonorrhoeae tetracycline susceptibility was observed relative to the proportion of isolates with resistance detected ten years ago (75%). However, the current levels of tetracycline resistance still preclude the renewed use of these drugs for gonococcal infection therapy. | G12: Yes | H12: No | I12: No | J12: This study assessed tetracycline resistance in Neisseria gonorrhoeae isolates in Russia after its removal from treatment protocols in 2003
A13: 31972174 | B13: Identification of potential therapeutic targets in Neisseria gonorrhoeae by an in-silico approach | C13: 2) Nuevos tratamientos | D13: in silico | F13: Neisseria gonorrhoeae is a gram negative diplococcus bacterium and the causative agent of the sexually transmitted disease Gonorrhea. It has been recently given the status of "superbug" by World Health Organization because of the increasing antibiotic resistance and unavailability of a viable vaccine candidate. Over recent years, there have been increasing reports about the use of subtractive genomics to identify potential drug and vaccine targets. Our study utilizes codon biasing, a tool to identify the essential genes, in N. gonorrhoeae that could be utilized as novel therapeutic targets for drug or vaccine development. Through the screening of 2350 total genes, we present a list of 29 such drug candidate genes based on codon adaptation. Through the data-mining with BLAST2GO and InterProScan databases, we could predict the function of these 29 genes. These genes are involved in pivotal cellular functions like DNA replication, energy synthesis and metabolites production. This study also shortlists the essential genes of N. gonorrhoeae that could be used to target Neisseria. We identified a molecule/drug which can be used to target essential protein DapD (succinyltransferase). | G13: No | H13: Yes | I13: No | J13: Essential genes identified via codon bias in N. gonorrhoeae suggest novel targets for drugs or vaccines, including DapD protein.
