Workbook
Name categoria: categorias!$A:$A
Name Estado: categorias!$C$2:$C$65536
Name EXCL: Excluidas!$A:$K
Name EXCLUIDAS: Excluidas!$A$1:$K$463
Name KEYWORDS: 'Palabras claves'!$A:$K
Name NgonorreaePost: '2017-2022'!#REF!
Name NgonorreaePre: '2012-2017'!$A$1:$K$534
Name PalabrasClave: 'Palabras claves'!$K$1:$K$1371
Name POST: '2017-2022'!$A:$K
Name POSTALERTA: '2017-2022'!$A$1:$B$857
Name PRE: '2012-2017'!$A:$K
Name PREALERTA: '2012-2017'!$A$1:$O$540
Name SegmentaciónDeDatos_Alerta1: #REF!
Name SegmentaciónDeDatos_KeyWords: #REF!
Name SegmentaciónDeDatos_PubYear: #REF!
Name subcategoria: categorias!$B:$B
Name TablaNgonoreae: '2012-2022'!$A$1:$K$4211

Sheet DashBoard
C2: Shigella spp 2012-2022
C3: Total de publicaciones de | F3: =C2 -> Shigella spp 2012-2022 | G3: : | H3: =COUNTA('2012-2022'!A$1:A$5016)-1 -> 5015
D5: Publicaciones por Año | I5: Categorías y Subcategorías
D17: Publicaciones por mes
C35: =IFERROR(__xludf.DUMMYFUNCTION("UNIQUE('2012-2022'!N:N)"),"Categoria") -> Categoria
C36: =IFERROR(__xludf.DUMMYFUNCTION("""COMPUTED_VALUE"""),"2) Nuevos tratamientos ") -> 2) Nuevos tratamientos | F36: =COUNTIF('2012-2022'!N:N,C36) -> 71
C37: =IFERROR(__xludf.DUMMYFUNCTION("""COMPUTED_VALUE"""),"")
C39: =IFERROR(__xludf.DUMMYFUNCTION("""COMPUTED_VALUE""")," 1) Reporte de cepas resistentes") -> 1) Reporte de cepas resistentes | F39: =COUNTIF('2012-2022'!N:N,C39) -> 29
C40: =IFERROR(__xludf.DUMMYFUNCTION("""COMPUTED_VALUE"""),"4) otros") -> 4) otros | F40: =COUNTIF('2012-2022'!N:N,C40) -> 29
C41: =IFERROR(__xludf.DUMMYFUNCTION("""COMPUTED_VALUE"""),"3) Inmunizacióm") -> 3) Inmunizacióm | F41: =COUNTIF('2012-2022'!N:N,C41) -> 12

Sheet categorias
A1: Categorias | B1: Subcategorias | C1: Estados
A2: 1) Reporte de cepas resistentes | B2: 2a) Productos naturales | C2: Revisar
A3: 2) Nuevos tratamientos | B3: 2b) Péptidos | C3: Listo
A4: 3) Inmunizacióm | B4: 2c) Droga de diseño | C4: Excluir
A5: 4) otros | B5: 2d) Anticuerpos | C5: Otros-A
B6: 2e) Bacteriófagos | C6: Otros-B
B7: 2f) Estrategias antivirulencia | C7: Otros-C
B8: 2g) nueva combinación de ATB | C8: Otros-D

Sheet TablasDinamicas
B1: Etiquetas de fila | C1: Cuenta de Title | E1: Cuenta de Title | I1: Categoria | J1: subcategoria | K1: Cuenta de Title
B2: PreAlerta | C2: 1822 | E2: PubYear | F2: PubMonth | G2: Total | I2: 1) Interacción huésped-patógeno | J2: (en blanco) | K2: 2 | L2: 1) Interacción huésped-patógeno | M2: (en blanco) | N2: =GETPIVOTDATA("Title",$I$1,"Categoria",L2,"subcategoria",M2) -> #REF! | P2: Etiquetas de fila | Q2: Cuenta de Title | S2: Etiquetas de fila | T2: Cuenta de Title | V2: Etiquetas de fila | W2: Cuenta de Title
B3: PostAlerta | C3: 2711 | E3: 2013 | F3: Jan | G3: 34 | I3: Total 1) Interacción huésped-patógeno | K3: 2 | L3: 2) Reporte de cepas resistentes | M3: (en blanco) | N3: =GETPIVOTDATA("Title",$I$1,"Categoria",L3,"subcategoria",M3) -> #REF! | P3: (en blanco) | Q3: 5015 | S3: 2012 | T3: 217 | V3: S/PalabrasClaves | W3: 3858
B4: Excluido | C4: 482 | F4: Feb | G4: 23 | I4: 2) Reporte de cepas resistentes | J4: (en blanco) | K4: 2 | L4: 3) Casos clínicos | M4: (en blanco) | N4: =GETPIVOTDATA("Title",$I$1,"Categoria",L4,"subcategoria",M4) -> #REF! | P4: Total general | Q4: 5015 | S4: 2013 | T4: 343 | V4: Excluido | W4: 364
B5: Total general | C5: 5015 | F5: Mar | G5: 40 | I5: Total 2) Reporte de cepas resistentes | K5: 2 | L5: 4) Nuevos tratamientos | M5: 4a) Productos naturales | N5: =GETPIVOTDATA("Title",$I$1,"Categoria",L5,"subcategoria",M5) -> #REF! | S5: 2014 | T5: 316 | V5: PostAlerta | W5: 2095
F6: Apr | G6: 28 | I6: 3) Casos clínicos | J6: (en blanco) | K6: 1 | L6: 4) Nuevos tratamientos | M6: 4b) Péptidos | N6: =GETPIVOTDATA("Title",$I$1,"Categoria",L6,"subcategoria",M6) -> #REF! | S6: 2015 | T6: 297 | V6: PreAlerta | W6: 1399
F7: May | G7: 29 | I7: Total 3) Casos clínicos | K7: 1 | L7: 4) Nuevos tratamientos | M7: 4c) Droga de diseño | N7: =GETPIVOTDATA("Title",$I$1,"Categoria",L7,"subcategoria",M7) -> #REF! | S7: 2016 | T7: 314 | V7: Total general | W7: 3858
F8: Jun | G8: 24 | I8: 4) Nuevos tratamientos | J8: 4a) Productos naturales | K8: 1 | L8: 4) Nuevos tratamientos | M8: 4d) Anticuerpos | N8: =GETPIVOTDATA("Title",$I$1,"Categoria",L8,"subcategoria",M8) -> #REF! | S8: 2017 | T8: 337
F9: Jul | G9: 33 | J9: 4b) Péptidos | K9: 1 | L9: 4) Nuevos tratamientos | M9: 4e) Bacteriófagos | N9: =GETPIVOTDATA("Title",$I$1,"Categoria",L9,"subcategoria",M9) -> #REF! | S9: 2018 | T9: 346
F10: Aug | G10: 42 | J10: 4c) Droga de diseño | K10: 2 | L10: 4) Nuevos tratamientos | M10: 4f) Estrategias antivirulencia | N10: =GETPIVOTDATA("Title",$I$1,"Categoria",L10,"subcategoria",M10) -> #REF! | S10: 2019 | T10: 392
F11: Sep | G11: 30 | J11: 4d) Anticuerpos | K11: 1 | S11: 2020 | T11: 454
F12: Oct | G12: 36 | J12: 4e) Bacteriófagos | K12: 1 | S12: 2021 | T12: 536
F13: Nov | G13: 23 | I13: Total 4) Nuevos tratamientos | K13: 6 | S13: 2022 | T13: 293
F14: Dec | G14: 51 | I14: (en blanco) | J14: (en blanco) | K14: 3847 | S14: 2023 | T14: 13
F15: (en blanco) | G15: 35 | I15: Total (en blanco) | K15: 3847 | S15: Total general | T15: 3858
F16: Summer | G16: 1 | I16: Total general | K16: 3858
F17: Autumn | G17: 1
E18: Total 2013 | G18: 430
E19: Total general | G19: 430

Sheet 2012-2022
A1: PMID | B1: Title | C1: Authors | D1: Citation | E1: First Author | F1: Journal/Book | G1: Publication Year | H1: Create Date | I1: PMCID | J1: NIHMS ID | K1: DOI | L1: Alerta | M1: KeyWords | N1: Categoria | O1: Subcategorias | P1: fecha de publicación | Q1: Estado | R1: PubYear | S1: PubMonth | T1: Abstract | U1: 1) Antimicrobial Resistance stain | V1: 2) New treatment | W1: 3) Immunization | X1: Human_summary
A2: 35174771 | B2: In vitro and in silico screening of novel typhoid drugs from endangered herb (Enicostema axillare) | C2: Perumal S, Gopal Samy M, Subramanian D. | D2: J Biomol Struct Dyn. 2023 Apr;41(7):2926-2936. doi: 10.1080/07391102.2022.2041488. Epub 2022 Feb 17. | E2: Perumal S | F2: J Biomol Struct Dyn | G2: 2023 | H2: 44609 | K2: 10.1080/07391102.2022.2041488 | L2: =IF(ISNUMBER(VLOOKUP(A2,EXCL,1,FALSE)),"Excluido",IF(ISNUMBER(VLOOKUP(A2,POST,1,FALSE)),"PostAlerta",IF(ISNUMBER(VLOOKUP(A2,PRE,1,FALSE)),"PreAlerta",""))) -> PostAlerta | M2: =IF(ISNUMBER(VLOOKUP(A2,KEYWORDS,1,FALSE)),"C/PalabrasClaves","S/PalabrasClaves") -> S/PalabrasClaves | N2: 2) Nuevos tratamientos | O2: 2a) Productos naturales | P2: 2023 Apr | Q2: Listo | R2: =LEFT(P2,4) -> 2023 | S2: Apr | T2: In the present study, antibacterial activity of swertiamarin from Enicostema axillare (Lam) was checked against three different human gram-negative pathogens namely Salmonella typhi, Klebsiella pneumoniae and Shigella flexneri. Minimum inhibitory concentration assay revealed low dose and efficient activity of swertiamarin on the above said pathogens. Though swertiamarin is a well-studied and characterized compound, there is no experimental proof available for its antibacterial activity. To gain more insight about the antibacterial efficiency of swertiamarin against typhoid causing S. typhi, a comparative molecular docking of S. typhi OmpF (3NSG) was performed with swertiamarin and other typhoid drugs available in the market which exposed better activity strength of swertiamarin compared with that of the other drugs. Further, molecular dynamics of S. typhi OmpF-swertiamarin shows good flexibility and stability at 100 ns. The outcome of this work will definitely provide an idea of using very low dose of swertiamarin as a potent and promising drug against typhoid fever.Communicated by Ramaswamy H. Sarma. | U2: No | V2: Yes | W2: No | X2: The study evaluates the antibacterial activity of swertiamarin as a potential drug against human pathogens, especially Salmonella typhi. | Y2: =IF(ISNUMBER(SEARCH("combination", B2)), "combination ", "")
A3: 36908341 | B3: Freeze dried probiotic carrot juice powder for better storage stability of probiotic | C3: Rishabh D, Athira A, Preetha R, Nagamaniammai G. | D3: J Food Sci Technol. 2023 Mar;60(3):916-924. doi: 10.1007/s13197-021-05259-2. Epub 2021 Sep 6. | E3: Rishabh D | F3: J Food Sci Technol | G3: 2023 | H3: 44998 | I3: PMC9998781 | K3: 10.1007/s13197-021-05259-2 | L3: =IF(ISNUMBER(VLOOKUP(A3,EXCL,1,FALSE)),"Excluido",IF(ISNUMBER(VLOOKUP(A3,POST,1,FALSE)),"PostAlerta",IF(ISNUMBER(VLOOKUP(A3,PRE,1,FALSE)),"PreAlerta",""))) -> PostAlerta | M3: =IF(ISNUMBER(VLOOKUP(A3,KEYWORDS,1,FALSE)),"C/PalabrasClaves","S/PalabrasClaves") -> S/PalabrasClaves | N3: =IF(ISNUMBER(SEARCH("TREATMENT", B3)), "4) Nuevos tratamientos", "") | P3: 2023 Mar | Q3: Excluir | R3: =LEFT(P3,4) -> 2023 | S3: Mar | Y3: =IF(ISNUMBER(SEARCH("combination", B3)), "combination ", "")
A4: 34453485 | B4: Green synthesis and characterization of Solanum xanthocarpum capped silver nanoparticles and its antimicrobial effect on multidrug-resistant bacterial (MDR) isolates | C4: Pungle R, Nile SH, Kharat AS. | D4: Chem Biol Drug Des. 2023 Mar;101(3):469-478. doi: 10.1111/cbdd.13945. Epub 2021 Oct 1. | E4: Pungle R | F4: Chem Biol Drug Des | G4: 2023 | H4: 44436 | K4: 10.1111/cbdd.13945 | L4: =IF(ISNUMBER(VLOOKUP(A4,EXCL,1,FALSE)),"Excluido",IF(ISNUMBER(VLOOKUP(A4,POST,1,FALSE)),"PostAlerta",IF(ISNUMBER(VLOOKUP(A4,PRE,1,FALSE)),"PreAlerta",""))) -> PostAlerta | M4: =IF(ISNUMBER(A4),(IF(ISNUMBER(VLOOKUP(A4,KEYWORDS,1,FALSE)),"C/PalabrasClaves","S/PalabrasClaves")),"") -> C/PalabrasClaves | N4: 2) Nuevos tratamientos | O4: 2b) Péptidos | P4: 2023 Mar | Q4: Listo | R4: =LEFT(P4,4) -> 2023 | S4: Mar | T4: Plant extracts and their bioactive compounds are considered as the promising options for green synthesis of nanoparticles instead expensive and hazardous materials. Here, Solanum xanthocarpum fruit was used for synthesis of silver nanoparticles (AgNP). The synthesized AgNPs were characterized by using chromatographic and spectroscopic analytical methods. AgNPs were confirmed by UV-visible absorbance at 420-470 nm. TEM analysis showed AgNP with 22.45 nm average size. X-ray diffraction studies revealed the crystalline and face central cubic nature of AgNPs. FTIR analysis revealed functional group present over AgNPs. The aminodiphenyl acetic acid, clomipramine, and fonisopril from fruit extracts were found to be major capping agents on AgNPs as a result of analysis by HRLC-MS. All clinical isolates showed resistance for ampicilline, amoxyclav, niladixic acid, and sulphafurazole, suggesting multidrug resistance. The results showed that all isolates were sensitive to AgNPs synthesized fruit extracts. On the contrary, all isolates were resistant to whole S. xanthocarpum fruit extracts alone. The antimicrobial activity of AgNP was explored against multidrug-resistant (MDR) Gram-negative clinical isolates including Escherichia coli, Shigella spp., Aeronomonas spp. and Pseudomonas spp. MIC values ranged between 1.25 mg/ml and 2.5 mg/ml at 8 McFarland's standards. Minimum bactericidal concentration was found to be in between 2.5 mg/ml to 5 mg/ml. Nanoparticles synthesized from fruit extract of S. xanthocarpum containing aminodiphenyl acetic acid, clomipramine, and fonisopril metabolites exhibit promising antimicrobial activity against MDR Gram-negative clinical isolates. | U4: No | V4: Yes | W4: No | X4: Silver nanoparticles synthesized from Solanum xanthocarpum fruit show promising antimicrobial activity against multidrug-resistant Gram-negative isolates. | Y4: =IF(ISNUMBER(SEARCH("combination", B4)), "combination ", "")
A5: 36817108 | B5: Analysis of microbial diversity in the feces of Arborophila rufipectus | C5: Ma X, Li J, Chen B, Li X, Ling Z, Feng S, Cao S, Zuo Z, Deng J, Huang X, Cai D, Wen Y, Zhao Q, Wang Y, Zhong Z, Peng G, Jiang Y, Gu Y. | D5: Front Microbiol. 2023 Feb 2;13:1075041. doi: 10.3389/fmicb.2022.1075041. eCollection 2022. | E5: Ma X | F5: Front Microbiol | G5: 2023 | H5: 44980 | I5: PMC9932278 | K5: 10.3389/fmicb.2022.1075041 | L5: =IF(ISNUMBER(VLOOKUP(A5,EXCL,1,FALSE)),"Excluido",IF(ISNUMBER(VLOOKUP(A5,POST,1,FALSE)),"PostAlerta",IF(ISNUMBER(VLOOKUP(A5,PRE,1,FALSE)),"PreAlerta",""))) -> PostAlerta | M5: =IF(ISNUMBER(A5),(IF(ISNUMBER(VLOOKUP(A5,KEYWORDS,1,FALSE)),"C/PalabrasClaves","S/PalabrasClaves")),"") -> S/PalabrasClaves | N5: =IF(ISNUMBER(SEARCH("TREATMENT", B5)), "4) Nuevos tratamientos", "") | P5: 2023 Feb 2 | Q5: Excluir | R5: =LEFT(P5,4) -> 2023 | S5: Feb | Y5: =IF(ISNUMBER(SEARCH("combination", B5)), "combination ", "")
A6: 36776392 | B6: Recent updates on correlates of vaccine-induced protection | C6: Plotkin SA. | D6: Front Immunol. 2023 Jan 27;13:1081107. doi: 10.3389/fimmu.2022.1081107. eCollection 2022. | E6: Plotkin SA | F6: Front Immunol | G6: 2023 | H6: 44970 | I6: PMC9912984 | K6: 10.3389/fimmu.2022.1081107 | L6: =IF(ISNUMBER(VLOOKUP(A6,EXCL,1,FALSE)),"Excluido",IF(ISNUMBER(VLOOKUP(A6,POST,1,FALSE)),"PostAlerta",IF(ISNUMBER(VLOOKUP(A6,PRE,1,FALSE)),"PreAlerta",""))) -> PostAlerta | M6: =IF(ISNUMBER(A6),(IF(ISNUMBER(VLOOKUP(A6,KEYWORDS,1,FALSE)),"C/PalabrasClaves","S/PalabrasClaves")),"") -> S/PalabrasClaves | P6: 2023 Jan 27 | Q6: Excluir | R6: =LEFT(P6,4) -> 2023 | S6: Jan | Y6: =IF(ISNUMBER(SEARCH("combination", B6)), "combination ", "")
A7: 36755580 | B7: Dysbiosis of gut microbiota and decreased propionic acid associated with metabolic abnormality in Cushing's syndrome | C7: Zhang Q, Hu WM, Deng YL, Wan JJ, Wang YJ, Jin P. | D7: Front Endocrinol (Lausanne). 2023 Jan 23;13:1095438. doi: 10.3389/fendo.2022.1095438. eCollection 2022. | E7: Zhang Q | F7: Front Endocrinol (Lausanne) | G7: 2023 | H7: 44966 | I7: PMC9901362 | K7: 10.3389/fendo.2022.1095438 | L7: =IF(ISNUMBER(VLOOKUP(A7,EXCL,1,FALSE)),"Excluido",IF(ISNUMBER(VLOOKUP(A7,POST,1,FALSE)),"PostAlerta",IF(ISNUMBER(VLOOKUP(A7,PRE,1,FALSE)),"PreAlerta",""))) -> PostAlerta | M7: =IF(ISNUMBER(A7),(IF(ISNUMBER(VLOOKUP(A7,KEYWORDS,1,FALSE)),"C/PalabrasClaves","S/PalabrasClaves")),"") -> S/PalabrasClaves | N7: =IF(ISNUMBER(SEARCH("TREATMENT", B7)), "4) Nuevos tratamientos", "") | P7: 2023 Jan 23 | Q7: Excluir | R7: =LEFT(P7,4) -> 2023 | S7: Jan | Y7: =IF(ISNUMBER(SEARCH("combination", B7)), "combination ", "")
A8: 36741899 | B8: Metagenomic insights into the relationship between gut microbiota and residual feed intake of small-sized meat ducks | C8: Bai H, Shi L, Guo Q, Jiang Y, Li X, Geng D, Wang C, Bi Y, Wang Z, Chen G, Xue F, Chang G. | D8: Front Microbiol. 2023 Jan 18;13:1075610. doi: 10.3389/fmicb.2022.1075610. eCollection 2022. | E8: Bai H | F8: Front Microbiol | G8: 2023 | H8: 44963 | I8: PMC9889972 | K8: 10.3389/fmicb.2022.1075610 | L8: =IF(ISNUMBER(VLOOKUP(A8,EXCL,1,FALSE)),"Excluido",IF(ISNUMBER(VLOOKUP(A8,POST,1,FALSE)),"PostAlerta",IF(ISNUMBER(VLOOKUP(A8,PRE,1,FALSE)),"PreAlerta",""))) -> PostAlerta | M8: =IF(ISNUMBER(A8),(IF(ISNUMBER(VLOOKUP(A8,KEYWORDS,1,FALSE)),"C/PalabrasClaves","S/PalabrasClaves")),"") -> S/PalabrasClaves | N8: =IF(ISNUMBER(SEARCH("TREATMENT", B8)), "4) Nuevos tratamientos", "") | P8: 2023 Jan 18 | Q8: Excluir | R8: =LEFT(P8,4) -> 2023 | S8: Jan | Y8: =IF(ISNUMBER(SEARCH("combination", B8)), "combination ", "")
A9: 36713461 | B9: Fecal microbiota transplantation and short-chain fatty acids reduce sepsis mortality by remodeling antibiotic-induced gut microbiota disturbances | C9: Lou X, Xue J, Shao R, Yang Y, Ning D, Mo C, Wang F, Chen G. | D9: Front Immunol. 2023 Jan 11;13:1063543. doi: 10.3389/fimmu.2022.1063543. eCollection 2022. | E9: Lou X | F9: Front Immunol | G9: 2023 | H9: 44956 | I9: PMC9874322 | K9: 10.3389/fimmu.2022.1063543 | L9: =IF(ISNUMBER(VLOOKUP(A9,EXCL,1,FALSE)),"Excluido",IF(ISNUMBER(VLOOKUP(A9,POST,1,FALSE)),"PostAlerta",IF(ISNUMBER(VLOOKUP(A9,PRE,1,FALSE)),"PreAlerta",""))) -> PostAlerta | M9: =IF(ISNUMBER(A9),(IF(ISNUMBER(VLOOKUP(A9,KEYWORDS,1,FALSE)),"C/PalabrasClaves","S/PalabrasClaves")),"") -> C/PalabrasClaves | N9: =IF(ISNUMBER(SEARCH("TREATMENT", B9)), "4) Nuevos tratamientos", "") | P9: 2023 Jan 11 | Q9: Excluir | R9: =LEFT(P9,4) -> 2023 | S9: Jan | Y9: =IF(ISNUMBER(SEARCH("combination", B9)), "combination ", "")
A10: 36713168 | B10: Altered intestinal microbiota composition with epilepsy and concomitant diarrhea and potential indicator biomarkers in infants | C10: Liu T, Jia F, Guo Y, Wang Q, Zhang X, Chang F, Xie Y. | D10: Front Microbiol. 2023 Jan 11;13:1081591. doi: 10.3389/fmicb.2022.1081591. eCollection 2022. | E10: Liu T | F10: Front Microbiol | G10: 2023 | H10: 44956 | I10: PMC9874329 | K10: 10.3389/fmicb.2022.1081591 | L10: =IF(ISNUMBER(VLOOKUP(A10,EXCL,1,FALSE)),"Excluido",IF(ISNUMBER(VLOOKUP(A10,POST,1,FALSE)),"PostAlerta",IF(ISNUMBER(VLOOKUP(A10,PRE,1,FALSE)),"PreAlerta",""))) -> PostAlerta | M10: =IF(ISNUMBER(A10),(IF(ISNUMBER(VLOOKUP(A10,KEYWORDS,1,FALSE)),"C/PalabrasClaves","S/PalabrasClaves")),"") -> S/PalabrasClaves | N10: =IF(ISNUMBER(SEARCH("TREATMENT", B10)), "4) Nuevos tratamientos", "") | P10: 2023 Jan 11 | Q10: Excluir | R10: =LEFT(P10,4) -> 2023 | S10: Jan | Y10: =IF(ISNUMBER(SEARCH("combination", B10)), "combination ", "")
A11: 36704458 | B11: Alteration of the gut microbiota and metabolite phenylacetylglutamine in patients with severe chronic heart failure | C11: Zhang Z, Cai B, Sun Y, Deng H, Wang H, Qiao Z. | D11: Front Cardiovasc Med. 2023 Jan 10;9:1076806. doi: 10.3389/fcvm.2022.1076806. eCollection 2022. | E11: Zhang Z | F11: Front Cardiovasc Med | G11: 2023 | H11: 44953 | I11: PMC9871785 | K11: 10.3389/fcvm.2022.1076806 | L11: =IF(ISNUMBER(VLOOKUP(A11,EXCL,1,FALSE)),"Excluido",IF(ISNUMBER(VLOOKUP(A11,POST,1,FALSE)),"PostAlerta",IF(ISNUMBER(VLOOKUP(A11,PRE,1,FALSE)),"PreAlerta",""))) -> PostAlerta | M11: =IF(ISNUMBER(A11),(IF(ISNUMBER(VLOOKUP(A11,KEYWORDS,1,FALSE)),"C/PalabrasClaves","S/PalabrasClaves")),"") -> S/PalabrasClaves | N11: =IF(ISNUMBER(SEARCH("TREATMENT", B11)), "4) Nuevos tratamientos", "") | P11: 2023 Jan 10 | Q11: Excluir | R11: =LEFT(P11,4) -> 2023 | S11: Jan | Y11: =IF(ISNUMBER(SEARCH("combination", B11)), "combination ", "")
A12: 36704106 | B12: Gut microbiota signatures in tissues of the colorectal polyp and normal colorectal mucosa, and faeces | C12: Zhong X, Wang Y, Xu J, Cao H, Zhang F, Wang X. | D12: Front Cell Infect Microbiol. 2023 Jan 10;12:1054808. doi: 10.3389/fcimb.2022.1054808. eCollection 2022. | E12: Zhong X | F12: Front Cell Infect Microbiol | G12: 2023 | H12: 44953 | I12: PMC9871776 | K12: 10.3389/fcimb.2022.1054808 | L12: =IF(ISNUMBER(VLOOKUP(A12,EXCL,1,FALSE)),"Excluido",IF(ISNUMBER(VLOOKUP(A12,POST,1,FALSE)),"PostAlerta",IF(ISNUMBER(VLOOKUP(A12,PRE,1,FALSE)),"PreAlerta",""))) -> Excluido | M12: =IF(ISNUMBER(A12),(IF(ISNUMBER(VLOOKUP(A12,KEYWORDS,1,FALSE)),"C/PalabrasClaves","S/PalabrasClaves")),"") -> S/PalabrasClaves | N12: =IF(ISNUMBER(SEARCH("TREATMENT", B12)), "4) Nuevos tratamientos", "") | P12: 2023 Jan 10 | Q12: Excluir | R12: =LEFT(P12,4) -> 2023 | S12: Jan | Y12: =IF(ISNUMBER(SEARCH("combination", B12)), "combination ", "")
A13: 36687653 | B13: Traditional Chinese medicine improves myasthenia gravis by regulating the symbiotic homeostasis of the intestinal microbiota and host | C13: Zhao M, Liu L, Liu F, Liu L, Liu Z, Gao Y, Cao J. | D13: Front Microbiol. 2023 Jan 6;13:1082565. doi: 10.3389/fmicb.2022.1082565. eCollection 2022. | E13: Zhao M | F13: Front Microbiol | G13: 2023 | H13: 44949 | I13: PMC9852828 | K13: 10.3389/fmicb.2022.1082565 | L13: =IF(ISNUMBER(VLOOKUP(A13,EXCL,1,FALSE)),"Excluido",IF(ISNUMBER(VLOOKUP(A13,POST,1,FALSE)),"PostAlerta",IF(ISNUMBER(VLOOKUP(A13,PRE,1,FALSE)),"PreAlerta",""))) -> PostAlerta | M13: =IF(ISNUMBER(A13),(IF(ISNUMBER(VLOOKUP(A13,KEYWORDS,1,FALSE)),"C/PalabrasClaves","S/PalabrasClaves")),"") -> S/PalabrasClaves | N13: =IF(ISNUMBER(SEARCH("TREATMENT", B13)), "4) Nuevos tratamientos", "") | P13: 2023 Jan 6 | Q13: Excluir | R13: =LEFT(P13,4) -> 2023 | S13: Jan | Y13: =IF(ISNUMBER(SEARCH("combination", B13)), "combination ", "")
A14: 36687673 | B14: Lacticaseibacillus rhamnosus Hao9 exerts antidiabetic effects by regulating gut microbiome, glucagon metabolism, and insulin levels in type 2 diabetic mice | C14: Han M, Liao W, Dong Y, Bai C, Gai Z. | D14: Front Nutr. 2023 Jan 5;9:1081778. doi: 10.3389/fnut.2022.1081778. eCollection 2022. | E14: Han M | F14: Front Nutr | G14: 2023 | H14: 44949 | I14: PMC9849894 | K14: 10.3389/fnut.2022.1081778 | L14: =IF(ISNUMBER(VLOOKUP(A14,EXCL,1,FALSE)),"Excluido",IF(ISNUMBER(VLOOKUP(A14,POST,1,FALSE)),"PostAlerta",IF(ISNUMBER(VLOOKUP(A14,PRE,1,FALSE)),"PreAlerta",""))) -> PostAlerta | M14: =IF(ISNUMBER(A14),(IF(ISNUMBER(VLOOKUP(A14,KEYWORDS,1,FALSE)),"C/PalabrasClaves","S/PalabrasClaves")),"") -> S/PalabrasClaves | N14: =IF(ISNUMBER(SEARCH("TREATMENT", B14)), "4) Nuevos tratamientos", "") | P14: 2023 Jan 5 | Q14: Excluir | R14: =LEFT(P14,4) -> 2023 | S14: Jan | Y14: =IF(ISNUMBER(SEARCH("combination", B14)), "combination ", "")
A15: 36686167 | B15: Pueraria lobata polysaccharides alleviate neonatal calf diarrhea by modulating gut microbiota and metabolites | C15: Shen L, Shen Y, You L, Zhang Y, Su Z, Peng G, Deng J, Zuo Z, Zhong Z, Ren Z, Yu S, Zong X, Zhu Y, Cao S. | D15: Front Vet Sci. 2023 Jan 4;9:1024392. doi: 10.3389/fvets.2022.1024392. eCollection 2022. | E15: Shen L | F15: Front Vet Sci | G15: 2023 | H15: 44949 | I15: PMC9845628 | K15: 10.3389/fvets.2022.1024392 | L15: =IF(ISNUMBER(VLOOKUP(A15,EXCL,1,FALSE)),"Excluido",IF(ISNUMBER(VLOOKUP(A15,POST,1,FALSE)),"PostAlerta",IF(ISNUMBER(VLOOKUP(A15,PRE,1,FALSE)),"PreAlerta",""))) -> PostAlerta | M15: =IF(ISNUMBER(A15),(IF(ISNUMBER(VLOOKUP(A15,KEYWORDS,1,FALSE)),"C/PalabrasClaves","S/PalabrasClaves")),"") -> S/PalabrasClaves | N15: 2) Nuevos tratamientos | O15: 2b) Péptidos | P15: 2023 Jan 4 | Q15: Listo | R15: =LEFT(P15,4) -> 2023 | S15: Jan | T15: Introduction: Neonatal calf diarrhea (NCD) is still one of the most critical diseases in calf rearing. Studies have shown that Pueraria lobata polysaccharides (PLP) have intense antioxidant and immunomodulatory activity and modulate gut microbiota. This randomized clinical trial aimed to determine the effect of PLP on the neonatal calf with diarrhea. Methods: In this study, we recorded the fecal score of experimental calves, and calves with fecal scores ≥ 2 were determined as diarrhea and assessed their serum concentrations of inflammatory cytokines and oxidative damage-related indices. Fecal microbiota and metabolomics of diarrheal calves were further investigated. Results: Results showed that treatment with PLP decreased the fecal score of diarrheal calves, serum concentrations of IL-1β, TNF-γ, and malondialdehyde, and also elevated the level of superoxide dismutase. In addition, PLP treatment altered the gut microbiota, significantly increased the relative abundances of beneficial bacteria, including the phyla Bacteroidetes and Actinobacteria, the genus Collinsella, Megamonas, and Bifidobacterium; decreased the relative abundances of pathogenetic or diarrhea related bacteria, such as Proteobacteria, Fusobacteria, Clostridium_sensu_stricto_1, and Escherichia_Shigella. Moreover, PLP can increase the fecal concentrations of isobutyric acid, propionic acid, and pantothenate; lower the levels of PC [18:0/18:1(9Z)], arachidonic acid, and docosahexaenoic acid. Discussion: Thus, the results suggested that the PLP may perform the therapeutic activity via alleviating intestinal inflammation and regulating gut microbiota, avoiding further dysbiosis to restore the metabolism of gut microbiota, and finally promoting the recovery of diarrhea. The change further mitigated intestinal inflammation and oxidative damage in diarrheal calves. This indicated that PLP might be a promising treatment to attenuate diarrhea in neonatal calves. | U15: No | V15: Yes | W15: No | X15: PLP treatment reduced diarrhea, inflammation, and oxidative damage in neonatal calves by regulating gut microbiota and improving metabolism. | Y15: =IF(ISNUMBER(SEARCH("combination", B15)), "combination ", "")
A16: 34998646 | B16: An in vivo acute toxicity and anti-shigellosis effect of designed formulation on rat | C16: Singh D, Agarwal V. | D16: J Ayurveda Integr Med. 2023 Jan-Feb;14(1):100536. doi: 10.1016/j.jaim.2021.100536. Epub 2022 Jan 5. | E16: Singh D | F16: J Ayurveda Integr Med | G16: 2023 | H16: 44570 | I16: PMC10105236 | K16: 10.1016/j.jaim.2021.100536 | L16: =IF(ISNUMBER(VLOOKUP(A16,EXCL,1,FALSE)),"Excluido",IF(ISNUMBER(VLOOKUP(A16,POST,1,FALSE)),"PostAlerta",IF(ISNUMBER(VLOOKUP(A16,PRE,1,FALSE)),"PreAlerta",""))) -> PostAlerta | M16: =IF(ISNUMBER(A16),(IF(ISNUMBER(VLOOKUP(A16,KEYWORDS,1,FALSE)),"C/PalabrasClaves","S/PalabrasClaves")),"") -> S/PalabrasClaves | N16: 2) Nuevos tratamientos | O16: 2c) Droga de diseño | P16: 2023 Jan-Feb | Q16: Listo | R16: =LEFT(P16,4) -> 2023 | S16: Feb | T16: Introduction: Shigellosis is an intestinal disease and is one of the main causes of morbidity and mortality among children in India. The study aims to analyze the effect of the designed formulation on the hematological parameters in shigellosis-induced rats and assess the in vivo toxicity of this formulation. Methods: Male Wistar rats were housed in different groups. Group 1 is normal control; group 2 is diseased control; group 3 and group 4 diseased rats received 250 mg/kg formulation and 20 mg/kg body weight norfloxacin, respectively, orally once a day. Shigellosis was induced by a single intraperitoneal injection of Shigella flexneri, and bacterial load was calculated using the Shigella agar plate. On completion of the study, blood was collected for hematological as well as electrolyte analysis. Results: The in vivo acute toxicity results indicate that the formulation is safe up to 2000 mg/kg. Furthermore, formulation significantly (p < 0.05) decreases the bacterial load and increases the RBC, WBC, MCHC, platelet, hemoglobin, and electrolytes (Ca++, K+, and Na+) compared to diseased control. Conclusion: The results support the designed formulation's safety and therapeutic effects and support its use as an alternative medicine for treating shigellosis. | U16: No | V16: Yes | W16: No | X16: The formulation reduced bacterial load and improved RBC, WBC, MCHC, platelets, hemoglobin, and electrolytes in shigellosis-induced rats. | Y16: =IF(ISNUMBER(SEARCH("combination", B16)), "combination ", "")
A17: 36643973 | B17: Gut microbiota mediates positive effects of liraglutide on dyslipidemia in mice fed a high-fat diet | C17: Zhao L, Qiu Y, Zhang P, Wu X, Zhao Z, Deng X, Yang L, Wang D, Yuan G. | D17: Front Nutr. 2022 Dec 29;9:1048693. doi: 10.3389/fnut.2022.1048693. eCollection 2022. | E17: Zhao L | F17: Front Nutr | G17: 2022 | H17: 44942 | I17: PMC9835552 | K17: 10.3389/fnut.2022.1048693 | L17: =IF(ISNUMBER(VLOOKUP(A17,EXCL,1,FALSE)),"Excluido",IF(ISNUMBER(VLOOKUP(A17,POST,1,FALSE)),"PostAlerta",IF(ISNUMBER(VLOOKUP(A17,PRE,1,FALSE)),"PreAlerta",""))) -> PostAlerta | M17: =IF(ISNUMBER(A17),(IF(ISNUMBER(VLOOKUP(A17,KEYWORDS,1,FALSE)),"C/PalabrasClaves","S/PalabrasClaves")),"") -> S/PalabrasClaves | N17: =IF(ISNUMBER(SEARCH("TREATMENT", B17)), "4) Nuevos tratamientos", "") | P17: 2022 Dec 29 | Q17: Excluir | R17: =LEFT(P17,4) -> 2022 | S17: Dec | Y17: =IF(ISNUMBER(SEARCH("combination", B17)), "combination ", "")
A18: 36601354 | B18: Gut Microbiota Signature of Obese Adults Across Different Classifications | C18: Hu J, Guo P, Mao R, Ren Z, Wen J, Yang Q, Yan T, Yu J, Zhang T, Liu Y. | D18: Diabetes Metab Syndr Obes. 2022 Dec 29;15:3933-3947. doi: 10.2147/DMSO.S387523. eCollection 2022. | E18: Hu J | F18: Diabetes Metab Syndr Obes | G18: 2022 | H18: 44931 | I18: PMC9807070 | K18: 10.2147/DMSO.S387523 | L18: =IF(ISNUMBER(VLOOKUP(A18,EXCL,1,FALSE)),"Excluido",IF(ISNUMBER(VLOOKUP(A18,POST,1,FALSE)),"PostAlerta",IF(ISNUMBER(VLOOKUP(A18,PRE,1,FALSE)),"PreAlerta",""))) -> PostAlerta | M18: =IF(ISNUMBER(A18),(IF(ISNUMBER(VLOOKUP(A18,KEYWORDS,1,FALSE)),"C/PalabrasClaves","S/PalabrasClaves")),"") -> S/PalabrasClaves | N18: =IF(ISNUMBER(SEARCH("TREATMENT", B18)), "4) Nuevos tratamientos", "") | P18: 2022 Dec 29 | Q18: Excluir | R18: =LEFT(P18,4) -> 2022 | S18: Dec | Y18: =IF(ISNUMBER(SEARCH("combination", B18)), "combination ", "")
A19: 36632531 | B19: Digyalipopeptide A, an antiparasitic cyclic peptide from the Ghanaian Bacillus sp. strain DE2B | C19: Nartey AP, Dofuor AK, Owusu KBA, Camas AS, Deng H, Jaspars M, Kyeremeh K. | D19: Beilstein J Org Chem. 2022 Dec 28;18:1763-1771. doi: 10.3762/bjoc.18.185. eCollection 2022. | E19: Nartey AP | F19: Beilstein J Org Chem | G19: 2022 | H19: 44938 | I19: PMC9811306 | K19: 10.3762/bjoc.18.185 | L19: =IF(ISNUMBER(VLOOKUP(A19,EXCL,1,FALSE)),"Excluido",IF(ISNUMBER(VLOOKUP(A19,POST,1,FALSE)),"PostAlerta",IF(ISNUMBER(VLOOKUP(A19,PRE,1,FALSE)),"PreAlerta",""))) -> PostAlerta | M19: =IF(ISNUMBER(A19),(IF(ISNUMBER(VLOOKUP(A19,KEYWORDS,1,FALSE)),"C/PalabrasClaves","S/PalabrasClaves")),"") -> S/PalabrasClaves | N19: =IF(ISNUMBER(SEARCH("TREATMENT", B19)), "4) Nuevos tratamientos", "") | P19: 2022 Dec 28 | Q19: Excluir | R19: =LEFT(P19,4) -> 2022 | S19: Dec | Y19: =IF(ISNUMBER(SEARCH("combination", B19)), "combination ", "")
A20: 36619987 | B20: Epidemiological investigations of diarrhea in children in Praia city, Cape Verde | C20: Colito DA, Dorta-Guerra R, Da Costa Lima HS, Pina C, Gonçalves D, Valladares B, Foronda P. | D20: Front Microbiol. 2022 Dec 22;13:1059431. doi: 10.3389/fmicb.2022.1059431. eCollection 2022. | E20: Colito DA | F20: Front Microbiol | G20: 2022 | H20: 44935 | I20: PMC9814011 | K20: 10.3389/fmicb.2022.1059431 | L20: =IF(ISNUMBER(VLOOKUP(A20,EXCL,1,FALSE)),"Excluido",IF(ISNUMBER(VLOOKUP(A20,POST,1,FALSE)),"PostAlerta",IF(ISNUMBER(VLOOKUP(A20,PRE,1,FALSE)),"PreAlerta",""))) -> PostAlerta | M20: =IF(ISNUMBER(A20),(IF(ISNUMBER(VLOOKUP(A20,KEYWORDS,1,FALSE)),"C/PalabrasClaves","S/PalabrasClaves")),"") -> S/PalabrasClaves | P20: 2022 Dec 22 | Q20: Excluir | R20: =LEFT(P20,4) -> 2022 | S20: Dec | Y20: =IF(ISNUMBER(SEARCH("combination", B20)), "combination ", "")
A21: 36618686 | B21: Anti-diabetic prospects of dietary bio-actives of millets and the significance of the gut microbiota: A case of finger millet | C21: Singh V, Lee G, Son H, Amani S, Baunthiyal M, Shin JH. | D21: Front Nutr. 2022 Dec 22;9:1056445. doi: 10.3389/fnut.2022.1056445. eCollection 2022. | E21: Singh V | F21: Front Nutr | G21: 2022 | H21: 44935 | I21: PMC9815516 | K21: 10.3389/fnut.2022.1056445 | L21: =IF(ISNUMBER(VLOOKUP(A21,EXCL,1,FALSE)),"Excluido",IF(ISNUMBER(VLOOKUP(A21,POST,1,FALSE)),"PostAlerta",IF(ISNUMBER(VLOOKUP(A21,PRE,1,FALSE)),"PreAlerta",""))) -> Excluido | M21: =IF(ISNUMBER(A21),(IF(ISNUMBER(VLOOKUP(A21,KEYWORDS,1,FALSE)),"C/PalabrasClaves","S/PalabrasClaves")),"") -> S/PalabrasClaves | P21: 2022 Dec 22 | Q21: Excluir | R21: =LEFT(P21,4) -> 2022 | S21: Dec | Y21: =IF(ISNUMBER(SEARCH("combination", B21)), "combination ", "")
A22: 34931711 | B22: BCL-2-family protein tBID can act as a BAX-like effector of apoptosis | C22: Flores-Romero H, Hohorst L, John M, Albert MC, King LE, Beckmann L, Szabo T, Hertlein V, Luo X, Villunger A, Frenzel LP, Kashkar H, Garcia-Saez AJ. | D22: EMBO J. 2022 Dec 17;41(2):e108690. doi: 10.15252/embj.2021108690. Epub 2021 Dec 21. | E22: Flores-Romero H | F22: EMBO J | G22: 2022 | H22: 44551 | I22: PMC8762556 | K22: 10.15252/embj.2021108690 | L22: =IF(ISNUMBER(VLOOKUP(A22,EXCL,1,FALSE)),"Excluido",IF(ISNUMBER(VLOOKUP(A22,POST,1,FALSE)),"PostAlerta",IF(ISNUMBER(VLOOKUP(A22,PRE,1,FALSE)),"PreAlerta",""))) -> PostAlerta | M22: =IF(ISNUMBER(A22),(IF(ISNUMBER(VLOOKUP(A22,KEYWORDS,1,FALSE)),"C/PalabrasClaves","S/PalabrasClaves")),"") -> S/PalabrasClaves | N22: 2) Nuevos tratamientos | O22: 2b) Péptidos | P22: 2022 Dec 17 | Q22: Listo | R22: =LEFT(P22,4) -> 2022 | S22: Dec | T22: During apoptosis, the BCL-2-family protein tBID promotes mitochondrial permeabilization by activating BAX and BAK and by blocking anti-apoptotic BCL-2 members. Here, we report that tBID can also mediate mitochondrial permeabilization by itself, resulting in release of cytochrome c and mitochondrial DNA, caspase activation and apoptosis even in absence of BAX and BAK. This previously unrecognized activity of tBID depends on helix 6, homologous to the pore-forming regions of BAX and BAK, and can be blocked by pro-survival BCL-2 proteins. Importantly, tBID-mediated mitochondrial permeabilization independent of BAX and BAK is physiologically relevant for SMAC release in the immune response against Shigella infection. Furthermore, it can be exploited to kill leukaemia cells with acquired venetoclax resistance due to lack of active BAX and BAK. Our findings define tBID as an effector of mitochondrial permeabilization in apoptosis and provide a new paradigm for BCL-2 proteins, with implications for anti-bacterial immunity and cancer therapy. | U22: No | V22: Yes | W22: No | X22: tBID mediates mitochondrial permeabilization independent of BAX and BAK, impacting SMAC release in immune response and leukemia therapy. | Y22: =IF(ISNUMBER(SEARCH("combination", B22)), "combination ", "")
A23: 36589853 | B23: Sacubitril/Valsartan contributes to improving the diabetic kidney disease and regulating the gut microbiota in mice | C23: Wang P, Guo R, Bai X, Cui W, Zhang Y, Li H, Shang J, Zhao Z. | D23: Front Endocrinol (Lausanne). 2022 Dec 16;13:1034818. doi: 10.3389/fendo.2022.1034818. eCollection 2022. | E23: Wang P | F23: Front Endocrinol (Lausanne) | G23: 2022 | H23: 44928 | I23: PMC9802116 | K23: 10.3389/fendo.2022.1034818 | L23: =IF(ISNUMBER(VLOOKUP(A23,EXCL,1,FALSE)),"Excluido",IF(ISNUMBER(VLOOKUP(A23,POST,1,FALSE)),"PostAlerta",IF(ISNUMBER(VLOOKUP(A23,PRE,1,FALSE)),"PreAlerta",""))) -> PostAlerta | M23: =IF(ISNUMBER(A23),(IF(ISNUMBER(VLOOKUP(A23,KEYWORDS,1,FALSE)),"C/PalabrasClaves","S/PalabrasClaves")),"") -> C/PalabrasClaves | P23: 2022 Dec 16 | Q23: Excluir | R23: =LEFT(P23,4) -> 2022 | S23: Dec | Y23: =IF(ISNUMBER(SEARCH("combination", B23)), "combination ", "")
A24: 36589940 | B24: Review of major meat-borne zoonotic bacterial pathogens | C24: Ali S, Alsayeqh AF. | D24: Front Public Health. 2022 Dec 15;10:1045599. doi: 10.3389/fpubh.2022.1045599. eCollection 2022. | E24: Ali S | F24: Front Public Health | G24: 2022 | H24: 44928 | I24: PMC9799061 | K24: 10.3389/fpubh.2022.1045599 | L24: =IF(ISNUMBER(VLOOKUP(A24,EXCL,1,FALSE)),"Excluido",IF(ISNUMBER(VLOOKUP(A24,POST,1,FALSE)),"PostAlerta",IF(ISNUMBER(VLOOKUP(A24,PRE,1,FALSE)),"PreAlerta",""))) -> Excluido | M24: =IF(ISNUMBER(A24),(IF(ISNUMBER(VLOOKUP(A24,KEYWORDS,1,FALSE)),"C/PalabrasClaves","S/PalabrasClaves")),"") -> C/PalabrasClaves | P24: 2022 Dec 15 | Q24: Excluir | R24: =LEFT(P24,4) -> 2022 | S24: Dec | Y24: =IF(ISNUMBER(SEARCH("combination", B24)), "combination ", "")
A25: 36591266 | B25: New insights into β-glucan-enhanced immunity in largemouth bass Micropterus salmoides by transcriptome and intestinal microbial composition | C25: Zhang Y, Guo M, Li N, Dong Z, Cai L, Wu B, Xie J, Liu L, Ren L, Shi B. | D25: Front Immunol. 2022 Dec 14;13:1086103. doi: 10.3389/fimmu.2022.1086103. eCollection 2022. | E25: Zhang Y | F25: Front Immunol | G25: 2022 | H25: 44928 | I25: PMC9794605 | K25: 10.3389/fimmu.2022.1086103 | L25: =IF(ISNUMBER(VLOOKUP(A25,EXCL,1,FALSE)),"Excluido",IF(ISNUMBER(VLOOKUP(A25,POST,1,FALSE)),"PostAlerta",IF(ISNUMBER(VLOOKUP(A25,PRE,1,FALSE)),"PreAlerta",""))) -> PostAlerta | M25: =IF(ISNUMBER(A25),(IF(ISNUMBER(VLOOKUP(A25,KEYWORDS,1,FALSE)),"C/PalabrasClaves","S/PalabrasClaves")),"") -> S/PalabrasClaves | P25: 2022 Dec 14 | Q25: Excluir | R25: =LEFT(P25,4) -> 2022 | S25: Dec | Y25: =IF(ISNUMBER(SEARCH("combination", B25)), "combination ", "")
A26: 36508428 | B26: Development of a recombinase polymerase amplification assay with lateral flow dipstick (RPA-LFD) for rapid detection of Shigella spp. and enteroinvasive Escherichia coli | C26: Bian Z, Liu W, Jin J, Hao Y, Jiang L, Xie Y, Zhang H. | D26: PLoS One. 2022 Dec 12;17(12):e0278869. doi: 10.1371/journal.pone.0278869. eCollection 2022. | E26: Bian Z | F26: PLoS One | G26: 2022 | H26: 44907 | I26: PMC9744308 | K26: 10.1371/journal.pone.0278869 | L26: =IF(ISNUMBER(VLOOKUP(A26,EXCL,1,FALSE)),"Excluido",IF(ISNUMBER(VLOOKUP(A26,POST,1,FALSE)),"PostAlerta",IF(ISNUMBER(VLOOKUP(A26,PRE,1,FALSE)),"PreAlerta",""))) -> PostAlerta | M26: =IF(ISNUMBER(A26),(IF(ISNUMBER(VLOOKUP(A26,KEYWORDS,1,FALSE)),"C/PalabrasClaves","S/PalabrasClaves")),"") -> S/PalabrasClaves | P26: 2022 Dec 12 | Q26: Excluir | R26: =LEFT(P26,4) -> 2022 | S26: Dec | Y26: =IF(ISNUMBER(SEARCH("combination", B26)), "combination ", "")
A27: 36477445 | B27: Using runaway replication to express polyhydroxyalkanoic acid (pha) genes from a novel marine bacterium in enteric bacteria: The influence of temperature and phasins on PHA accumulation | C27: Kolibachuk D, Ryder BJ, Lyons ER, Woolsey A, Lopes MK, Thakkar K, Pacheco Nunez M, Duquenoy M, Valente NR, Nieves A. | D27: PLoS One. 2022 Dec 7;17(12):e0275597. doi: 10.1371/journal.pone.0275597. eCollection 2022. | E27: Kolibachuk D | F27: PLoS One | G27: 2022 | H27: 44903 | I27: PMC9728866 | K27: 10.1371/journal.pone.0275597 | L27: =IF(ISNUMBER(VLOOKUP(A27,EXCL,1,FALSE)),"Excluido",IF(ISNUMBER(VLOOKUP(A27,POST,1,FALSE)),"PostAlerta",IF(ISNUMBER(VLOOKUP(A27,PRE,1,FALSE)),"PreAlerta",""))) -> PostAlerta | M27: =IF(ISNUMBER(A27),(IF(ISNUMBER(VLOOKUP(A27,KEYWORDS,1,FALSE)),"C/PalabrasClaves","S/PalabrasClaves")),"") -> S/PalabrasClaves | P27: 2022 Dec 7 | Q27: Excluir | R27: =LEFT(P27,4) -> 2022 | S27: Dec | Y27: =IF(ISNUMBER(SEARCH("combination", B27)), "combination ", "")
A28: 36506782 | B28: Effects of Gabexate Mesylate on the Gut Microbiota and Metabolomics in Rats with Sepsis | C28: Sun W, Cui Y, Zhang X, Wang Y, Zhang Z, Ding X, Liang H, Wang D, Sun Y, Liu S, Duan X, Lu Y, Sun T. | D28: J Inflamm Res. 2022 Dec 5;15:6581-6594. doi: 10.2147/JIR.S392060. eCollection 2022. | E28: Sun W | F28: J Inflamm Res | G28: 2022 | H28: 44907 | I28: PMC9733569 | K28: 10.2147/JIR.S392060 | L28: =IF(ISNUMBER(VLOOKUP(A28,EXCL,1,FALSE)),"Excluido",IF(ISNUMBER(VLOOKUP(A28,POST,1,FALSE)),"PostAlerta",IF(ISNUMBER(VLOOKUP(A28,PRE,1,FALSE)),"PreAlerta",""))) -> PostAlerta | M28: =IF(ISNUMBER(A28),(IF(ISNUMBER(VLOOKUP(A28,KEYWORDS,1,FALSE)),"C/PalabrasClaves","S/PalabrasClaves")),"") -> S/PalabrasClaves | P28: 2022 Dec 5 | Q28: Excluir | R28: =LEFT(P28,4) -> 2022 | S28: Dec | Y28: =IF(ISNUMBER(SEARCH("combination", B28)), "combination ", "")
A29: 35149579 | B29: Shigella is common in symptomatic and asymptomatic men who have sex with men visiting a sexual health clinic in Amsterdam | C29: Braam JF, Bruisten SM, Hoogeland M, de Vries HJC, Schim van der Loeff MF, van Dam AP. | D29: Sex Transm Infect. 2022 Dec;98(8):564-569. doi: 10.1136/sextrans-2021-055274. Epub 2022 Feb 11. | E29: Braam JF | F29: Sex Transm Infect | G29: 2022 | H29: 44604 | K29: 10.1136/sextrans-2021-055274 | L29: =IF(ISNUMBER(VLOOKUP(A29,EXCL,1,FALSE)),"Excluido",IF(ISNUMBER(VLOOKUP(A29,POST,1,FALSE)),"PostAlerta",IF(ISNUMBER(VLOOKUP(A29,PRE,1,FALSE)),"PreAlerta",""))) -> PostAlerta | M29: =IF(ISNUMBER(A29),(IF(ISNUMBER(VLOOKUP(A29,KEYWORDS,1,FALSE)),"C/PalabrasClaves","S/PalabrasClaves")),"") -> S/PalabrasClaves | P29: 2022 Dec | Q29: Excluir | R29: =LEFT(P29,4) -> 2022 | S29: Dec | Y29: =IF(ISNUMBER(SEARCH("combination", B29)), "combination ", "")
A30: 35147277 | B30: Synthesis and biological activity profile of novel triazole/quinoline hybrids | C30: Jamshidi H, Naimi-Jamal MR, Safavi M, RayatSanati K, Azerang P, Tahghighi A. | D30: Chem Biol Drug Des. 2022 Dec;100(6):935-946. doi: 10.1111/cbdd.14031. Epub 2022 Feb 21. | E30: Jamshidi H | F30: Chem Biol Drug Des | G30: 2022 | H30: 44603 | K30: 10.1111/cbdd.14031 | L30: =IF(ISNUMBER(VLOOKUP(A30,EXCL,1,FALSE)),"Excluido",IF(ISNUMBER(VLOOKUP(A30,POST,1,FALSE)),"PostAlerta",IF(ISNUMBER(VLOOKUP(A30,PRE,1,FALSE)),"PreAlerta",""))) -> PostAlerta | M30: =IF(ISNUMBER(A30),(IF(ISNUMBER(VLOOKUP(A30,KEYWORDS,1,FALSE)),"C/PalabrasClaves","S/PalabrasClaves")),"") -> S/PalabrasClaves | N30: 2) Nuevos tratamientos | O30: 2g) nueva combinación de ATB | P30: 2022 Dec | Q30: Listo | R30: =LEFT(P30,4) -> 2022 | S30: Dec | T30: Based on the significant and diverse pharmacophore features of triazole ring and considering the potent antimicrobial properties of quinoline scaffold, a novel series of 1,2,3-triazole-based polyaromatic compounds containing chloroquinoline moiety were synthesized through a well-established synthetic methodology, named click chemistry. The structure of the synthetic compounds was characterized by various spectroscopic methods. The final products of triazole/quinoline hybrids and ((prop-2-yn-1-yloxy)methyl)benzene intermediates were screened for their antibacterial (Staphylococcus aureus, Escherichia coli, Shigella flexneri, and Salmonella enterica), antifungal (Candida albicans, Saccharomyces cerevisiae, and Aspergillus fumigatus), and cytotoxic activities. The best antifungal compounds exhibited minimum inhibitory concentration (MIC), in the range of 0.35-0.63 µM, against S. cerevisiae without any cytotoxic effect. These compounds can be selected as the potential candidates for treating invasive fungal infections caused by S. cerevisiae, after further investigation. Preliminary in silico ADME studies also predicted the favorable pharmacokinetic attributes of most compounds. | U30: No | V30: Yes | W30: No | X30: Triazole/quinoline hybrids showed potent antifungal activity against S. cerevisiae with no cytotoxicity, supporting their use as new treatments. | Y30: =IF(ISNUMBER(SEARCH("combination", B30)), "combination ", "")
A31: 34458959 | B31: In Vitro and In Vivo Evaluation of Lacticaseibacillus rhamnosus GG and Bifidobacterium lactis Bb12 Against Avian Pathogenic Escherichia coli and Identification of Novel Probiotic-Derived Bioactive Peptides | C31: Kathayat D, Closs G Jr, Helmy YA, Deblais L, Srivastava V, Rajashekara G. | D31: Probiotics Antimicrob Proteins. 2022 Dec;14(6):1012-1028. doi: 10.1007/s12602-021-09840-1. Epub 2021 Aug 30. | E31: Kathayat D | F31: Probiotics Antimicrob Proteins | G31: 2022 | H31: 44438 | K31: 10.1007/s12602-021-09840-1 | L31: =IF(ISNUMBER(VLOOKUP(A31,EXCL,1,FALSE)),"Excluido",IF(ISNUMBER(VLOOKUP(A31,POST,1,FALSE)),"PostAlerta",IF(ISNUMBER(VLOOKUP(A31,PRE,1,FALSE)),"PreAlerta",""))) -> PostAlerta | M31: =IF(ISNUMBER(A31),(IF(ISNUMBER(VLOOKUP(A31,KEYWORDS,1,FALSE)),"C/PalabrasClaves","S/PalabrasClaves")),"") -> C/PalabrasClaves | P31: 2022 Dec | Q31: Excluir | R31: =LEFT(P31,4) -> 2022 | S31: Dec | Y31: =IF(ISNUMBER(SEARCH("combination", B31)), "combination ", "")
A32: 34058958 | B32: Bacterial endotoxin-induced maternal inflammation leads to fetal intestinal injury and affects microbial colonization in the neonatal period | C32: Huang Q, Lu S, Zhu Y, Wei B, Chen Y, Bai F. | D32: J Matern Fetal Neonatal Med. 2022 Dec;35(25):6917-6927. doi: 10.1080/14767058.2021.1931101. Epub 2021 May 31. | E32: Huang Q | F32: J Matern Fetal Neonatal Med | G32: 2022 | H32: 44348 | K32: 10.1080/14767058.2021.1931101 | L32: =IF(ISNUMBER(VLOOKUP(A32,EXCL,1,FALSE)),"Excluido",IF(ISNUMBER(VLOOKUP(A32,POST,1,FALSE)),"PostAlerta",IF(ISNUMBER(VLOOKUP(A32,PRE,1,FALSE)),"PreAlerta",""))) -> PostAlerta | M32: =IF(ISNUMBER(A32),(IF(ISNUMBER(VLOOKUP(A32,KEYWORDS,1,FALSE)),"C/PalabrasClaves","S/PalabrasClaves")),"") -> S/PalabrasClaves | P32: 2022 Dec | Q32: Excluir | R32: =LEFT(P32,4) -> 2022 | S32: Dec | Y32: =IF(ISNUMBER(SEARCH("combination", B32)), "combination ", "")
A33: 36532479 | B33: Nourishing neonatal piglets with synthetic milk and Lactobacillus sp. at birth highly modifies the gut microbial communities at the post-weaning stage | C33: Sampath V, Song JH, Jeong J, Mun S, Han K, Kim IH. | D33: Front Microbiol. 2022 Nov 30;13:1044256. doi: 10.3389/fmicb.2022.1044256. eCollection 2022. | E33: Sampath V | F33: Front Microbiol | G33: 2022 | H33: 44914 | I33: PMC9748437 | K33: 10.3389/fmicb.2022.1044256 | L33: =IF(ISNUMBER(VLOOKUP(A33,EXCL,1,FALSE)),"Excluido",IF(ISNUMBER(VLOOKUP(A33,POST,1,FALSE)),"PostAlerta",IF(ISNUMBER(VLOOKUP(A33,PRE,1,FALSE)),"PreAlerta",""))) -> PostAlerta | M33: =IF(ISNUMBER(A33),(IF(ISNUMBER(VLOOKUP(A33,KEYWORDS,1,FALSE)),"C/PalabrasClaves","S/PalabrasClaves")),"") -> S/PalabrasClaves | P33: 2022 Nov 30 | Q33: Excluir | R33: =LEFT(P33,4) -> 2022 | S33: Nov | Y33: =IF(ISNUMBER(SEARCH("combination", B33)), "combination ", "")
A34: 36467878 | B34: The Antibacterial Effects of Cocktail and Single Forms of Lytic Phages Belonging to Podoviridae and Myoviridae Families from Sewage against Shigella sonnei and Shigella flexneri | C34: Jokar J, Rahimian N, Ghasemian A, Najafipour S. | D34: Biomed Res Int. 2022 Nov 25;2022:7833565. doi: 10.1155/2022/7833565. eCollection 2022. | E34: Jokar J | F34: Biomed Res Int | G34: 2022 | H34: 44900 | I34: PMC9718628 | K34: 10.1155/2022/7833565 | L34: =IF(ISNUMBER(VLOOKUP(A34,EXCL,1,FALSE)),"Excluido",IF(ISNUMBER(VLOOKUP(A34,POST,1,FALSE)),"PostAlerta",IF(ISNUMBER(VLOOKUP(A34,PRE,1,FALSE)),"PreAlerta",""))) -> PostAlerta | M34: =IF(ISNUMBER(A34),(IF(ISNUMBER(VLOOKUP(A34,KEYWORDS,1,FALSE)),"C/PalabrasClaves","S/PalabrasClaves")),"") -> C/PalabrasClaves | P34: 2022 Nov 25 | Q34: Excluir | R34: =LEFT(P34,4) -> 2022 | S34: Nov | Y34: =IF(ISNUMBER(SEARCH("combination", B34)), "combination ", "")
A35: 36504960 | B35: Analysis of the gut microbiome in obese native Tibetan children living at different altitudes: A case-control study | C35: Du W, Liu L, Ma Y, Zhu Q, Jia R, Han Y, Wu Z, Yan X, Ailizire A, Zhang W. | D35: Front Public Health. 2022 Nov 24;10:963202. doi: 10.3389/fpubh.2022.963202. eCollection 2022. | E35: Du W | F35: Front Public Health | G35: 2022 | H35: 44907 | I35: PMC9731119 | K35: 10.3389/fpubh.2022.963202 | L35: =IF(ISNUMBER(VLOOKUP(A35,EXCL,1,FALSE)),"Excluido",IF(ISNUMBER(VLOOKUP(A35,POST,1,FALSE)),"PostAlerta",IF(ISNUMBER(VLOOKUP(A35,PRE,1,FALSE)),"PreAlerta",""))) -> PostAlerta | M35: =IF(ISNUMBER(A35),(IF(ISNUMBER(VLOOKUP(A35,KEYWORDS,1,FALSE)),"C/PalabrasClaves","S/PalabrasClaves")),"") -> S/PalabrasClaves | P35: 2022 Nov 24 | Q35: Excluir | R35: =LEFT(P35,4) -> 2022 | S35: Nov | Y35: =IF(ISNUMBER(SEARCH("combination", B35)), "combination ", "")
A36: 36466967 | B36: Prevalence of Multiple Drug-Resistant Bacteria in the Main Campus Wastewater Treatment Plant of Wolaita Sodo University, Southern Ethiopia | C36: Adugna C, Sivalingam KM. | D36: Int J Microbiol. 2022 Nov 23;2022:1781518. doi: 10.1155/2022/1781518. eCollection 2022. | E36: Adugna C | F36: Int J Microbiol | G36: 2022 | H36: 44900 | I36: PMC9711955 | K36: 10.1155/2022/1781518 | L36: =IF(ISNUMBER(VLOOKUP(A36,EXCL,1,FALSE)),"Excluido",IF(ISNUMBER(VLOOKUP(A36,POST,1,FALSE)),"PostAlerta",IF(ISNUMBER(VLOOKUP(A36,PRE,1,FALSE)),"PreAlerta",""))) -> PostAlerta | M36: =IF(ISNUMBER(A36),(IF(ISNUMBER(VLOOKUP(A36,KEYWORDS,1,FALSE)),"C/PalabrasClaves","S/PalabrasClaves")),"") -> C/PalabrasClaves | P36: 2022 Nov 23 | Q36: Excluir | R36: =LEFT(P36,4) -> 2022 | S36: Nov | Y36: =IF(ISNUMBER(SEARCH("combination", B36)), "combination ", "")
A37: 36478676 | B37: Do we need to change our perspective about gut biomarkers? A public data mining approach to identify differentially abundant bacteria in intestinal inflammatory diseases | C37: Vega L, Bohórquez L, Ramírez JD, Muñoz M. | D37: Front Cell Infect Microbiol. 2022 Nov 21;12:918237. doi: 10.3389/fcimb.2022.918237. eCollection 2022. | E37: Vega L | F37: Front Cell Infect Microbiol | G37: 2022 | H37: 44903 | I37: PMC9719923 | K37: 10.3389/fcimb.2022.918237 | L37: =IF(ISNUMBER(VLOOKUP(A37,EXCL,1,FALSE)),"Excluido",IF(ISNUMBER(VLOOKUP(A37,POST,1,FALSE)),"PostAlerta",IF(ISNUMBER(VLOOKUP(A37,PRE,1,FALSE)),"PreAlerta",""))) -> PostAlerta | M37: =IF(ISNUMBER(A37),(IF(ISNUMBER(VLOOKUP(A37,KEYWORDS,1,FALSE)),"C/PalabrasClaves","S/PalabrasClaves")),"") -> S/PalabrasClaves | P37: 2022 Nov 21 | Q37: Excluir | R37: =LEFT(P37,4) -> 2022 | S37: Nov | Y37: =IF(ISNUMBER(SEARCH("combination", B37)), "combination ", "")
A38: 36409683 | B38: Antimicrobial resistance in shigellosis: A surveillance study among urban and rural children over 20 years in Bangladesh | C38: Nuzhat S, Das R, Das S, Islam SB, Palit P, Haque MA, Chakraborty S, Khan SH, Ahmed D, Alam B, Ahmed T, Chisti MJ, Faruque ASG. | D38: PLoS One. 2022 Nov 21;17(11):e0277574. doi: 10.1371/journal.pone.0277574. eCollection 2022. | E38: Nuzhat S | F38: PLoS One | G38: 2022 | H38: 44886 | I38: PMC9678309 | K38: 10.1371/journal.pone.0277574 | L38: =IF(ISNUMBER(VLOOKUP(A38,EXCL,1,FALSE)),"Excluido",IF(ISNUMBER(VLOOKUP(A38,POST,1,FALSE)),"PostAlerta",IF(ISNUMBER(VLOOKUP(A38,PRE,1,FALSE)),"PreAlerta",""))) -> PostAlerta | M38: =IF(ISNUMBER(A38),(IF(ISNUMBER(VLOOKUP(A38,KEYWORDS,1,FALSE)),"C/PalabrasClaves","S/PalabrasClaves")),"") -> C/PalabrasClaves | N38: 1) Reporte de cepas resistentes | P38: 2022 Nov 21 | Q38: Listo | R38: =LEFT(P38,4) -> 2022 | S38: Nov | T38: Antimicrobial resistance against shigellosis is increasingly alarming. However, evidence-based knowledge gaps regarding the changing trends of shigellosis in Bangladesh exist due to the scarcity of longitudinal data on antimicrobial resistance. Our study evaluated the last 20 years antimicrobial resistance patterns against shigellosis among under-5 children in the urban and rural sites of Bangladesh. Data were extracted from the Diarrheal Disease Surveillance System (DDSS) of Dhaka Hospital (urban site) and Matlab Hospital (rural site) of the International Centre for Diarrheal Disease Research, Bangladesh (icddr,b) between January 2001 and December 2020. We studied culture-confirmed shigellosis cases from urban Dhaka Hospital (n = 883) and rural Matlab Hospital (n = 1263). Since 2001, a declining percentage of shigellosis in children observed in urban and rural sites. Moreover, higher isolation rates of Shigella were found in the rural site [1263/15684 (8.1%)] compared to the urban site [883/26804 (3.3%)] in the last 20 years. In both areas, S. flexneri was the predominant species. The upward trend of S. sonnei in both the study sites was statistically significant after adjusting for age and sex. WHO-recommended 1st line antibiotic ciprofloxacin resistance gradually reached more than 70% in both the urban and rural site by 2020. In multiple logistic regression after adjusting for age and sex, ciprofloxacin, azithromycin, mecillinam, ceftriaxone, and multidrug resistance (resistance to any two of these four drugs) among under-5 children were found to be increasing significantly (p<0.01) in the last 20 years in both sites. The study results underscore the importance of therapeutic interventions for shigellosis by appropriate drugs based on their current antibiogram for under-5 children. These observations may help policymakers in formulating better case management strategies for shigellosis. | U38: Yes | V38: No | W38: No | X38: Ciprofloxacin and multidrug resistance in Shigella from under-5 children rose >70% in 20 years in Bangladesh, revealing resistant strains. | Y38: =IF(ISNUMBER(SEARCH("combination", B38)), "combination ", "")
A39: 36452327 | B39: Cocultivation of Chinese prescription and intestine microbiota: SJZD alleviated the major symptoms of IBS-D subjects by tuning neurotransmitter metabolism | C39: Xia X, Xie Y, Chen Q, Ding D, Wang Z, Xu Y, Wang Y, Wang X, Ding W. | D39: Front Endocrinol (Lausanne). 2022 Nov 14;13:1053103. doi: 10.3389/fendo.2022.1053103. eCollection 2022. | E39: Xia X | F39: Front Endocrinol (Lausanne) | G39: 2022 | H39: 44896 | I39: PMC9704418 | K39: 10.3389/fendo.2022.1053103 | L39: =IF(ISNUMBER(VLOOKUP(A39,EXCL,1,FALSE)),"Excluido",IF(ISNUMBER(VLOOKUP(A39,POST,1,FALSE)),"PostAlerta",IF(ISNUMBER(VLOOKUP(A39,PRE,1,FALSE)),"PreAlerta",""))) -> PostAlerta | M39: =IF(ISNUMBER(A39),(IF(ISNUMBER(VLOOKUP(A39,KEYWORDS,1,FALSE)),"C/PalabrasClaves","S/PalabrasClaves")),"") -> S/PalabrasClaves | P39: 2022 Nov 14 | Q39: Excluir | R39: =LEFT(P39,4) -> 2022 | S39: Nov | Y39: =IF(ISNUMBER(SEARCH("combination", B39)), "combination ", "")
A40: 36425784 | B40: Reprogrammed fecal and mucosa-associated intestinal microbiota and weakened mucus layer in intestinal goblet cell- specific Piezo1-deficient mice | C40: Liu Y, Fang F, Xiong Y, Wu J, Li X, Li G, Bai T, Hou X, Song J. | D40: Front Cell Infect Microbiol. 2022 Nov 8;12:1035386. doi: 10.3389/fcimb.2022.1035386. eCollection 2022. | E40: Liu Y | F40: Front Cell Infect Microbiol | G40: 2022 | H40: 44890 | I40: PMC9679152 | K40: 10.3389/fcimb.2022.1035386 | L40: =IF(ISNUMBER(VLOOKUP(A40,EXCL,1,FALSE)),"Excluido",IF(ISNUMBER(VLOOKUP(A40,POST,1,FALSE)),"PostAlerta",IF(ISNUMBER(VLOOKUP(A40,PRE,1,FALSE)),"PreAlerta",""))) -> PostAlerta | M40: =IF(ISNUMBER(A40),(IF(ISNUMBER(VLOOKUP(A40,KEYWORDS,1,FALSE)),"C/PalabrasClaves","S/PalabrasClaves")),"") -> S/PalabrasClaves | P40: 2022 Nov 8 | Q40: Excluir | R40: =LEFT(P40,4) -> 2022 | S40: Nov | Y40: =IF(ISNUMBER(SEARCH("combination", B40)), "combination ", "")
...

Sheet Test
A1: PMID | B1: Title | C1: Categoria | D1: Subcategorias | E1: Estado | F1: PubYear | G1: Abstract | H1: 1) Antimicrobial Resistance stain | I1: 2) New treatment | J1: 3) Immunization | K1: Human_summary
A2: 35174771 | B2: In vitro and in silico screening of novel typhoid drugs from endangered herb (Enicostema axillare) | C2: 2) Nuevos tratamientos | D2: 2a) Productos naturales | E2: Listo | F2: 2023 | G2: In the present study, antibacterial activity of swertiamarin from Enicostema axillare (Lam) was checked against three different human gram-negative pathogens namely Salmonella typhi, Klebsiella pneumoniae and Shigella flexneri. Minimum inhibitory concentration assay revealed low dose and efficient activity of swertiamarin on the above said pathogens. Though swertiamarin is a well-studied and characterized compound, there is no experimental proof available for its antibacterial activity. To gain more insight about the antibacterial efficiency of swertiamarin against typhoid causing S. typhi, a comparative molecular docking of S. typhi OmpF (3NSG) was performed with swertiamarin and other typhoid drugs available in the market which exposed better activity strength of swertiamarin compared with that of the other drugs. Further, molecular dynamics of S. typhi OmpF-swertiamarin shows good flexibility and stability at 100 ns. The outcome of this work will definitely provide an idea of using very low dose of swertiamarin as a potent and promising drug against typhoid fever.Communicated by Ramaswamy H. Sarma. | H2: No | I2: Yes | J2: No | K2: The study evaluates the antibacterial activity of swertiamarin as a potential drug against human pathogens, especially Salmonella typhi.
A3: 34453485 | B3: Green synthesis and characterization of Solanum xanthocarpum capped silver nanoparticles and its antimicrobial effect on multidrug-resistant bacterial (MDR) isolates | C3: 2) Nuevos tratamientos | D3: 2b) Péptidos | E3: Listo | F3: 2023 | G3: Plant extracts and their bioactive compounds are considered as the promising options for green synthesis of nanoparticles instead expensive and hazardous materials. Here, Solanum xanthocarpum fruit was used for synthesis of silver nanoparticles (AgNP). The synthesized AgNPs were characterized by using chromatographic and spectroscopic analytical methods. AgNPs were confirmed by UV-visible absorbance at 420-470 nm. TEM analysis showed AgNP with 22.45 nm average size. X-ray diffraction studies revealed the crystalline and face central cubic nature of AgNPs. FTIR analysis revealed functional group present over AgNPs. The aminodiphenyl acetic acid, clomipramine, and fonisopril from fruit extracts were found to be major capping agents on AgNPs as a result of analysis by HRLC-MS. All clinical isolates showed resistance for ampicilline, amoxyclav, niladixic acid, and sulphafurazole, suggesting multidrug resistance. The results showed that all isolates were sensitive to AgNPs synthesized fruit extracts. On the contrary, all isolates were resistant to whole S. xanthocarpum fruit extracts alone. The antimicrobial activity of AgNP was explored against multidrug-resistant (MDR) Gram-negative clinical isolates including Escherichia coli, Shigella spp., Aeronomonas spp. and Pseudomonas spp. MIC values ranged between 1.25 mg/ml and 2.5 mg/ml at 8 McFarland's standards. Minimum bactericidal concentration was found to be in between 2.5 mg/ml to 5 mg/ml. Nanoparticles synthesized from fruit extract of S. xanthocarpum containing aminodiphenyl acetic acid, clomipramine, and fonisopril metabolites exhibit promising antimicrobial activity against MDR Gram-negative clinical isolates. | H3: No | I3: Yes | J3: No | K3: Silver nanoparticles synthesized from Solanum xanthocarpum fruit show promising antimicrobial activity against multidrug-resistant Gram-negative isolates.
A4: 36686167 | B4: Pueraria lobata polysaccharides alleviate neonatal calf diarrhea by modulating gut microbiota and metabolites | C4: 2) Nuevos tratamientos | D4: 2b) Péptidos | E4: Listo | F4: 2023 | G4: Introduction: Neonatal calf diarrhea (NCD) is still one of the most critical diseases in calf rearing. Studies have shown that Pueraria lobata polysaccharides (PLP) have intense antioxidant and immunomodulatory activity and modulate gut microbiota. This randomized clinical trial aimed to determine the effect of PLP on the neonatal calf with diarrhea. Methods: In this study, we recorded the fecal score of experimental calves, and calves with fecal scores ≥ 2 were determined as diarrhea and assessed their serum concentrations of inflammatory cytokines and oxidative damage-related indices. Fecal microbiota and metabolomics of diarrheal calves were further investigated. Results: Results showed that treatment with PLP decreased the fecal score of diarrheal calves, serum concentrations of IL-1β, TNF-γ, and malondialdehyde, and also elevated the level of superoxide dismutase. In addition, PLP treatment altered the gut microbiota, significantly increased the relative abundances of beneficial bacteria, including the phyla Bacteroidetes and Actinobacteria, the genus Collinsella, Megamonas, and Bifidobacterium; decreased the relative abundances of pathogenetic or diarrhea related bacteria, such as Proteobacteria, Fusobacteria, Clostridium_sensu_stricto_1, and Escherichia_Shigella. Moreover, PLP can increase the fecal concentrations of isobutyric acid, propionic acid, and pantothenate; lower the levels of PC [18:0/18:1(9Z)], arachidonic acid, and docosahexaenoic acid. Discussion: Thus, the results suggested that the PLP may perform the therapeutic activity via alleviating intestinal inflammation and regulating gut microbiota, avoiding further dysbiosis to restore the metabolism of gut microbiota, and finally promoting the recovery of diarrhea. The change further mitigated intestinal inflammation and oxidative damage in diarrheal calves. This indicated that PLP might be a promising treatment to attenuate diarrhea in neonatal calves. | H4: No | I4: Yes | J4: No | K4: PLP treatment reduced diarrhea, inflammation, and oxidative damage in neonatal calves by regulating gut microbiota and improving metabolism.
